[INFO] 2025-10-19 11:14:26,204 | googleapiclient.discovery_cache | file_cache is only supported with oauth2client<4.0.0
[WARNING] 2025-10-19 11:19:29,293 | django.server | "GET /static/frontend/css/style_contro.css HTTP/1.1" 404 1901
[ERROR] 2025-10-19 11:19:54,780 | django.request | Internal Server Error: /dashboard/contributor/submit_content
Traceback (most recent call last):
  File "C:\Users\gauri\AppData\Local\Programs\Python\Python310\lib\site-packages\django\core\handlers\exception.py", line 55, in inner
    response = get_response(request)
  File "C:\Users\gauri\AppData\Local\Programs\Python\Python310\lib\site-packages\django\core\handlers\base.py", line 197, in _get_response
    response = wrapped_callback(request, *callback_args, **callback_kwargs)
  File "C:\Users\gauri\IdeaProjects\oer\accounts\views\views.py", line 152, in test_contributor_editor
    return contributor_editor(request)
  File "C:\Users\gauri\AppData\Local\Programs\Python\Python310\lib\site-packages\django\views\decorators\csrf.py", line 65, in _view_wrapper
    return view_func(request, *args, **kwargs)
  File "C:\Users\gauri\IdeaProjects\oer\accounts\views\contributor\file_saving.py", line 87, in contributor_editor
    return render(request, 'accounts/contributor/submit_content.html', {'files': files})
  File "C:\Users\gauri\AppData\Local\Programs\Python\Python310\lib\site-packages\django\shortcuts.py", line 25, in render
    content = loader.render_to_string(template_name, context, request, using=using)
  File "C:\Users\gauri\AppData\Local\Programs\Python\Python310\lib\site-packages\django\template\loader.py", line 61, in render_to_string
    template = get_template(template_name, using=using)
  File "C:\Users\gauri\AppData\Local\Programs\Python\Python310\lib\site-packages\django\template\loader.py", line 19, in get_template
    raise TemplateDoesNotExist(template_name, chain=chain)
django.template.exceptions.TemplateDoesNotExist: accounts/contributor/submit_content.html
[ERROR] 2025-10-19 11:19:54,780 | django.server | "GET /dashboard/contributor/submit_content HTTP/1.1" 500 94086
[INFO] 2025-10-19 11:23:26,831 | googleapiclient.discovery_cache | file_cache is only supported with oauth2client<4.0.0
[INFO] 2025-10-19 11:24:05,140 | googleapiclient.discovery_cache | file_cache is only supported with oauth2client<4.0.0
[INFO] 2025-10-19 11:35:17,706 | googleapiclient.discovery_cache | file_cache is only supported with oauth2client<4.0.0
[WARNING] 2025-10-19 11:35:30,802 | django.server | "GET /static/frontend/css/style.css HTTP/1.1" 404 1880
[WARNING] 2025-10-19 11:35:41,897 | django.server | "GET /static/frontend/css/style_contro.css HTTP/1.1" 404 1901
[INFO] 2025-10-19 11:36:20,972 | googleapiclient.discovery_cache | file_cache is only supported with oauth2client<4.0.0
[ERROR] 2025-10-19 11:36:25,956 | django.request | Internal Server Error: /dashboard/contributor/submit_content/
Traceback (most recent call last):
  File "C:\Users\gauri\AppData\Local\Programs\Python\Python310\lib\site-packages\django\core\handlers\exception.py", line 55, in inner
    response = get_response(request)
  File "C:\Users\gauri\AppData\Local\Programs\Python\Python310\lib\site-packages\django\core\handlers\base.py", line 197, in _get_response
    response = wrapped_callback(request, *callback_args, **callback_kwargs)
  File "C:\Users\gauri\IdeaProjects\oer\accounts\views\contributor\contributor_dashboard.py", line 25, in contributor_submit_content_view
    return contributor_editor(request)
  File "C:\Users\gauri\AppData\Local\Programs\Python\Python310\lib\site-packages\django\views\decorators\csrf.py", line 65, in _view_wrapper
    return view_func(request, *args, **kwargs)
  File "C:\Users\gauri\IdeaProjects\oer\accounts\views\contributor\file_saving.py", line 87, in contributor_editor
    return render(request, 'accounts/contributor/submit_content.html', {'files': files})
  File "C:\Users\gauri\AppData\Local\Programs\Python\Python310\lib\site-packages\django\shortcuts.py", line 25, in render
    content = loader.render_to_string(template_name, context, request, using=using)
  File "C:\Users\gauri\AppData\Local\Programs\Python\Python310\lib\site-packages\django\template\loader.py", line 61, in render_to_string
    template = get_template(template_name, using=using)
  File "C:\Users\gauri\AppData\Local\Programs\Python\Python310\lib\site-packages\django\template\loader.py", line 19, in get_template
    raise TemplateDoesNotExist(template_name, chain=chain)
django.template.exceptions.TemplateDoesNotExist: accounts/contributor/submit_content.html
[ERROR] 2025-10-19 11:36:25,968 | django.server | "GET /dashboard/contributor/submit_content/ HTTP/1.1" 500 93381
[INFO] 2025-10-19 11:39:28,615 | googleapiclient.discovery_cache | file_cache is only supported with oauth2client<4.0.0
[INFO] 2025-10-19 11:39:34,703 | googleapiclient.discovery_cache | file_cache is only supported with oauth2client<4.0.0
[INFO] 2025-10-19 11:39:48,265 | googleapiclient.discovery_cache | file_cache is only supported with oauth2client<4.0.0
[ERROR] 2025-10-19 11:39:52,337 | django.request | Internal Server Error: /dashboard/contributor/submit_content/
Traceback (most recent call last):
  File "C:\Users\gauri\AppData\Local\Programs\Python\Python310\lib\site-packages\django\core\handlers\exception.py", line 55, in inner
    response = get_response(request)
  File "C:\Users\gauri\AppData\Local\Programs\Python\Python310\lib\site-packages\django\core\handlers\base.py", line 197, in _get_response
    response = wrapped_callback(request, *callback_args, **callback_kwargs)
  File "C:\Users\gauri\IdeaProjects\oer\accounts\views\contributor\contributor_dashboard.py", line 36, in contributor_submit_content_view
    return render(request, "accounts/contributor/submit_content.html")
  File "C:\Users\gauri\AppData\Local\Programs\Python\Python310\lib\site-packages\django\shortcuts.py", line 25, in render
    content = loader.render_to_string(template_name, context, request, using=using)
  File "C:\Users\gauri\AppData\Local\Programs\Python\Python310\lib\site-packages\django\template\loader.py", line 61, in render_to_string
    template = get_template(template_name, using=using)
  File "C:\Users\gauri\AppData\Local\Programs\Python\Python310\lib\site-packages\django\template\loader.py", line 19, in get_template
    raise TemplateDoesNotExist(template_name, chain=chain)
django.template.exceptions.TemplateDoesNotExist: accounts/contributor/submit_content.html
[ERROR] 2025-10-19 11:39:52,354 | django.server | "GET /dashboard/contributor/submit_content/ HTTP/1.1" 500 85460
[ERROR] 2025-10-19 11:39:54,835 | django.request | Internal Server Error: /dashboard/contributor/submit_content/
Traceback (most recent call last):
  File "C:\Users\gauri\AppData\Local\Programs\Python\Python310\lib\site-packages\django\core\handlers\exception.py", line 55, in inner
    response = get_response(request)
  File "C:\Users\gauri\AppData\Local\Programs\Python\Python310\lib\site-packages\django\core\handlers\base.py", line 197, in _get_response
    response = wrapped_callback(request, *callback_args, **callback_kwargs)
  File "C:\Users\gauri\IdeaProjects\oer\accounts\views\contributor\contributor_dashboard.py", line 36, in contributor_submit_content_view
    return render(request, "accounts/contributor/submit_content.html")
  File "C:\Users\gauri\AppData\Local\Programs\Python\Python310\lib\site-packages\django\shortcuts.py", line 25, in render
    content = loader.render_to_string(template_name, context, request, using=using)
  File "C:\Users\gauri\AppData\Local\Programs\Python\Python310\lib\site-packages\django\template\loader.py", line 61, in render_to_string
    template = get_template(template_name, using=using)
  File "C:\Users\gauri\AppData\Local\Programs\Python\Python310\lib\site-packages\django\template\loader.py", line 19, in get_template
    raise TemplateDoesNotExist(template_name, chain=chain)
django.template.exceptions.TemplateDoesNotExist: accounts/contributor/submit_content.html
[ERROR] 2025-10-19 11:39:54,838 | django.server | "GET /dashboard/contributor/submit_content/ HTTP/1.1" 500 85460
[ERROR] 2025-10-19 11:39:58,548 | django.request | Internal Server Error: /dashboard/contributor/submit_content/
Traceback (most recent call last):
  File "C:\Users\gauri\AppData\Local\Programs\Python\Python310\lib\site-packages\django\core\handlers\exception.py", line 55, in inner
    response = get_response(request)
  File "C:\Users\gauri\AppData\Local\Programs\Python\Python310\lib\site-packages\django\core\handlers\base.py", line 197, in _get_response
    response = wrapped_callback(request, *callback_args, **callback_kwargs)
  File "C:\Users\gauri\IdeaProjects\oer\accounts\views\contributor\contributor_dashboard.py", line 36, in contributor_submit_content_view
    return render(request, "accounts/contributor/submit_content.html")
  File "C:\Users\gauri\AppData\Local\Programs\Python\Python310\lib\site-packages\django\shortcuts.py", line 25, in render
    content = loader.render_to_string(template_name, context, request, using=using)
  File "C:\Users\gauri\AppData\Local\Programs\Python\Python310\lib\site-packages\django\template\loader.py", line 61, in render_to_string
    template = get_template(template_name, using=using)
  File "C:\Users\gauri\AppData\Local\Programs\Python\Python310\lib\site-packages\django\template\loader.py", line 19, in get_template
    raise TemplateDoesNotExist(template_name, chain=chain)
django.template.exceptions.TemplateDoesNotExist: accounts/contributor/submit_content.html
[ERROR] 2025-10-19 11:39:58,552 | django.server | "GET /dashboard/contributor/submit_content/ HTTP/1.1" 500 85460
[INFO] 2025-10-19 11:42:35,936 | googleapiclient.discovery_cache | file_cache is only supported with oauth2client<4.0.0
[ERROR] 2025-10-19 11:42:38,109 | django.request | Internal Server Error: /dashboard/contributor/submit_content/
Traceback (most recent call last):
  File "C:\Users\gauri\AppData\Local\Programs\Python\Python310\lib\site-packages\django\core\handlers\exception.py", line 55, in inner
    response = get_response(request)
  File "C:\Users\gauri\AppData\Local\Programs\Python\Python310\lib\site-packages\django\core\handlers\base.py", line 197, in _get_response
    response = wrapped_callback(request, *callback_args, **callback_kwargs)
  File "C:\Users\gauri\IdeaProjects\oer\accounts\views\contributor\contributor_dashboard.py", line 36, in contributor_submit_content_view
    return render(request, "contributor/submit_content.html")
  File "C:\Users\gauri\AppData\Local\Programs\Python\Python310\lib\site-packages\django\shortcuts.py", line 25, in render
    content = loader.render_to_string(template_name, context, request, using=using)
  File "C:\Users\gauri\AppData\Local\Programs\Python\Python310\lib\site-packages\django\template\loader.py", line 62, in render_to_string
    return template.render(context, request)
  File "C:\Users\gauri\AppData\Local\Programs\Python\Python310\lib\site-packages\django\template\backends\django.py", line 107, in render
    return self.template.render(context)
  File "C:\Users\gauri\AppData\Local\Programs\Python\Python310\lib\site-packages\django\template\base.py", line 171, in render
    return self._render(context)
  File "C:\Users\gauri\AppData\Local\Programs\Python\Python310\lib\site-packages\django\template\base.py", line 163, in _render
    return self.nodelist.render(context)
  File "C:\Users\gauri\AppData\Local\Programs\Python\Python310\lib\site-packages\django\template\base.py", line 1016, in render
    return SafeString("".join([node.render_annotated(context) for node in self]))
  File "C:\Users\gauri\AppData\Local\Programs\Python\Python310\lib\site-packages\django\template\base.py", line 1016, in <listcomp>
    return SafeString("".join([node.render_annotated(context) for node in self]))
  File "C:\Users\gauri\AppData\Local\Programs\Python\Python310\lib\site-packages\django\template\base.py", line 977, in render_annotated
    return self.render(context)
  File "C:\Users\gauri\AppData\Local\Programs\Python\Python310\lib\site-packages\django\template\defaulttags.py", line 480, in render
    url = reverse(view_name, args=args, kwargs=kwargs, current_app=current_app)
  File "C:\Users\gauri\AppData\Local\Programs\Python\Python310\lib\site-packages\django\urls\base.py", line 98, in reverse
    resolved_url = resolver._reverse_with_prefix(view, prefix, *args, **kwargs)
  File "C:\Users\gauri\AppData\Local\Programs\Python\Python310\lib\site-packages\django\urls\resolvers.py", line 831, in _reverse_with_prefix
    raise NoReverseMatch(msg)
django.urls.exceptions.NoReverseMatch: Reverse for 'index' not found. 'index' is not a valid view function or pattern name.
[ERROR] 2025-10-19 11:42:38,121 | django.server | "GET /dashboard/contributor/submit_content/ HTTP/1.1" 500 124230
[ERROR] 2025-10-19 11:43:30,351 | django.request | Internal Server Error: /dashboard/contributor/submit_content/
Traceback (most recent call last):
  File "C:\Users\gauri\AppData\Local\Programs\Python\Python310\lib\site-packages\django\core\handlers\exception.py", line 55, in inner
    response = get_response(request)
  File "C:\Users\gauri\AppData\Local\Programs\Python\Python310\lib\site-packages\django\core\handlers\base.py", line 197, in _get_response
    response = wrapped_callback(request, *callback_args, **callback_kwargs)
  File "C:\Users\gauri\IdeaProjects\oer\accounts\views\contributor\contributor_dashboard.py", line 36, in contributor_submit_content_view
    return render(request, "contributor/submit_content.html")
  File "C:\Users\gauri\AppData\Local\Programs\Python\Python310\lib\site-packages\django\shortcuts.py", line 25, in render
    content = loader.render_to_string(template_name, context, request, using=using)
  File "C:\Users\gauri\AppData\Local\Programs\Python\Python310\lib\site-packages\django\template\loader.py", line 62, in render_to_string
    return template.render(context, request)
  File "C:\Users\gauri\AppData\Local\Programs\Python\Python310\lib\site-packages\django\template\backends\django.py", line 107, in render
    return self.template.render(context)
  File "C:\Users\gauri\AppData\Local\Programs\Python\Python310\lib\site-packages\django\template\base.py", line 171, in render
    return self._render(context)
  File "C:\Users\gauri\AppData\Local\Programs\Python\Python310\lib\site-packages\django\template\base.py", line 163, in _render
    return self.nodelist.render(context)
  File "C:\Users\gauri\AppData\Local\Programs\Python\Python310\lib\site-packages\django\template\base.py", line 1016, in render
    return SafeString("".join([node.render_annotated(context) for node in self]))
  File "C:\Users\gauri\AppData\Local\Programs\Python\Python310\lib\site-packages\django\template\base.py", line 1016, in <listcomp>
    return SafeString("".join([node.render_annotated(context) for node in self]))
  File "C:\Users\gauri\AppData\Local\Programs\Python\Python310\lib\site-packages\django\template\base.py", line 977, in render_annotated
    return self.render(context)
  File "C:\Users\gauri\AppData\Local\Programs\Python\Python310\lib\site-packages\django\template\defaulttags.py", line 480, in render
    url = reverse(view_name, args=args, kwargs=kwargs, current_app=current_app)
  File "C:\Users\gauri\AppData\Local\Programs\Python\Python310\lib\site-packages\django\urls\base.py", line 98, in reverse
    resolved_url = resolver._reverse_with_prefix(view, prefix, *args, **kwargs)
  File "C:\Users\gauri\AppData\Local\Programs\Python\Python310\lib\site-packages\django\urls\resolvers.py", line 831, in _reverse_with_prefix
    raise NoReverseMatch(msg)
django.urls.exceptions.NoReverseMatch: Reverse for 'submit_content' not found. 'submit_content' is not a valid view function or pattern name.
[ERROR] 2025-10-19 11:43:30,359 | django.server | "GET /dashboard/contributor/submit_content/ HTTP/1.1" 500 126104
[ERROR] 2025-10-19 11:44:20,342 | django.request | Internal Server Error: /dashboard/contributor/submit_content/
Traceback (most recent call last):
  File "C:\Users\gauri\AppData\Local\Programs\Python\Python310\lib\site-packages\django\core\handlers\exception.py", line 55, in inner
    response = get_response(request)
  File "C:\Users\gauri\AppData\Local\Programs\Python\Python310\lib\site-packages\django\core\handlers\base.py", line 197, in _get_response
    response = wrapped_callback(request, *callback_args, **callback_kwargs)
  File "C:\Users\gauri\IdeaProjects\oer\accounts\views\contributor\contributor_dashboard.py", line 36, in contributor_submit_content_view
    return render(request, "contributor/submit_content.html")
  File "C:\Users\gauri\AppData\Local\Programs\Python\Python310\lib\site-packages\django\shortcuts.py", line 25, in render
    content = loader.render_to_string(template_name, context, request, using=using)
  File "C:\Users\gauri\AppData\Local\Programs\Python\Python310\lib\site-packages\django\template\loader.py", line 62, in render_to_string
    return template.render(context, request)
  File "C:\Users\gauri\AppData\Local\Programs\Python\Python310\lib\site-packages\django\template\backends\django.py", line 107, in render
    return self.template.render(context)
  File "C:\Users\gauri\AppData\Local\Programs\Python\Python310\lib\site-packages\django\template\base.py", line 171, in render
    return self._render(context)
  File "C:\Users\gauri\AppData\Local\Programs\Python\Python310\lib\site-packages\django\template\base.py", line 163, in _render
    return self.nodelist.render(context)
  File "C:\Users\gauri\AppData\Local\Programs\Python\Python310\lib\site-packages\django\template\base.py", line 1016, in render
    return SafeString("".join([node.render_annotated(context) for node in self]))
  File "C:\Users\gauri\AppData\Local\Programs\Python\Python310\lib\site-packages\django\template\base.py", line 1016, in <listcomp>
    return SafeString("".join([node.render_annotated(context) for node in self]))
  File "C:\Users\gauri\AppData\Local\Programs\Python\Python310\lib\site-packages\django\template\base.py", line 977, in render_annotated
    return self.render(context)
  File "C:\Users\gauri\AppData\Local\Programs\Python\Python310\lib\site-packages\django\template\defaulttags.py", line 480, in render
    url = reverse(view_name, args=args, kwargs=kwargs, current_app=current_app)
  File "C:\Users\gauri\AppData\Local\Programs\Python\Python310\lib\site-packages\django\urls\base.py", line 98, in reverse
    resolved_url = resolver._reverse_with_prefix(view, prefix, *args, **kwargs)
  File "C:\Users\gauri\AppData\Local\Programs\Python\Python310\lib\site-packages\django\urls\resolvers.py", line 831, in _reverse_with_prefix
    raise NoReverseMatch(msg)
django.urls.exceptions.NoReverseMatch: Reverse for 'contributor/submit_content' not found. 'contributor/submit_content' is not a valid view function or pattern name.
[ERROR] 2025-10-19 11:44:20,347 | django.server | "GET /dashboard/contributor/submit_content/ HTTP/1.1" 500 126404
[WARNING] 2025-10-19 11:45:15,549 | django.server | "GET /static/frontend/css/style_contro.css HTTP/1.1" 404 1901
[WARNING] 2025-10-19 11:45:15,549 | django.server | "GET /static/frontend/images/high-five.jpg HTTP/1.1" 404 1901
[WARNING] 2025-10-19 11:45:15,557 | django.server | "GET /static/frontend/js/contributor.js HTTP/1.1" 404 1892
[WARNING] 2025-10-19 11:46:25,994 | django.server | "GET /static/frontend/images/high-five.jpg HTTP/1.1" 404 1901
[WARNING] 2025-10-19 11:46:25,996 | django.server | "GET /static/frontend/css/style_contro.css HTTP/1.1" 404 1901
[WARNING] 2025-10-19 11:46:26,007 | django.server | "GET /static/frontend/js/contributor.js HTTP/1.1" 404 1892
[WARNING] 2025-10-19 11:48:14,985 | django.server | "GET /static/frontend/css/style_contro.css HTTP/1.1" 404 1901
[WARNING] 2025-10-19 11:48:14,985 | django.server | "GET /static/frontend/images/high-five.jpg HTTP/1.1" 404 1901
[WARNING] 2025-10-19 11:48:14,994 | django.server | "GET /static/frontend/js/contributor.js HTTP/1.1" 404 1892
[WARNING] 2025-10-19 11:48:37,511 | django.server | "GET /static/frontend/images/high-five.jpg HTTP/1.1" 404 1901
[WARNING] 2025-10-19 11:48:37,517 | django.server | "GET /static/frontend/css/style_contro.css HTTP/1.1" 404 1901
[WARNING] 2025-10-19 11:48:37,523 | django.server | "GET /static/frontend/js/contributor.js HTTP/1.1" 404 1892
[WARNING] 2025-10-19 11:48:54,483 | django.server | "GET /static/frontend/images/high-five.jpg HTTP/1.1" 404 1901
[WARNING] 2025-10-19 11:48:54,485 | django.server | "GET /static/frontend/css/style_contro.css HTTP/1.1" 404 1901
[WARNING] 2025-10-19 11:48:54,486 | django.server | "GET /static/frontend/js/contributor.js HTTP/1.1" 404 1892
[WARNING] 2025-10-19 12:01:42,716 | django.server | "GET /static/frontend/css/style_contro.css HTTP/1.1" 404 1901
[WARNING] 2025-10-19 12:01:42,716 | django.server | "GET /static/frontend/images/high-five.jpg HTTP/1.1" 404 1901
[WARNING] 2025-10-19 12:01:42,716 | django.server | "GET /static/frontend/js/contributor.js HTTP/1.1" 404 1892
[WARNING] 2025-10-19 12:02:51,098 | django.server | "GET /static/frontend/js/contributor.js HTTP/1.1" 404 1892
[WARNING] 2025-10-19 12:02:51,098 | django.server | "GET /static/frontend/css/style_contro.css HTTP/1.1" 404 1901
[WARNING] 2025-10-19 12:02:51,098 | django.server | "GET /static/frontend/images/high-five.jpg HTTP/1.1" 404 1901
[INFO] 2025-10-19 12:10:17,010 | googleapiclient.discovery_cache | file_cache is only supported with oauth2client<4.0.0
[INFO] 2025-10-19 12:11:06,085 | googleapiclient.discovery_cache | file_cache is only supported with oauth2client<4.0.0
[WARNING] 2025-10-19 12:11:12,482 | django.server | "GET /static/frontend/css/style_contro.css HTTP/1.1" 404 1901
[WARNING] 2025-10-19 12:11:12,482 | django.server | "GET /static/frontend/images/high-five.jpg HTTP/1.1" 404 1901
[WARNING] 2025-10-19 12:11:12,484 | django.server | "GET /static/frontend/js/contributor.js HTTP/1.1" 404 1892
[WARNING] 2025-10-19 12:12:04,851 | django.server | "GET /static/frontend/css/style_contro.css HTTP/1.1" 404 1901
[WARNING] 2025-10-19 12:12:04,851 | django.server | "GET /static/frontend/images/high-five.jpg HTTP/1.1" 404 1901
[WARNING] 2025-10-19 12:12:04,851 | django.server | "GET /static/frontend/js/contributor.js HTTP/1.1" 404 1892
[INFO] 2025-10-19 12:17:18,528 | googleapiclient.discovery_cache | file_cache is only supported with oauth2client<4.0.0
[INFO] 2025-10-19 12:17:41,388 | googleapiclient.discovery_cache | file_cache is only supported with oauth2client<4.0.0
[WARNING] 2025-10-19 12:18:04,927 | django.server | "GET /static/frontend/images/high-five.jpg HTTP/1.1" 404 1901
[WARNING] 2025-10-19 12:18:04,927 | django.server | "GET /static/frontend/js/contributor.js HTTP/1.1" 404 1892
[WARNING] 2025-10-19 12:18:04,927 | django.server | "GET /static/frontend/css/style_contro.css HTTP/1.1" 404 1901
[WARNING] 2025-10-19 12:18:46,163 | django.server | "GET /static/frontend/css/style_contro.css HTTP/1.1" 404 1901
[WARNING] 2025-10-19 12:18:46,185 | django.server | "GET /static/frontend/js/contributor.js HTTP/1.1" 404 1892
[WARNING] 2025-10-19 12:18:46,187 | django.server | "GET /static/frontend/images/high-five.jpg HTTP/1.1" 404 1901
[INFO] 2025-10-19 12:21:40,499 | googleapiclient.discovery_cache | file_cache is only supported with oauth2client<4.0.0
[INFO] 2025-10-19 12:21:40,540 | googleapiclient.discovery_cache | file_cache is only supported with oauth2client<4.0.0
[INFO] 2025-10-19 12:21:40,578 | googleapiclient.discovery_cache | file_cache is only supported with oauth2client<4.0.0
[INFO] 2025-10-19 12:24:43,125 | googleapiclient.discovery_cache | file_cache is only supported with oauth2client<4.0.0
[WARNING] 2025-10-19 12:24:48,287 | django.server | "GET /static/frontend/css/style_contro.css HTTP/1.1" 404 1901
[WARNING] 2025-10-19 12:24:48,298 | django.server | "GET /static/frontend/images/high-five.jpg HTTP/1.1" 404 1901
[WARNING] 2025-10-19 12:24:48,299 | django.server | "GET /static/frontend/js/contributor.js HTTP/1.1" 404 1892
[WARNING] 2025-10-19 12:25:14,863 | django.server | "GET /static/frontend/images/high-five.jpg HTTP/1.1" 404 1901
[WARNING] 2025-10-19 12:25:14,864 | django.server | "GET /static/frontend/js/contributor.js HTTP/1.1" 404 1892
[WARNING] 2025-10-19 12:25:14,864 | django.server | "GET /static/frontend/css/style_contro.css HTTP/1.1" 404 1901
[WARNING] 2025-10-19 12:32:40,314 | django.server | "GET /static/frontend/css/style_contro.css HTTP/1.1" 404 1901
[WARNING] 2025-10-19 12:32:40,318 | django.server | "GET /static/frontend/images/high-five.jpg HTTP/1.1" 404 1901
[WARNING] 2025-10-19 12:32:40,320 | django.server | "GET /static/frontend/js/contributor.js HTTP/1.1" 404 1892
[ERROR] 2025-10-19 12:35:43,812 | django.request | Internal Server Error: /register/
Traceback (most recent call last):
  File "C:\Users\gauri\AppData\Local\Programs\Python\Python310\lib\site-packages\django\core\handlers\exception.py", line 55, in inner
    response = get_response(request)
  File "C:\Users\gauri\AppData\Local\Programs\Python\Python310\lib\site-packages\django\core\handlers\base.py", line 197, in _get_response
    response = wrapped_callback(request, *callback_args, **callback_kwargs)
  File "C:\Users\gauri\IdeaProjects\oer\accounts\views\views.py", line 110, in register_view
    user.role = User.Role.CONTRIBUTOR
AttributeError: type object 'User' has no attribute 'Role'
[ERROR] 2025-10-19 12:35:43,832 | django.server | "POST /register/ HTTP/1.1" 500 74343
[INFO] 2025-10-19 12:45:24,557 | googleapiclient.discovery_cache | file_cache is only supported with oauth2client<4.0.0
[INFO] 2025-10-19 12:46:13,457 | googleapiclient.discovery_cache | file_cache is only supported with oauth2client<4.0.0
[INFO] 2025-10-19 12:46:25,698 | googleapiclient.discovery_cache | file_cache is only supported with oauth2client<4.0.0
[INFO] 2025-10-19 12:46:53,564 | googleapiclient.discovery_cache | file_cache is only supported with oauth2client<4.0.0
[ERROR] 2025-10-19 12:47:30,650 | django.request | Internal Server Error: /register/
Traceback (most recent call last):
  File "C:\Users\gauri\AppData\Local\Programs\Python\Python310\lib\site-packages\django\core\handlers\exception.py", line 55, in inner
    response = get_response(request)
  File "C:\Users\gauri\AppData\Local\Programs\Python\Python310\lib\site-packages\django\core\handlers\base.py", line 197, in _get_response
    response = wrapped_callback(request, *callback_args, **callback_kwargs)
  File "C:\Users\gauri\IdeaProjects\oer\accounts\views\views.py", line 110, in register_view
    user.role = User.Role.CONTRIBUTOR
AttributeError: type object 'User' has no attribute 'Role'
[ERROR] 2025-10-19 12:47:30,653 | django.server | "POST /register/ HTTP/1.1" 500 74364
[INFO] 2025-10-19 12:48:58,044 | googleapiclient.discovery_cache | file_cache is only supported with oauth2client<4.0.0
[INFO] 2025-10-19 12:49:41,546 | googleapiclient.discovery_cache | file_cache is only supported with oauth2client<4.0.0
[INFO] 2025-10-19 12:50:26,227 | googleapiclient.discovery_cache | file_cache is only supported with oauth2client<4.0.0
[INFO] 2025-10-19 12:50:35,815 | googleapiclient.discovery_cache | file_cache is only supported with oauth2client<4.0.0
[INFO] 2025-10-19 12:50:47,063 | googleapiclient.discovery_cache | file_cache is only supported with oauth2client<4.0.0
[ERROR] 2025-10-19 12:51:21,741 | django.request | Internal Server Error: /register/
Traceback (most recent call last):
  File "C:\Users\gauri\AppData\Local\Programs\Python\Python310\lib\site-packages\django\core\handlers\exception.py", line 55, in inner
    response = get_response(request)
  File "C:\Users\gauri\AppData\Local\Programs\Python\Python310\lib\site-packages\django\core\handlers\base.py", line 197, in _get_response
    response = wrapped_callback(request, *callback_args, **callback_kwargs)
  File "C:\Users\gauri\IdeaProjects\oer\accounts\views\views.py", line 283, in register_view
    user.domain_of_expertise = request.POST.get('domain', '').strip()
  File "C:\Users\gauri\AppData\Local\Programs\Python\Python310\lib\site-packages\django\db\models\fields\related_descriptors.py", line 291, in __set__
    raise ValueError(
ValueError: Cannot assign "'SQL'": "User.domain_of_expertise" must be a "Expertise" instance.
[ERROR] 2025-10-19 12:51:21,744 | django.server | "POST /register/ HTTP/1.1" 500 78783
[INFO] 2025-10-19 12:52:21,461 | googleapiclient.discovery_cache | file_cache is only supported with oauth2client<4.0.0
[INFO] 2025-10-19 12:52:27,043 | googleapiclient.discovery_cache | file_cache is only supported with oauth2client<4.0.0
[INFO] 2025-10-19 12:52:43,338 | googleapiclient.discovery_cache | file_cache is only supported with oauth2client<4.0.0
[ERROR] 2025-10-19 12:53:09,506 | django.request | Internal Server Error: /register/
Traceback (most recent call last):
  File "C:\Users\gauri\AppData\Local\Programs\Python\Python310\lib\site-packages\django\core\handlers\exception.py", line 55, in inner
    response = get_response(request)
  File "C:\Users\gauri\AppData\Local\Programs\Python\Python310\lib\site-packages\django\core\handlers\base.py", line 197, in _get_response
    response = wrapped_callback(request, *callback_args, **callback_kwargs)
  File "C:\Users\gauri\IdeaProjects\oer\accounts\views\views.py", line 110, in register_view
    user.role = User.Role.CONTRIBUTOR
AttributeError: type object 'User' has no attribute 'Role'
[ERROR] 2025-10-19 12:53:09,511 | django.server | "POST /register/ HTTP/1.1" 500 74367
[ERROR] 2025-10-19 13:01:01,176 | django.request | Internal Server Error: /admin/accounts/user/
Traceback (most recent call last):
  File "C:\Users\gauri\AppData\Local\Programs\Python\Python310\lib\site-packages\django\db\backends\utils.py", line 105, in _execute
    return self.cursor.execute(sql, params)
psycopg2.errors.UndefinedColumn: column accounts_user.program_id does not exist
LINE 1: ...ignation", "accounts_user"."years_of_experience", "accounts_...
                                                             ^


The above exception was the direct cause of the following exception:

Traceback (most recent call last):
  File "C:\Users\gauri\AppData\Local\Programs\Python\Python310\lib\site-packages\django\core\handlers\exception.py", line 55, in inner
    response = get_response(request)
  File "C:\Users\gauri\AppData\Local\Programs\Python\Python310\lib\site-packages\django\core\handlers\base.py", line 197, in _get_response
    response = wrapped_callback(request, *callback_args, **callback_kwargs)
  File "C:\Users\gauri\AppData\Local\Programs\Python\Python310\lib\site-packages\django\contrib\admin\options.py", line 719, in wrapper
    return self.admin_site.admin_view(view)(*args, **kwargs)
  File "C:\Users\gauri\AppData\Local\Programs\Python\Python310\lib\site-packages\django\utils\decorators.py", line 192, in _view_wrapper
    result = _process_exception(request, e)
  File "C:\Users\gauri\AppData\Local\Programs\Python\Python310\lib\site-packages\django\utils\decorators.py", line 190, in _view_wrapper
    response = view_func(request, *args, **kwargs)
  File "C:\Users\gauri\AppData\Local\Programs\Python\Python310\lib\site-packages\django\views\decorators\cache.py", line 80, in _view_wrapper
    response = view_func(request, *args, **kwargs)
  File "C:\Users\gauri\AppData\Local\Programs\Python\Python310\lib\site-packages\django\contrib\admin\sites.py", line 246, in inner
    return view(request, *args, **kwargs)
  File "C:\Users\gauri\AppData\Local\Programs\Python\Python310\lib\site-packages\django\utils\decorators.py", line 48, in _wrapper
    return bound_method(*args, **kwargs)
  File "C:\Users\gauri\AppData\Local\Programs\Python\Python310\lib\site-packages\django\utils\decorators.py", line 192, in _view_wrapper
    result = _process_exception(request, e)
  File "C:\Users\gauri\AppData\Local\Programs\Python\Python310\lib\site-packages\django\utils\decorators.py", line 190, in _view_wrapper
    response = view_func(request, *args, **kwargs)
  File "C:\Users\gauri\AppData\Local\Programs\Python\Python310\lib\site-packages\django\contrib\admin\options.py", line 2163, in changelist_view
    "selection_note": _("0 of %(cnt)s selected") % {"cnt": len(cl.result_list)},
  File "C:\Users\gauri\AppData\Local\Programs\Python\Python310\lib\site-packages\django\db\models\query.py", line 366, in __len__
    self._fetch_all()
  File "C:\Users\gauri\AppData\Local\Programs\Python\Python310\lib\site-packages\django\db\models\query.py", line 1949, in _fetch_all
    self._result_cache = list(self._iterable_class(self))
  File "C:\Users\gauri\AppData\Local\Programs\Python\Python310\lib\site-packages\django\db\models\query.py", line 91, in __iter__
    results = compiler.execute_sql(
  File "C:\Users\gauri\AppData\Local\Programs\Python\Python310\lib\site-packages\django\db\models\sql\compiler.py", line 1623, in execute_sql
    cursor.execute(sql, params)
  File "C:\Users\gauri\AppData\Local\Programs\Python\Python310\lib\site-packages\django\db\backends\utils.py", line 122, in execute
    return super().execute(sql, params)
  File "C:\Users\gauri\AppData\Local\Programs\Python\Python310\lib\site-packages\django\db\backends\utils.py", line 79, in execute
    return self._execute_with_wrappers(
  File "C:\Users\gauri\AppData\Local\Programs\Python\Python310\lib\site-packages\django\db\backends\utils.py", line 92, in _execute_with_wrappers
    return executor(sql, params, many, context)
  File "C:\Users\gauri\AppData\Local\Programs\Python\Python310\lib\site-packages\django\db\backends\utils.py", line 100, in _execute
    with self.db.wrap_database_errors:
  File "C:\Users\gauri\AppData\Local\Programs\Python\Python310\lib\site-packages\django\db\utils.py", line 91, in __exit__
    raise dj_exc_value.with_traceback(traceback) from exc_value
  File "C:\Users\gauri\AppData\Local\Programs\Python\Python310\lib\site-packages\django\db\backends\utils.py", line 105, in _execute
    return self.cursor.execute(sql, params)
django.db.utils.ProgrammingError: column accounts_user.program_id does not exist
LINE 1: ...ignation", "accounts_user"."years_of_experience", "accounts_...
                                                             ^

[ERROR] 2025-10-19 13:01:01,186 | django.server | "GET /admin/accounts/user/ HTTP/1.1" 500 175485
[ERROR] 2025-10-19 13:01:23,088 | django.request | Internal Server Error: /admin/accounts/user/
Traceback (most recent call last):
  File "C:\Users\gauri\AppData\Local\Programs\Python\Python310\lib\site-packages\django\db\backends\utils.py", line 105, in _execute
    return self.cursor.execute(sql, params)
psycopg2.errors.UndefinedColumn: column accounts_user.program_id does not exist
LINE 1: ...ignation", "accounts_user"."years_of_experience", "accounts_...
                                                             ^


The above exception was the direct cause of the following exception:

Traceback (most recent call last):
  File "C:\Users\gauri\AppData\Local\Programs\Python\Python310\lib\site-packages\django\core\handlers\exception.py", line 55, in inner
    response = get_response(request)
  File "C:\Users\gauri\AppData\Local\Programs\Python\Python310\lib\site-packages\django\core\handlers\base.py", line 197, in _get_response
    response = wrapped_callback(request, *callback_args, **callback_kwargs)
  File "C:\Users\gauri\AppData\Local\Programs\Python\Python310\lib\site-packages\django\contrib\admin\options.py", line 719, in wrapper
    return self.admin_site.admin_view(view)(*args, **kwargs)
  File "C:\Users\gauri\AppData\Local\Programs\Python\Python310\lib\site-packages\django\utils\decorators.py", line 192, in _view_wrapper
    result = _process_exception(request, e)
  File "C:\Users\gauri\AppData\Local\Programs\Python\Python310\lib\site-packages\django\utils\decorators.py", line 190, in _view_wrapper
    response = view_func(request, *args, **kwargs)
  File "C:\Users\gauri\AppData\Local\Programs\Python\Python310\lib\site-packages\django\views\decorators\cache.py", line 80, in _view_wrapper
    response = view_func(request, *args, **kwargs)
  File "C:\Users\gauri\AppData\Local\Programs\Python\Python310\lib\site-packages\django\contrib\admin\sites.py", line 246, in inner
    return view(request, *args, **kwargs)
  File "C:\Users\gauri\AppData\Local\Programs\Python\Python310\lib\site-packages\django\utils\decorators.py", line 48, in _wrapper
    return bound_method(*args, **kwargs)
  File "C:\Users\gauri\AppData\Local\Programs\Python\Python310\lib\site-packages\django\utils\decorators.py", line 192, in _view_wrapper
    result = _process_exception(request, e)
  File "C:\Users\gauri\AppData\Local\Programs\Python\Python310\lib\site-packages\django\utils\decorators.py", line 190, in _view_wrapper
    response = view_func(request, *args, **kwargs)
  File "C:\Users\gauri\AppData\Local\Programs\Python\Python310\lib\site-packages\django\contrib\admin\options.py", line 2163, in changelist_view
    "selection_note": _("0 of %(cnt)s selected") % {"cnt": len(cl.result_list)},
  File "C:\Users\gauri\AppData\Local\Programs\Python\Python310\lib\site-packages\django\db\models\query.py", line 366, in __len__
    self._fetch_all()
  File "C:\Users\gauri\AppData\Local\Programs\Python\Python310\lib\site-packages\django\db\models\query.py", line 1949, in _fetch_all
    self._result_cache = list(self._iterable_class(self))
  File "C:\Users\gauri\AppData\Local\Programs\Python\Python310\lib\site-packages\django\db\models\query.py", line 91, in __iter__
    results = compiler.execute_sql(
  File "C:\Users\gauri\AppData\Local\Programs\Python\Python310\lib\site-packages\django\db\models\sql\compiler.py", line 1623, in execute_sql
    cursor.execute(sql, params)
  File "C:\Users\gauri\AppData\Local\Programs\Python\Python310\lib\site-packages\django\db\backends\utils.py", line 122, in execute
    return super().execute(sql, params)
  File "C:\Users\gauri\AppData\Local\Programs\Python\Python310\lib\site-packages\django\db\backends\utils.py", line 79, in execute
    return self._execute_with_wrappers(
  File "C:\Users\gauri\AppData\Local\Programs\Python\Python310\lib\site-packages\django\db\backends\utils.py", line 92, in _execute_with_wrappers
    return executor(sql, params, many, context)
  File "C:\Users\gauri\AppData\Local\Programs\Python\Python310\lib\site-packages\django\db\backends\utils.py", line 100, in _execute
    with self.db.wrap_database_errors:
  File "C:\Users\gauri\AppData\Local\Programs\Python\Python310\lib\site-packages\django\db\utils.py", line 91, in __exit__
    raise dj_exc_value.with_traceback(traceback) from exc_value
  File "C:\Users\gauri\AppData\Local\Programs\Python\Python310\lib\site-packages\django\db\backends\utils.py", line 105, in _execute
    return self.cursor.execute(sql, params)
django.db.utils.ProgrammingError: column accounts_user.program_id does not exist
LINE 1: ...ignation", "accounts_user"."years_of_experience", "accounts_...
                                                             ^

[ERROR] 2025-10-19 13:01:23,092 | django.server | "GET /admin/accounts/user/ HTTP/1.1" 500 175495
[ERROR] 2025-10-19 13:04:11,867 | django.request | Internal Server Error: /admin/accounts/user/
Traceback (most recent call last):
  File "C:\Users\gauri\AppData\Local\Programs\Python\Python310\lib\site-packages\django\db\backends\utils.py", line 105, in _execute
    return self.cursor.execute(sql, params)
psycopg2.errors.UndefinedColumn: column accounts_user.program_id does not exist
LINE 1: ...ignation", "accounts_user"."years_of_experience", "accounts_...
                                                             ^


The above exception was the direct cause of the following exception:

Traceback (most recent call last):
  File "C:\Users\gauri\AppData\Local\Programs\Python\Python310\lib\site-packages\django\core\handlers\exception.py", line 55, in inner
    response = get_response(request)
  File "C:\Users\gauri\AppData\Local\Programs\Python\Python310\lib\site-packages\django\core\handlers\base.py", line 197, in _get_response
    response = wrapped_callback(request, *callback_args, **callback_kwargs)
  File "C:\Users\gauri\AppData\Local\Programs\Python\Python310\lib\site-packages\django\contrib\admin\options.py", line 719, in wrapper
    return self.admin_site.admin_view(view)(*args, **kwargs)
  File "C:\Users\gauri\AppData\Local\Programs\Python\Python310\lib\site-packages\django\utils\decorators.py", line 192, in _view_wrapper
    result = _process_exception(request, e)
  File "C:\Users\gauri\AppData\Local\Programs\Python\Python310\lib\site-packages\django\utils\decorators.py", line 190, in _view_wrapper
    response = view_func(request, *args, **kwargs)
  File "C:\Users\gauri\AppData\Local\Programs\Python\Python310\lib\site-packages\django\views\decorators\cache.py", line 80, in _view_wrapper
    response = view_func(request, *args, **kwargs)
  File "C:\Users\gauri\AppData\Local\Programs\Python\Python310\lib\site-packages\django\contrib\admin\sites.py", line 246, in inner
    return view(request, *args, **kwargs)
  File "C:\Users\gauri\AppData\Local\Programs\Python\Python310\lib\site-packages\django\utils\decorators.py", line 48, in _wrapper
    return bound_method(*args, **kwargs)
  File "C:\Users\gauri\AppData\Local\Programs\Python\Python310\lib\site-packages\django\utils\decorators.py", line 192, in _view_wrapper
    result = _process_exception(request, e)
  File "C:\Users\gauri\AppData\Local\Programs\Python\Python310\lib\site-packages\django\utils\decorators.py", line 190, in _view_wrapper
    response = view_func(request, *args, **kwargs)
  File "C:\Users\gauri\AppData\Local\Programs\Python\Python310\lib\site-packages\django\contrib\admin\options.py", line 2163, in changelist_view
    "selection_note": _("0 of %(cnt)s selected") % {"cnt": len(cl.result_list)},
  File "C:\Users\gauri\AppData\Local\Programs\Python\Python310\lib\site-packages\django\db\models\query.py", line 366, in __len__
    self._fetch_all()
  File "C:\Users\gauri\AppData\Local\Programs\Python\Python310\lib\site-packages\django\db\models\query.py", line 1949, in _fetch_all
    self._result_cache = list(self._iterable_class(self))
  File "C:\Users\gauri\AppData\Local\Programs\Python\Python310\lib\site-packages\django\db\models\query.py", line 91, in __iter__
    results = compiler.execute_sql(
  File "C:\Users\gauri\AppData\Local\Programs\Python\Python310\lib\site-packages\django\db\models\sql\compiler.py", line 1623, in execute_sql
    cursor.execute(sql, params)
  File "C:\Users\gauri\AppData\Local\Programs\Python\Python310\lib\site-packages\django\db\backends\utils.py", line 122, in execute
    return super().execute(sql, params)
  File "C:\Users\gauri\AppData\Local\Programs\Python\Python310\lib\site-packages\django\db\backends\utils.py", line 79, in execute
    return self._execute_with_wrappers(
  File "C:\Users\gauri\AppData\Local\Programs\Python\Python310\lib\site-packages\django\db\backends\utils.py", line 92, in _execute_with_wrappers
    return executor(sql, params, many, context)
  File "C:\Users\gauri\AppData\Local\Programs\Python\Python310\lib\site-packages\django\db\backends\utils.py", line 100, in _execute
    with self.db.wrap_database_errors:
  File "C:\Users\gauri\AppData\Local\Programs\Python\Python310\lib\site-packages\django\db\utils.py", line 91, in __exit__
    raise dj_exc_value.with_traceback(traceback) from exc_value
  File "C:\Users\gauri\AppData\Local\Programs\Python\Python310\lib\site-packages\django\db\backends\utils.py", line 105, in _execute
    return self.cursor.execute(sql, params)
django.db.utils.ProgrammingError: column accounts_user.program_id does not exist
LINE 1: ...ignation", "accounts_user"."years_of_experience", "accounts_...
                                                             ^

[ERROR] 2025-10-19 13:04:11,872 | django.server | "GET /admin/accounts/user/ HTTP/1.1" 500 175504
[WARNING] 2025-10-19 14:19:26,587 | django.server | "GET /static/frontend/images/high-five.jpg HTTP/1.1" 404 1901
[WARNING] 2025-10-19 14:19:26,591 | django.server | "GET /static/frontend/js/contributor.js HTTP/1.1" 404 1892
[WARNING] 2025-10-19 14:19:26,591 | django.server | "GET /static/frontend/css/style_contro.css HTTP/1.1" 404 1901
[INFO] 2025-10-19 14:23:54,745 | googleapiclient.discovery_cache | file_cache is only supported with oauth2client<4.0.0
[WARNING] 2025-10-19 14:24:00,613 | django.server | "GET /static/frontend/images/high-five.jpg HTTP/1.1" 404 1901
[WARNING] 2025-10-19 14:24:00,621 | django.server | "GET /static/frontend/css/style_contro.css HTTP/1.1" 404 1901
[WARNING] 2025-10-19 14:24:00,633 | django.server | "GET /static/frontend/js/contributor.js HTTP/1.1" 404 1892
[INFO] 2025-10-19 14:25:18,662 | googleapiclient.discovery_cache | file_cache is only supported with oauth2client<4.0.0
[WARNING] 2025-10-19 14:25:20,083 | django.server | "GET /static/frontend/css/style_contro.css HTTP/1.1" 404 1901
[WARNING] 2025-10-19 14:25:20,100 | django.server | "GET /static/frontend/images/high-five.jpg HTTP/1.1" 404 1901
[WARNING] 2025-10-19 14:25:20,119 | django.server | "GET /static/frontend/js/contributor.js HTTP/1.1" 404 1892
[INFO] 2025-10-19 14:25:48,211 | googleapiclient.discovery_cache | file_cache is only supported with oauth2client<4.0.0
[WARNING] 2025-10-19 14:26:00,219 | googleapiclient.http | Encountered 403 Forbidden with reason "storageQuotaExceeded"
[ERROR] 2025-10-19 14:26:00,316 | django.request | Internal Server Error: /dashboard/contributor/submit_content/upload
Traceback (most recent call last):
  File "C:\Users\gauri\AppData\Local\Programs\Python\Python310\lib\site-packages\django\core\handlers\exception.py", line 55, in inner
    response = get_response(request)
  File "C:\Users\gauri\AppData\Local\Programs\Python\Python310\lib\site-packages\django\core\handlers\base.py", line 197, in _get_response
    response = wrapped_callback(request, *callback_args, **callback_kwargs)
  File "C:\Users\gauri\IdeaProjects\oer\accounts\views\contributor\submit_content.py", line 86, in upload_files
    file = service.files().create(body=metadata, media_body=media, fields='id').execute()
  File "C:\Users\gauri\AppData\Local\Programs\Python\Python310\lib\site-packages\googleapiclient\_helpers.py", line 130, in positional_wrapper
    return wrapped(*args, **kwargs)
  File "C:\Users\gauri\AppData\Local\Programs\Python\Python310\lib\site-packages\googleapiclient\http.py", line 938, in execute
    raise HttpError(resp, content, uri=self.uri)
googleapiclient.errors.HttpError: <HttpError 403 when requesting https://www.googleapis.com/upload/drive/v3/files?fields=id&alt=json&uploadType=multipart returned "Service Accounts do not have storage quota. Leverage shared drives (https://developers.google.com/workspace/drive/api/guides/about-shareddrives), or use OAuth delegation (http://support.google.com/a/answer/7281227) instead.". Details: "[{'message': 'Service Accounts do not have storage quota. Leverage shared drives (https://developers.google.com/workspace/drive/api/guides/about-shareddrives), or use OAuth delegation (http://support.google.com/a/answer/7281227) instead.', 'domain': 'usageLimits', 'reason': 'storageQuotaExceeded'}]">
[ERROR] 2025-10-19 14:26:00,318 | django.server | "POST /dashboard/contributor/submit_content/upload HTTP/1.1" 500 92755
[INFO] 2025-10-19 14:31:26,418 | googleapiclient.discovery_cache | file_cache is only supported with oauth2client<4.0.0
[WARNING] 2025-10-19 14:31:32,432 | django.server | "GET /static/frontend/css/style_contro.css HTTP/1.1" 404 1901
[WARNING] 2025-10-19 14:31:32,434 | django.server | "GET /static/frontend/images/high-five.jpg HTTP/1.1" 404 1901
[WARNING] 2025-10-19 14:31:32,441 | django.server | "GET /static/frontend/js/contributor.js HTTP/1.1" 404 1892
[INFO] 2025-10-19 14:31:54,355 | googleapiclient.discovery_cache | file_cache is only supported with oauth2client<4.0.0
[ERROR] 2025-10-19 14:31:55,543 | django.request | Internal Server Error: /dashboard/contributor/submit_content/upload
Traceback (most recent call last):
  File "C:\Users\gauri\AppData\Local\Programs\Python\Python310\lib\site-packages\django\core\handlers\exception.py", line 55, in inner
    response = get_response(request)
  File "C:\Users\gauri\AppData\Local\Programs\Python\Python310\lib\site-packages\django\core\handlers\base.py", line 197, in _get_response
    response = wrapped_callback(request, *callback_args, **callback_kwargs)
  File "C:\Users\gauri\IdeaProjects\oer\accounts\views\contributor\submit_content.py", line 85, in upload_files
    oer_content_id = get_or_create_drive_folder(service, "oer_content")
  File "C:\Users\gauri\IdeaProjects\oer\accounts\views\contributor\submit_content.py", line 44, in get_or_create_drive_folder
    ).execute()
  File "C:\Users\gauri\AppData\Local\Programs\Python\Python310\lib\site-packages\googleapiclient\_helpers.py", line 130, in positional_wrapper
    return wrapped(*args, **kwargs)
  File "C:\Users\gauri\AppData\Local\Programs\Python\Python310\lib\site-packages\googleapiclient\http.py", line 938, in execute
    raise HttpError(resp, content, uri=self.uri)
googleapiclient.errors.HttpError: <HttpError 404 when requesting https://www.googleapis.com/drive/v3/files?q=mimeType%3D%27application%2Fvnd.google-apps.folder%27+and+name%3D%27oer_content%27&spaces=drive&corpora=drive&driveId=1SsOPpMRDccaUkdqSZOCOfku5WbXzhZ8U&includeItemsFromAllDrives=true&supportsAllDrives=true&fields=files%28id%2C+name%29&alt=json returned "Shared drive not found: 1SsOPpMRDccaUkdqSZOCOfku5WbXzhZ8U". Details: "[{'message': 'Shared drive not found: 1SsOPpMRDccaUkdqSZOCOfku5WbXzhZ8U', 'domain': 'global', 'reason': 'notFound', 'location': 'driveId', 'locationType': 'parameter'}]">
[ERROR] 2025-10-19 14:31:55,543 | django.server | "POST /dashboard/contributor/submit_content/upload HTTP/1.1" 500 89153
