[WARNING] 2025-10-22 11:08:55,136 | django.request | Not Found: /favicon.ico
[WARNING] 2025-10-22 11:08:55,137 | django.server | "GET /favicon.ico HTTP/1.1" 404 4912
[WARNING] 2025-10-22 11:09:02,208 | django.server | "GET /static/frontend/css/style_contro.css HTTP/1.1" 404 1901
[WARNING] 2025-10-22 11:09:11,240 | django.server | "GET /static/frontend/css/style_contro.css HTTP/1.1" 404 1901
[WARNING] 2025-10-22 11:09:15,806 | django.server | "GET /static/frontend/images/high-five.jpg HTTP/1.1" 404 1901
[WARNING] 2025-10-22 11:09:15,806 | django.server | "GET /static/frontend/css/style_contro.css HTTP/1.1" 404 1901
[WARNING] 2025-10-22 11:09:16,117 | django.server | "GET /static/frontend/js/contributor.js HTTP/1.1" 404 1892
[INFO] 2025-10-22 11:09:40,820 | googleapiclient.discovery_cache | file_cache is only supported with oauth2client<4.0.0
[INFO] 2025-10-22 11:09:41,363 | google_auth_httplib2 | Refreshing credentials due to a 401 response. Attempt 1/2.
[ERROR] 2025-10-22 11:09:41,815 | django.request | Internal Server Error: /dashboard/contributor/submit_content/upload
Traceback (most recent call last):
  File "C:\Users\gauri\AppData\Local\Programs\Python\Python310\lib\site-packages\django\core\handlers\exception.py", line 55, in inner
    response = get_response(request)
  File "C:\Users\gauri\AppData\Local\Programs\Python\Python310\lib\site-packages\django\core\handlers\base.py", line 197, in _get_response
    response = wrapped_callback(request, *callback_args, **callback_kwargs)
  File "C:\Users\gauri\IdeaProjects\oer\accounts\views\contributor\submit_content.py", line 86, in upload_files
    oer_content_id = get_or_create_drive_folder(service, "oer_content")
  File "C:\Users\gauri\IdeaProjects\oer\accounts\views\contributor\submit_content.py", line 45, in get_or_create_drive_folder
    ).execute()
  File "C:\Users\gauri\AppData\Local\Programs\Python\Python310\lib\site-packages\googleapiclient\_helpers.py", line 130, in positional_wrapper
    return wrapped(*args, **kwargs)
  File "C:\Users\gauri\AppData\Local\Programs\Python\Python310\lib\site-packages\googleapiclient\http.py", line 923, in execute
    resp, content = _retry_request(
  File "C:\Users\gauri\AppData\Local\Programs\Python\Python310\lib\site-packages\googleapiclient\http.py", line 191, in _retry_request
    resp, content = http.request(uri, method, *args, **kwargs)
  File "C:\Users\gauri\AppData\Local\Programs\Python\Python310\lib\site-packages\google_auth_httplib2.py", line 245, in request
    self.credentials.refresh(self._request)
  File "C:\Users\gauri\AppData\Local\Programs\Python\Python310\lib\site-packages\google\oauth2\credentials.py", line 397, in refresh
    raise exceptions.RefreshError(
google.auth.exceptions.RefreshError: The credentials do not contain the necessary fields need to refresh the access token. You must specify refresh_token, token_uri, client_id, and client_secret.
[ERROR] 2025-10-22 11:09:41,832 | django.server | "POST /dashboard/contributor/submit_content/upload HTTP/1.1" 500 103751
[WARNING] 2025-10-22 11:14:09,522 | django.server | "GET /static/frontend/css/style_contro.css HTTP/1.1" 404 1901
[WARNING] 2025-10-22 11:14:13,168 | django.request | Not Found: /loin
[WARNING] 2025-10-22 11:14:13,169 | django.server | "GET /loin HTTP/1.1" 404 4891
[WARNING] 2025-10-22 11:14:23,688 | django.server | "GET /static/frontend/css/style_contro.css HTTP/1.1" 404 1901
[WARNING] 2025-10-22 11:14:27,115 | django.server | "GET /static/frontend/css/style_contro.css HTTP/1.1" 404 1901
[WARNING] 2025-10-22 11:14:32,924 | django.server | "GET /static/frontend/css/style_contro.css HTTP/1.1" 404 1901
[WARNING] 2025-10-22 11:14:32,930 | django.server | "GET /static/frontend/images/high-five.jpg HTTP/1.1" 404 1901
[WARNING] 2025-10-22 11:14:32,988 | django.server | "GET /static/frontend/js/contributor.js HTTP/1.1" 404 1892
[INFO] 2025-10-22 11:14:54,591 | googleapiclient.discovery_cache | file_cache is only supported with oauth2client<4.0.0
[INFO] 2025-10-22 11:14:54,959 | google_auth_httplib2 | Refreshing credentials due to a 401 response. Attempt 1/2.
[ERROR] 2025-10-22 11:15:07,265 | django.request | Internal Server Error: /dashboard/contributor/submit_content/upload
Traceback (most recent call last):
  File "C:\Users\gauri\AppData\Local\Programs\Python\Python310\lib\site-packages\django\core\handlers\exception.py", line 55, in inner
    response = get_response(request)
  File "C:\Users\gauri\AppData\Local\Programs\Python\Python310\lib\site-packages\django\core\handlers\base.py", line 197, in _get_response
    response = wrapped_callback(request, *callback_args, **callback_kwargs)
  File "C:\Users\gauri\IdeaProjects\oer\accounts\views\contributor\submit_content.py", line 114, in upload_files
    os.remove(temp_path)
PermissionError: [WinError 32] The process cannot access the file because it is being used by another process: 'C:\\Users\\gauri\\AppData\\Local\\Temp\\SQL – DML Commands.pdf'
[ERROR] 2025-10-22 11:15:07,265 | django.server | "POST /dashboard/contributor/submit_content/upload HTTP/1.1" 500 79707
[WARNING] 2025-10-22 11:28:37,774 | django.server | "GET /static/frontend/css/style_contro.css HTTP/1.1" 404 1901
[WARNING] 2025-10-22 11:28:46,753 | django.server | "GET /static/frontend/css/style_contro.css HTTP/1.1" 404 1901
[WARNING] 2025-10-22 11:28:50,010 | django.server | "GET /static/frontend/css/style_contro.css HTTP/1.1" 404 1901
[WARNING] 2025-10-22 11:28:55,225 | django.server | "GET /static/frontend/css/style_contro.css HTTP/1.1" 404 1901
[WARNING] 2025-10-22 11:28:55,239 | django.server | "GET /static/frontend/images/high-five.jpg HTTP/1.1" 404 1901
[WARNING] 2025-10-22 11:28:55,240 | django.server | "GET /static/frontend/js/contributor.js HTTP/1.1" 404 1892
[INFO] 2025-10-22 11:29:31,880 | googleapiclient.discovery_cache | file_cache is only supported with oauth2client<4.0.0
[INFO] 2025-10-22 11:29:32,257 | google_auth_httplib2 | Refreshing credentials due to a 401 response. Attempt 1/2.
[INFO] 2025-10-22 11:29:38,097 | googleapiclient.discovery_cache | file_cache is only supported with oauth2client<4.0.0
[INFO] 2025-10-22 11:29:38,436 | google_auth_httplib2 | Refreshing credentials due to a 401 response. Attempt 1/2.
[WARNING] 2025-10-22 11:33:52,942 | django.server | "GET /static/frontend/js/contributor.js HTTP/1.1" 404 1892
[WARNING] 2025-10-22 11:33:52,942 | django.server | "GET /static/frontend/css/style_contro.css HTTP/1.1" 404 1901
[WARNING] 2025-10-22 11:33:52,942 | django.server | "GET /static/frontend/images/high-five.jpg HTTP/1.1" 404 1901
[INFO] 2025-10-22 11:34:14,316 | google_auth_httplib2 | Refreshing credentials due to a 401 response. Attempt 1/2.
[WARNING] 2025-10-22 11:43:40,447 | django.server | "GET /static/frontend/css/style_contro.css HTTP/1.1" 404 1901
[WARNING] 2025-10-22 11:43:48,771 | django.server | "GET /static/frontend/css/style_contro.css HTTP/1.1" 404 1901
[WARNING] 2025-10-22 11:43:51,292 | django.server | "GET /static/frontend/css/style_contro.css HTTP/1.1" 404 1901
[WARNING] 2025-10-22 11:43:56,148 | django.server | "GET /static/frontend/css/style_contro.css HTTP/1.1" 404 1901
[WARNING] 2025-10-22 11:43:56,148 | django.server | "GET /static/frontend/images/high-five.jpg HTTP/1.1" 404 1901
[WARNING] 2025-10-22 11:43:56,180 | django.server | "GET /static/frontend/js/contributor.js HTTP/1.1" 404 1892
[INFO] 2025-10-22 11:44:19,932 | google_auth_httplib2 | Refreshing credentials due to a 401 response. Attempt 1/2.
[INFO] 2025-10-22 11:44:44,270 | google_auth_httplib2 | Refreshing credentials due to a 401 response. Attempt 1/2.
[INFO] 2025-10-22 11:44:44,551 | google_auth_httplib2 | Refreshing credentials due to a 401 response. Attempt 1/2.
[WARNING] 2025-10-22 11:51:51,622 | django.server | "GET /static/frontend/css/style_contro.css HTTP/1.1" 404 1901
[WARNING] 2025-10-22 11:52:23,075 | django.request | Not Found: /dashboard/contributor/submit_content/[object RadioNodeList]
[WARNING] 2025-10-22 11:52:24,097 | django.server | "POST /dashboard/contributor/submit_content/[object%20RadioNodeList] HTTP/1.1" 404 5063
[WARNING] 2025-10-22 11:52:40,201 | django.request | Not Found: /dashboard/contributor/submit_content/[object RadioNodeList]
[WARNING] 2025-10-22 11:52:40,729 | django.server | "POST /dashboard/contributor/submit_content/[object%20RadioNodeList] HTTP/1.1" 404 5063
[WARNING] 2025-10-22 11:53:03,635 | django.server | "GET /static/frontend/css/style_contro.css HTTP/1.1" 404 1901
[WARNING] 2025-10-22 11:53:14,282 | django.server | "GET /static/frontend/css/style_contro.css HTTP/1.1" 404 1901
[WARNING] 2025-10-22 11:53:36,047 | django.request | Not Found: /dashboard/contributor/submit_content/[object RadioNodeList]
[WARNING] 2025-10-22 11:53:36,674 | django.server | "POST /dashboard/contributor/submit_content/[object%20RadioNodeList] HTTP/1.1" 404 5063
[WARNING] 2025-10-22 11:54:06,858 | django.server | "GET /static/frontend/css/style_contro.css HTTP/1.1" 404 1901
[WARNING] 2025-10-22 11:54:06,859 | django.server | "GET /static/frontend/js/contributor.js HTTP/1.1" 404 1892
[WARNING] 2025-10-22 11:54:06,859 | django.server | "GET /static/frontend/images/high-five.jpg HTTP/1.1" 404 1901
[INFO] 2025-10-22 11:54:39,752 | google_auth_httplib2 | Refreshing credentials due to a 401 response. Attempt 1/2.
[ERROR] 2025-10-22 11:54:51,002 | django.request | Internal Server Error: /dashboard/contributor/submit_content/upload
Traceback (most recent call last):
  File "C:\Users\gauri\AppData\Local\Programs\Python\Python310\lib\site-packages\django\core\handlers\exception.py", line 55, in inner
    response = get_response(request)
  File "C:\Users\gauri\AppData\Local\Programs\Python\Python310\lib\site-packages\django\core\handlers\base.py", line 197, in _get_response
    response = wrapped_callback(request, *callback_args, **callback_kwargs)
  File "C:\Users\gauri\AppData\Local\Programs\Python\Python310\lib\site-packages\django\views\decorators\csrf.py", line 65, in _view_wrapper
    return view_func(request, *args, **kwargs)
  File "C:\Users\gauri\IdeaProjects\oer\accounts\views\contributor\submit_content.py", line 101, in upload_files
    os.remove(temp_path)
PermissionError: [WinError 32] The process cannot access the file because it is being used by another process: 'C:\\Users\\gauri\\AppData\\Local\\Temp\\DBMS fundamentals.pdf'
[ERROR] 2025-10-22 11:54:51,030 | django.server | "POST /dashboard/contributor/submit_content/upload HTTP/1.1" 500 85278
[WARNING] 2025-10-22 11:58:54,457 | django.server | "GET /static/frontend/js/contributor.js HTTP/1.1" 404 1892
[WARNING] 2025-10-22 11:58:54,457 | django.server | "GET /static/frontend/css/style_contro.css HTTP/1.1" 404 1901
[WARNING] 2025-10-22 11:58:54,471 | django.server | "GET /static/frontend/images/high-five.jpg HTTP/1.1" 404 1901
[INFO] 2025-10-22 11:59:13,616 | google_auth_httplib2 | Refreshing credentials due to a 401 response. Attempt 1/2.
[WARNING] 2025-10-22 12:04:23,807 | django.server | "GET /static/frontend/css/style_contro.css HTTP/1.1" 404 1901
[WARNING] 2025-10-22 12:04:23,821 | django.server | "GET /static/frontend/js/contributor.js HTTP/1.1" 404 1892
[WARNING] 2025-10-22 12:04:23,821 | django.server | "GET /static/frontend/images/high-five.jpg HTTP/1.1" 404 1901
[INFO] 2025-10-22 12:04:47,013 | google_auth_httplib2 | Refreshing credentials due to a 401 response. Attempt 1/2.
[WARNING] 2025-10-22 12:06:08,247 | django.server | "GET /static/frontend/js/contributor.js HTTP/1.1" 404 1892
[WARNING] 2025-10-22 12:06:08,263 | django.server | "GET /static/frontend/images/high-five.jpg HTTP/1.1" 404 1901
[WARNING] 2025-10-22 12:06:08,263 | django.server | "GET /static/frontend/css/style_contro.css HTTP/1.1" 404 1901
[INFO] 2025-10-22 12:06:57,149 | googleapiclient.discovery_cache | file_cache is only supported with oauth2client<4.0.0
[INFO] 2025-10-22 12:06:57,557 | google_auth_httplib2 | Refreshing credentials due to a 401 response. Attempt 1/2.
[ERROR] 2025-10-22 12:07:03,759 | django.request | Internal Server Error: /dashboard/contributor/submit_content/upload
Traceback (most recent call last):
  File "C:\Users\gauri\AppData\Local\Programs\Python\Python310\lib\site-packages\django\core\handlers\exception.py", line 55, in inner
    response = get_response(request)
  File "C:\Users\gauri\AppData\Local\Programs\Python\Python310\lib\site-packages\django\core\handlers\base.py", line 197, in _get_response
    response = wrapped_callback(request, *callback_args, **callback_kwargs)
  File "C:\Users\gauri\IdeaProjects\oer\accounts\views\contributor\submit_content.py", line 114, in upload_files
    os.remove(temp_path)
PermissionError: [WinError 32] The process cannot access the file because it is being used by another process: 'C:\\Users\\gauri\\AppData\\Local\\Temp\\DBMS fundamentals.pdf'
[ERROR] 2025-10-22 12:07:03,759 | django.server | "POST /dashboard/contributor/submit_content/upload HTTP/1.1" 500 79857
[WARNING] 2025-10-22 12:10:08,894 | django.server | "GET /static/frontend/images/high-five.jpg HTTP/1.1" 404 1901
[WARNING] 2025-10-22 12:10:08,894 | django.server | "GET /static/frontend/css/style_contro.css HTTP/1.1" 404 1901
[WARNING] 2025-10-22 12:10:08,894 | django.server | "GET /static/frontend/js/contributor.js HTTP/1.1" 404 1892
[ERROR] 2025-10-22 12:10:44,842 | django.request | Internal Server Error: /dashboard/contributor/submit_content/upload
Traceback (most recent call last):
  File "C:\Users\gauri\AppData\Local\Programs\Python\Python310\lib\site-packages\django\core\handlers\exception.py", line 55, in inner
    response = get_response(request)
  File "C:\Users\gauri\AppData\Local\Programs\Python\Python310\lib\site-packages\django\core\handlers\base.py", line 197, in _get_response
    response = wrapped_callback(request, *callback_args, **callback_kwargs)
  File "C:\Users\gauri\IdeaProjects\oer\accounts\views\contributor\submit_content.py", line 87, in upload_files
    service = get_drive_service()
  File "C:\Users\gauri\IdeaProjects\oer\accounts\views\contributor\submit_content.py", line 21, in get_drive_service
    token_uri=token_data["token_uri", "https://oauth2.googleapis.com/token"],
KeyError: ('token_uri', 'https://oauth2.googleapis.com/token')
[ERROR] 2025-10-22 12:10:44,852 | django.server | "POST /dashboard/contributor/submit_content/upload HTTP/1.1" 500 76258
[WARNING] 2025-10-22 12:13:20,417 | django.server | "GET /static/frontend/css/style_contro.css HTTP/1.1" 404 1901
[WARNING] 2025-10-22 12:13:20,417 | django.server | "GET /static/frontend/images/high-five.jpg HTTP/1.1" 404 1901
[WARNING] 2025-10-22 12:13:20,422 | django.server | "GET /static/frontend/js/contributor.js HTTP/1.1" 404 1892
[ERROR] 2025-10-22 12:13:51,709 | django.request | Internal Server Error: /dashboard/contributor/submit_content/upload
Traceback (most recent call last):
  File "C:\Users\gauri\AppData\Local\Programs\Python\Python310\lib\site-packages\django\core\handlers\exception.py", line 55, in inner
    response = get_response(request)
  File "C:\Users\gauri\AppData\Local\Programs\Python\Python310\lib\site-packages\django\core\handlers\base.py", line 197, in _get_response
    response = wrapped_callback(request, *callback_args, **callback_kwargs)
  File "C:\Users\gauri\IdeaProjects\oer\accounts\views\contributor\submit_content.py", line 96, in upload_files
    oer_content_id = get_or_create_drive_folder(service, "oer_content")
  File "C:\Users\gauri\IdeaProjects\oer\accounts\views\contributor\submit_content.py", line 51, in get_or_create_drive_folder
    driveId=SHARED_DRIVE_ID,
NameError: name 'SHARED_DRIVE_ID' is not defined
[ERROR] 2025-10-22 12:13:51,709 | django.server | "POST /dashboard/contributor/submit_content/upload HTTP/1.1" 500 75966
[INFO] 2025-10-22 12:17:05,788 | googleapiclient.discovery_cache | file_cache is only supported with oauth2client<4.0.0
[INFO] 2025-10-22 12:17:05,788 | googleapiclient.discovery_cache | file_cache is only supported with oauth2client<4.0.0
[INFO] 2025-10-22 12:17:06,231 | google_auth_httplib2 | Refreshing credentials due to a 401 response. Attempt 1/2.
[INFO] 2025-10-22 12:17:06,231 | google_auth_httplib2 | Refreshing credentials due to a 401 response. Attempt 1/2.
[WARNING] 2025-10-22 12:17:07,836 | django.server | "GET /static/frontend/css/style_contro.css HTTP/1.1" 404 1901
[WARNING] 2025-10-22 12:17:08,155 | django.server | "GET /static/frontend/js/contributor.js HTTP/1.1" 404 1892
[WARNING] 2025-10-22 12:17:08,178 | django.server | "GET /static/frontend/images/high-five.jpg HTTP/1.1" 404 1901
[WARNING] 2025-10-22 12:17:10,066 | django.server | "GET /static/frontend/css/style_contro.css HTTP/1.1" 404 1901
[WARNING] 2025-10-22 12:17:10,066 | django.server | "GET /static/frontend/images/high-five.jpg HTTP/1.1" 404 1901
[WARNING] 2025-10-22 12:17:10,066 | django.server | "GET /static/frontend/js/contributor.js HTTP/1.1" 404 1892
[ERROR] 2025-10-22 12:17:13,039 | django.request | Internal Server Error: /dashboard/contributor/submit_content/upload
Traceback (most recent call last):
  File "C:\Users\gauri\AppData\Local\Programs\Python\Python310\lib\site-packages\django\core\handlers\exception.py", line 55, in inner
    response = get_response(request)
  File "C:\Users\gauri\AppData\Local\Programs\Python\Python310\lib\site-packages\django\core\handlers\base.py", line 197, in _get_response
    response = wrapped_callback(request, *callback_args, **callback_kwargs)
  File "C:\Users\gauri\IdeaProjects\oer\accounts\views\contributor\submit_content.py", line 116, in upload_files
    os.remove(temp_path)
PermissionError: [WinError 32] The process cannot access the file because it is being used by another process: 'C:\\Users\\gauri\\AppData\\Local\\Temp\\DBMS fundamentals.pdf'
[ERROR] 2025-10-22 12:17:14,864 | django.request | Internal Server Error: /dashboard/contributor/submit_content/upload
Traceback (most recent call last):
  File "C:\Users\gauri\AppData\Local\Programs\Python\Python310\lib\site-packages\django\core\handlers\exception.py", line 55, in inner
    response = get_response(request)
  File "C:\Users\gauri\AppData\Local\Programs\Python\Python310\lib\site-packages\django\core\handlers\base.py", line 197, in _get_response
    response = wrapped_callback(request, *callback_args, **callback_kwargs)
  File "C:\Users\gauri\IdeaProjects\oer\accounts\views\contributor\submit_content.py", line 116, in upload_files
    os.remove(temp_path)
PermissionError: [WinError 32] The process cannot access the file because it is being used by another process: 'C:\\Users\\gauri\\AppData\\Local\\Temp\\DBMS fundamentals.pdf'
[INFO] 2025-10-22 12:17:39,165 | googleapiclient.discovery_cache | file_cache is only supported with oauth2client<4.0.0
[INFO] 2025-10-22 12:17:39,619 | google_auth_httplib2 | Refreshing credentials due to a 401 response. Attempt 1/2.
[ERROR] 2025-10-22 12:17:48,243 | django.request | Internal Server Error: /dashboard/contributor/submit_content/upload
Traceback (most recent call last):
  File "C:\Users\gauri\AppData\Local\Programs\Python\Python310\lib\site-packages\django\core\handlers\exception.py", line 55, in inner
    response = get_response(request)
  File "C:\Users\gauri\AppData\Local\Programs\Python\Python310\lib\site-packages\django\core\handlers\base.py", line 197, in _get_response
    response = wrapped_callback(request, *callback_args, **callback_kwargs)
  File "C:\Users\gauri\IdeaProjects\oer\accounts\views\contributor\submit_content.py", line 116, in upload_files
    os.remove(temp_path)
PermissionError: [WinError 32] The process cannot access the file because it is being used by another process: 'C:\\Users\\gauri\\AppData\\Local\\Temp\\DBMS fundamentals.pdf'
[ERROR] 2025-10-22 12:17:48,243 | django.server | "POST /dashboard/contributor/submit_content/upload HTTP/1.1" 500 79857
[INFO] 2025-10-22 12:18:55,421 | googleapiclient.discovery_cache | file_cache is only supported with oauth2client<4.0.0
[INFO] 2025-10-22 12:18:55,421 | googleapiclient.discovery_cache | file_cache is only supported with oauth2client<4.0.0
[INFO] 2025-10-22 12:18:55,912 | google_auth_httplib2 | Refreshing credentials due to a 401 response. Attempt 1/2.
[INFO] 2025-10-22 12:18:55,913 | google_auth_httplib2 | Refreshing credentials due to a 401 response. Attempt 1/2.
[ERROR] 2025-10-22 12:19:01,728 | django.request | Internal Server Error: /dashboard/contributor/submit_content/upload
Traceback (most recent call last):
  File "C:\Users\gauri\AppData\Local\Programs\Python\Python310\lib\site-packages\django\core\handlers\exception.py", line 55, in inner
    response = get_response(request)
  File "C:\Users\gauri\AppData\Local\Programs\Python\Python310\lib\site-packages\django\core\handlers\base.py", line 197, in _get_response
    response = wrapped_callback(request, *callback_args, **callback_kwargs)
  File "C:\Users\gauri\IdeaProjects\oer\accounts\views\contributor\submit_content.py", line 116, in upload_files
    os.remove(temp_path)
PermissionError: [WinError 32] The process cannot access the file because it is being used by another process: 'C:\\Users\\gauri\\AppData\\Local\\Temp\\DBMS fundamentals.pdf'
[ERROR] 2025-10-22 12:19:01,740 | django.server | "POST /dashboard/contributor/submit_content/upload HTTP/1.1" 500 79857
[ERROR] 2025-10-22 12:19:01,769 | django.request | Internal Server Error: /dashboard/contributor/submit_content/upload
Traceback (most recent call last):
  File "C:\Users\gauri\AppData\Local\Programs\Python\Python310\lib\site-packages\django\core\handlers\exception.py", line 55, in inner
    response = get_response(request)
  File "C:\Users\gauri\AppData\Local\Programs\Python\Python310\lib\site-packages\django\core\handlers\base.py", line 197, in _get_response
    response = wrapped_callback(request, *callback_args, **callback_kwargs)
  File "C:\Users\gauri\IdeaProjects\oer\accounts\views\contributor\submit_content.py", line 116, in upload_files
    os.remove(temp_path)
PermissionError: [WinError 32] The process cannot access the file because it is being used by another process: 'C:\\Users\\gauri\\AppData\\Local\\Temp\\DBMS fundamentals.pdf'
[ERROR] 2025-10-22 12:19:01,776 | django.server | "POST /dashboard/contributor/submit_content/upload HTTP/1.1" 500 79857
[WARNING] 2025-10-22 12:25:23,456 | django.server | "GET /static/frontend/js/contributor.js HTTP/1.1" 404 1892
[WARNING] 2025-10-22 12:25:23,456 | django.server | "GET /static/frontend/css/style_contro.css HTTP/1.1" 404 1901
[WARNING] 2025-10-22 12:25:23,456 | django.server | "GET /static/frontend/images/high-five.jpg HTTP/1.1" 404 1901
[INFO] 2025-10-22 12:25:47,352 | googleapiclient.discovery_cache | file_cache is only supported with oauth2client<4.0.0
[INFO] 2025-10-22 12:25:47,879 | google_auth_httplib2 | Refreshing credentials due to a 401 response. Attempt 1/2.
[ERROR] 2025-10-22 12:25:55,980 | django.request | Internal Server Error: /dashboard/contributor/submit_content/upload
Traceback (most recent call last):
  File "C:\Users\gauri\AppData\Local\Programs\Python\Python310\lib\site-packages\django\core\handlers\exception.py", line 55, in inner
    response = get_response(request)
  File "C:\Users\gauri\AppData\Local\Programs\Python\Python310\lib\site-packages\django\core\handlers\base.py", line 197, in _get_response
    response = wrapped_callback(request, *callback_args, **callback_kwargs)
  File "C:\Users\gauri\IdeaProjects\oer\accounts\views\contributor\submit_content.py", line 99, in upload_files
    os.remove(temp_path)
PermissionError: [WinError 32] The process cannot access the file because it is being used by another process: 'C:\\Users\\gauri\\AppData\\Local\\Temp\\Database Normalization.pdf'
[ERROR] 2025-10-22 12:25:55,982 | django.server | "POST /dashboard/contributor/submit_content/upload HTTP/1.1" 500 79649
[WARNING] 2025-10-22 12:31:03,789 | django.server | "GET /static/frontend/css/style_contro.css HTTP/1.1" 404 1901
[WARNING] 2025-10-22 12:31:09,982 | django.server | "GET /static/frontend/css/style_contro.css HTTP/1.1" 404 1901
[WARNING] 2025-10-22 12:31:09,984 | django.server | "GET /static/frontend/js/contributor.js HTTP/1.1" 404 1892
[WARNING] 2025-10-22 12:31:10,283 | django.server | "GET /static/frontend/images/high-five.jpg HTTP/1.1" 404 1901
[INFO] 2025-10-22 12:31:35,756 | googleapiclient.discovery_cache | file_cache is only supported with oauth2client<4.0.0
[INFO] 2025-10-22 12:31:36,150 | google_auth_httplib2 | Refreshing credentials due to a 401 response. Attempt 1/2.
[WARNING] 2025-10-22 12:35:13,691 | django.server | "GET /static/frontend/css/style_contro.css HTTP/1.1" 404 1901
[WARNING] 2025-10-22 12:35:13,692 | django.server | "GET /static/frontend/images/high-five.jpg HTTP/1.1" 404 1901
[WARNING] 2025-10-22 12:35:13,692 | django.server | "GET /static/frontend/js/contributor.js HTTP/1.1" 404 1892
[INFO] 2025-10-22 12:35:36,970 | googleapiclient.discovery_cache | file_cache is only supported with oauth2client<4.0.0
[INFO] 2025-10-22 12:35:37,409 | google_auth_httplib2 | Refreshing credentials due to a 401 response. Attempt 1/2.
[ERROR] 2025-10-22 12:35:44,668 | django.request | Internal Server Error: /dashboard/contributor/submit_content/upload
Traceback (most recent call last):
  File "C:\Users\gauri\AppData\Local\Programs\Python\Python310\lib\site-packages\django\core\handlers\exception.py", line 55, in inner
    response = get_response(request)
  File "C:\Users\gauri\AppData\Local\Programs\Python\Python310\lib\site-packages\django\core\handlers\base.py", line 197, in _get_response
    response = wrapped_callback(request, *callback_args, **callback_kwargs)
  File "C:\Users\gauri\IdeaProjects\oer\accounts\views\contributor\submit_content.py", line 103, in upload_files
    os.remove(temp_path)
PermissionError: [WinError 32] The process cannot access the file because it is being used by another process: 'C:\\Users\\gauri\\AppData\\Local\\Temp\\DBMS fundamentals.pdf'
[ERROR] 2025-10-22 12:35:44,680 | django.server | "POST /dashboard/contributor/submit_content/upload HTTP/1.1" 500 79730
[WARNING] 2025-10-22 12:40:05,268 | django.server | "GET /static/frontend/images/high-five.jpg HTTP/1.1" 404 1901
[WARNING] 2025-10-22 12:40:05,268 | django.server | "GET /static/frontend/js/contributor.js HTTP/1.1" 404 1892
[WARNING] 2025-10-22 12:40:05,268 | django.server | "GET /static/frontend/css/style_contro.css HTTP/1.1" 404 1901
[INFO] 2025-10-22 12:41:52,367 | googleapiclient.discovery_cache | file_cache is only supported with oauth2client<4.0.0
[INFO] 2025-10-22 12:41:52,804 | google_auth_httplib2 | Refreshing credentials due to a 401 response. Attempt 1/2.
[WARNING] 2025-10-22 12:48:38,100 | django.server | "GET /static/frontend/css/style_contro.css HTTP/1.1" 404 1901
[WARNING] 2025-10-22 12:48:38,403 | django.server | "GET /static/frontend/js/contributor.js HTTP/1.1" 404 1892
[WARNING] 2025-10-22 12:48:38,403 | django.server | "GET /static/frontend/images/high-five.jpg HTTP/1.1" 404 1901
[ERROR] 2025-10-22 12:49:09,154 | django.request | Internal Server Error: /dashboard/contributor/submit_content/upload
Traceback (most recent call last):
  File "C:\Users\gauri\AppData\Local\Programs\Python\Python310\lib\site-packages\django\core\handlers\exception.py", line 55, in inner
    response = get_response(request)
  File "C:\Users\gauri\AppData\Local\Programs\Python\Python310\lib\site-packages\django\core\handlers\base.py", line 197, in _get_response
    response = wrapped_callback(request, *callback_args, **callback_kwargs)
TypeError: upload_files() missing 4 required positional arguments: 'folder_id', 'file_path', 'file_name', and 'mime_type'
[ERROR] 2025-10-22 12:49:09,159 | django.server | "POST /dashboard/contributor/submit_content/upload HTTP/1.1" 500 67967
[WARNING] 2025-10-22 12:52:00,505 | django.server | "GET /static/frontend/css/style_contro.css HTTP/1.1" 404 1901
[WARNING] 2025-10-22 12:52:00,505 | django.server | "GET /static/frontend/images/high-five.jpg HTTP/1.1" 404 1901
[WARNING] 2025-10-22 12:52:00,505 | django.server | "GET /static/frontend/js/contributor.js HTTP/1.1" 404 1892
[ERROR] 2025-10-22 12:52:26,522 | django.request | Internal Server Error: /dashboard/contributor/submit_content/upload
Traceback (most recent call last):
  File "C:\Users\gauri\AppData\Local\Programs\Python\Python310\lib\site-packages\django\core\handlers\exception.py", line 55, in inner
    response = get_response(request)
  File "C:\Users\gauri\AppData\Local\Programs\Python\Python310\lib\site-packages\django\core\handlers\base.py", line 197, in _get_response
    response = wrapped_callback(request, *callback_args, **callback_kwargs)
TypeError: upload_file() missing 4 required positional arguments: 'folder_id', 'file_path', 'file_name', and 'mime_type'
[ERROR] 2025-10-22 12:52:26,538 | django.server | "POST /dashboard/contributor/submit_content/upload HTTP/1.1" 500 67960
[WARNING] 2025-10-22 12:55:22,194 | django.server | "GET /static/frontend/js/contributor.js HTTP/1.1" 404 1892
[WARNING] 2025-10-22 12:55:22,194 | django.server | "GET /static/frontend/images/high-five.jpg HTTP/1.1" 404 1901
[WARNING] 2025-10-22 12:55:22,196 | django.server | "GET /static/frontend/css/style_contro.css HTTP/1.1" 404 1901
[INFO] 2025-10-22 12:55:44,939 | googleapiclient.discovery_cache | file_cache is only supported with oauth2client<4.0.0
[INFO] 2025-10-22 12:55:45,533 | google_auth_httplib2 | Refreshing credentials due to a 401 response. Attempt 1/2.
[ERROR] 2025-10-22 12:55:45,619 | django.request | Internal Server Error: /dashboard/contributor/submit_content/upload
Traceback (most recent call last):
  File "C:\Users\gauri\AppData\Local\Programs\Python\Python310\lib\site-packages\django\core\handlers\exception.py", line 55, in inner
    response = get_response(request)
  File "C:\Users\gauri\AppData\Local\Programs\Python\Python310\lib\site-packages\django\core\handlers\base.py", line 197, in _get_response
    response = wrapped_callback(request, *callback_args, **callback_kwargs)
  File "C:\Users\gauri\IdeaProjects\oer\accounts\views\contributor\submit_content.py", line 90, in upload_files
    oer_content_id = get_or_create_drive_folder(service, "oer_content")
  File "C:\Users\gauri\IdeaProjects\oer\accounts\views\contributor\submit_content.py", line 49, in get_or_create_drive_folder
    ).execute()
  File "C:\Users\gauri\AppData\Local\Programs\Python\Python310\lib\site-packages\googleapiclient\_helpers.py", line 130, in positional_wrapper
    return wrapped(*args, **kwargs)
  File "C:\Users\gauri\AppData\Local\Programs\Python\Python310\lib\site-packages\googleapiclient\http.py", line 923, in execute
    resp, content = _retry_request(
  File "C:\Users\gauri\AppData\Local\Programs\Python\Python310\lib\site-packages\googleapiclient\http.py", line 191, in _retry_request
    resp, content = http.request(uri, method, *args, **kwargs)
  File "C:\Users\gauri\AppData\Local\Programs\Python\Python310\lib\site-packages\google_auth_httplib2.py", line 245, in request
    self.credentials.refresh(self._request)
  File "C:\Users\gauri\AppData\Local\Programs\Python\Python310\lib\site-packages\google\oauth2\credentials.py", line 397, in refresh
    raise exceptions.RefreshError(
google.auth.exceptions.RefreshError: The credentials do not contain the necessary fields need to refresh the access token. You must specify refresh_token, token_uri, client_id, and client_secret.
[ERROR] 2025-10-22 12:55:45,619 | django.server | "POST /dashboard/contributor/submit_content/upload HTTP/1.1" 500 103866
[WARNING] 2025-10-22 12:56:57,709 | django.server | "GET /static/frontend/images/high-five.jpg HTTP/1.1" 404 1901
[WARNING] 2025-10-22 12:56:57,709 | django.server | "GET /static/frontend/css/style_contro.css HTTP/1.1" 404 1901
[WARNING] 2025-10-22 12:56:57,714 | django.server | "GET /static/frontend/js/contributor.js HTTP/1.1" 404 1892
[INFO] 2025-10-22 12:57:20,714 | googleapiclient.discovery_cache | file_cache is only supported with oauth2client<4.0.0
[INFO] 2025-10-22 12:57:21,212 | google_auth_httplib2 | Refreshing credentials due to a 401 response. Attempt 1/2.
[WARNING] 2025-10-22 12:57:22,010 | googleapiclient.http | Encountered 403 Forbidden with reason "teamDriveIdRequiresTeamDriveCorpora"
[ERROR] 2025-10-22 12:57:22,159 | django.request | Internal Server Error: /dashboard/contributor/submit_content/upload
Traceback (most recent call last):
  File "C:\Users\gauri\AppData\Local\Programs\Python\Python310\lib\site-packages\django\core\handlers\exception.py", line 55, in inner
    response = get_response(request)
  File "C:\Users\gauri\AppData\Local\Programs\Python\Python310\lib\site-packages\django\core\handlers\base.py", line 197, in _get_response
    response = wrapped_callback(request, *callback_args, **callback_kwargs)
  File "C:\Users\gauri\IdeaProjects\oer\accounts\views\contributor\submit_content.py", line 91, in upload_files
    oer_content_id = get_or_create_drive_folder(service, "oer_content")
  File "C:\Users\gauri\IdeaProjects\oer\accounts\views\contributor\submit_content.py", line 50, in get_or_create_drive_folder
    ).execute()
  File "C:\Users\gauri\AppData\Local\Programs\Python\Python310\lib\site-packages\googleapiclient\_helpers.py", line 130, in positional_wrapper
    return wrapped(*args, **kwargs)
  File "C:\Users\gauri\AppData\Local\Programs\Python\Python310\lib\site-packages\googleapiclient\http.py", line 938, in execute
    raise HttpError(resp, content, uri=self.uri)
googleapiclient.errors.HttpError: <HttpError 403 when requesting https://www.googleapis.com/drive/v3/files?q=mimeType%3D%27application%2Fvnd.google-apps.folder%27+and+name%3D%27oer_content%27&spaces=drive&corpora=drive&includeItemsFromAllDrives=true&supportsAllDrives=true&fields=files%28id%2C+name%29&alt=json returned "The driveId parameter must be specified if and only if corpora is set to drive.". Details: "[{'message': 'The driveId parameter must be specified if and only if corpora is set to drive.', 'domain': 'global', 'reason': 'teamDriveIdRequiresTeamDriveCorpora'}]">
[ERROR] 2025-10-22 12:57:22,167 | django.server | "POST /dashboard/contributor/submit_content/upload HTTP/1.1" 500 88541
[WARNING] 2025-10-22 12:59:06,959 | django.server | "GET /static/frontend/css/style_contro.css HTTP/1.1" 404 1901
[WARNING] 2025-10-22 12:59:06,961 | django.server | "GET /static/frontend/images/high-five.jpg HTTP/1.1" 404 1901
[WARNING] 2025-10-22 12:59:06,961 | django.server | "GET /static/frontend/js/contributor.js HTTP/1.1" 404 1892
[INFO] 2025-10-22 12:59:28,259 | googleapiclient.discovery_cache | file_cache is only supported with oauth2client<4.0.0
[INFO] 2025-10-22 12:59:28,884 | google_auth_httplib2 | Refreshing credentials due to a 401 response. Attempt 1/2.
[ERROR] 2025-10-22 12:59:34,550 | django.request | Internal Server Error: /dashboard/contributor/submit_content/upload
Traceback (most recent call last):
  File "C:\Users\gauri\AppData\Local\Programs\Python\Python310\lib\site-packages\django\core\handlers\exception.py", line 55, in inner
    response = get_response(request)
  File "C:\Users\gauri\AppData\Local\Programs\Python\Python310\lib\site-packages\django\core\handlers\base.py", line 197, in _get_response
    response = wrapped_callback(request, *callback_args, **callback_kwargs)
  File "C:\Users\gauri\IdeaProjects\oer\accounts\views\contributor\submit_content.py", line 108, in upload_files
    os.remove(temp_path)
PermissionError: [WinError 32] The process cannot access the file because it is being used by another process: 'C:\\Users\\gauri\\AppData\\Local\\Temp\\Sample Questions for DBMS IAT-1.pdf'
[ERROR] 2025-10-22 12:59:34,550 | django.server | "POST /dashboard/contributor/submit_content/upload HTTP/1.1" 500 79990
[INFO] 2025-10-22 13:00:18,573 | googleapiclient.discovery_cache | file_cache is only supported with oauth2client<4.0.0
[INFO] 2025-10-22 13:00:18,618 | googleapiclient.discovery_cache | file_cache is only supported with oauth2client<4.0.0
[INFO] 2025-10-22 13:00:18,960 | google_auth_httplib2 | Refreshing credentials due to a 401 response. Attempt 1/2.
[INFO] 2025-10-22 13:00:18,960 | google_auth_httplib2 | Refreshing credentials due to a 401 response. Attempt 1/2.
[ERROR] 2025-10-22 13:00:24,519 | django.request | Internal Server Error: /dashboard/contributor/submit_content/upload
Traceback (most recent call last):
  File "C:\Users\gauri\AppData\Local\Programs\Python\Python310\lib\site-packages\django\core\handlers\exception.py", line 55, in inner
    response = get_response(request)
  File "C:\Users\gauri\AppData\Local\Programs\Python\Python310\lib\site-packages\django\core\handlers\base.py", line 197, in _get_response
    response = wrapped_callback(request, *callback_args, **callback_kwargs)
  File "C:\Users\gauri\IdeaProjects\oer\accounts\views\contributor\submit_content.py", line 108, in upload_files
    os.remove(temp_path)
PermissionError: [WinError 32] The process cannot access the file because it is being used by another process: 'C:\\Users\\gauri\\AppData\\Local\\Temp\\Sample Questions for DBMS IAT-1.pdf'
[ERROR] 2025-10-22 13:00:24,519 | django.server | "POST /dashboard/contributor/submit_content/upload HTTP/1.1" 500 79962
[ERROR] 2025-10-22 13:00:24,718 | django.request | Internal Server Error: /dashboard/contributor/submit_content/upload
Traceback (most recent call last):
  File "C:\Users\gauri\AppData\Local\Programs\Python\Python310\lib\site-packages\django\core\handlers\exception.py", line 55, in inner
    response = get_response(request)
  File "C:\Users\gauri\AppData\Local\Programs\Python\Python310\lib\site-packages\django\core\handlers\base.py", line 197, in _get_response
    response = wrapped_callback(request, *callback_args, **callback_kwargs)
  File "C:\Users\gauri\IdeaProjects\oer\accounts\views\contributor\submit_content.py", line 108, in upload_files
    os.remove(temp_path)
PermissionError: [WinError 32] The process cannot access the file because it is being used by another process: 'C:\\Users\\gauri\\AppData\\Local\\Temp\\Sample Questions for DBMS IAT-1.pdf'
[ERROR] 2025-10-22 13:00:24,718 | django.server | "POST /dashboard/contributor/submit_content/upload HTTP/1.1" 500 79962
[INFO] 2025-10-22 13:00:44,149 | googleapiclient.discovery_cache | file_cache is only supported with oauth2client<4.0.0
[INFO] 2025-10-22 13:00:44,166 | googleapiclient.discovery_cache | file_cache is only supported with oauth2client<4.0.0
[INFO] 2025-10-22 13:00:44,166 | googleapiclient.discovery_cache | file_cache is only supported with oauth2client<4.0.0
[INFO] 2025-10-22 13:00:44,563 | google_auth_httplib2 | Refreshing credentials due to a 401 response. Attempt 1/2.
[INFO] 2025-10-22 13:00:44,563 | google_auth_httplib2 | Refreshing credentials due to a 401 response. Attempt 1/2.
[INFO] 2025-10-22 13:00:44,563 | google_auth_httplib2 | Refreshing credentials due to a 401 response. Attempt 1/2.
[ERROR] 2025-10-22 13:00:50,259 | django.request | Internal Server Error: /dashboard/contributor/submit_content/upload
Traceback (most recent call last):
  File "C:\Users\gauri\AppData\Local\Programs\Python\Python310\lib\site-packages\django\core\handlers\exception.py", line 55, in inner
    response = get_response(request)
  File "C:\Users\gauri\AppData\Local\Programs\Python\Python310\lib\site-packages\django\core\handlers\base.py", line 197, in _get_response
    response = wrapped_callback(request, *callback_args, **callback_kwargs)
  File "C:\Users\gauri\IdeaProjects\oer\accounts\views\contributor\submit_content.py", line 108, in upload_files
    os.remove(temp_path)
PermissionError: [WinError 32] The process cannot access the file because it is being used by another process: 'C:\\Users\\gauri\\AppData\\Local\\Temp\\Sample Questions for DBMS IAT-1.pdf'
[ERROR] 2025-10-22 13:00:50,259 | django.server | "POST /dashboard/contributor/submit_content/upload HTTP/1.1" 500 79962
[ERROR] 2025-10-22 13:00:51,885 | django.request | Internal Server Error: /dashboard/contributor/submit_content/upload
Traceback (most recent call last):
  File "C:\Users\gauri\AppData\Local\Programs\Python\Python310\lib\site-packages\django\core\handlers\exception.py", line 55, in inner
    response = get_response(request)
  File "C:\Users\gauri\AppData\Local\Programs\Python\Python310\lib\site-packages\django\core\handlers\base.py", line 197, in _get_response
    response = wrapped_callback(request, *callback_args, **callback_kwargs)
  File "C:\Users\gauri\IdeaProjects\oer\accounts\views\contributor\submit_content.py", line 108, in upload_files
    os.remove(temp_path)
PermissionError: [WinError 32] The process cannot access the file because it is being used by another process: 'C:\\Users\\gauri\\AppData\\Local\\Temp\\Sample Questions for DBMS IAT-1.pdf'
[ERROR] 2025-10-22 13:00:51,888 | django.server | "POST /dashboard/contributor/submit_content/upload HTTP/1.1" 500 79962
[ERROR] 2025-10-22 13:00:52,166 | django.request | Internal Server Error: /dashboard/contributor/submit_content/upload
Traceback (most recent call last):
  File "C:\Users\gauri\AppData\Local\Programs\Python\Python310\lib\site-packages\django\core\handlers\exception.py", line 55, in inner
    response = get_response(request)
  File "C:\Users\gauri\AppData\Local\Programs\Python\Python310\lib\site-packages\django\core\handlers\base.py", line 197, in _get_response
    response = wrapped_callback(request, *callback_args, **callback_kwargs)
  File "C:\Users\gauri\IdeaProjects\oer\accounts\views\contributor\submit_content.py", line 108, in upload_files
    os.remove(temp_path)
PermissionError: [WinError 32] The process cannot access the file because it is being used by another process: 'C:\\Users\\gauri\\AppData\\Local\\Temp\\Sample Questions for DBMS IAT-1.pdf'
[ERROR] 2025-10-22 13:00:52,172 | django.server | "POST /dashboard/contributor/submit_content/upload HTTP/1.1" 500 79962
[WARNING] 2025-10-22 13:04:05,879 | django.server | "GET /static/frontend/css/style_contro.css HTTP/1.1" 404 1901
[WARNING] 2025-10-22 13:04:05,879 | django.server | "GET /static/frontend/images/high-five.jpg HTTP/1.1" 404 1901
[WARNING] 2025-10-22 13:04:05,888 | django.server | "GET /static/frontend/js/contributor.js HTTP/1.1" 404 1892
[INFO] 2025-10-22 13:04:31,912 | googleapiclient.discovery_cache | file_cache is only supported with oauth2client<4.0.0
[INFO] 2025-10-22 13:04:32,414 | google_auth_httplib2 | Refreshing credentials due to a 401 response. Attempt 1/2.
[ERROR] 2025-10-22 13:04:39,272 | django.request | Internal Server Error: /dashboard/contributor/submit_content/upload
Traceback (most recent call last):
  File "C:\Users\gauri\AppData\Local\Programs\Python\Python310\lib\site-packages\django\core\handlers\exception.py", line 55, in inner
    response = get_response(request)
  File "C:\Users\gauri\AppData\Local\Programs\Python\Python310\lib\site-packages\django\core\handlers\base.py", line 197, in _get_response
    response = wrapped_callback(request, *callback_args, **callback_kwargs)
  File "C:\Users\gauri\IdeaProjects\oer\accounts\views\contributor\submit_content.py", line 114, in upload_files
    os.remove(temp_path)
PermissionError: [WinError 32] The process cannot access the file because it is being used by another process: 'C:\\Users\\gauri\\AppData\\Local\\Temp\\SQL – DML Commands.pdf'
[ERROR] 2025-10-22 13:04:39,287 | django.server | "POST /dashboard/contributor/submit_content/upload HTTP/1.1" 500 80001
[WARNING] 2025-10-22 13:08:11,340 | django.server | "GET /static/frontend/js/contributor.js HTTP/1.1" 404 1892
[WARNING] 2025-10-22 13:08:11,360 | django.server | "GET /static/frontend/css/style_contro.css HTTP/1.1" 404 1901
[WARNING] 2025-10-22 13:08:11,360 | django.server | "GET /static/frontend/images/high-five.jpg HTTP/1.1" 404 1901
[INFO] 2025-10-22 13:08:19,849 | googleapiclient.discovery_cache | file_cache is only supported with oauth2client<4.0.0
[INFO] 2025-10-22 13:08:20,473 | google_auth_httplib2 | Refreshing credentials due to a 401 response. Attempt 1/2.
[ERROR] 2025-10-22 13:08:26,331 | django.request | Internal Server Error: /dashboard/contributor/submit_content/upload
Traceback (most recent call last):
  File "C:\Users\gauri\AppData\Local\Programs\Python\Python310\lib\site-packages\django\core\handlers\exception.py", line 55, in inner
    response = get_response(request)
  File "C:\Users\gauri\AppData\Local\Programs\Python\Python310\lib\site-packages\django\core\handlers\base.py", line 197, in _get_response
    response = wrapped_callback(request, *callback_args, **callback_kwargs)
  File "C:\Users\gauri\IdeaProjects\oer\accounts\views\contributor\submit_content.py", line 114, in upload_files
    os.remove(temp_path)
PermissionError: [WinError 32] The process cannot access the file because it is being used by another process: 'C:\\Users\\gauri\\AppData\\Local\\Temp\\DBMS QBANK IAT2 previous year.pdf'
[ERROR] 2025-10-22 13:08:26,342 | django.server | "POST /dashboard/contributor/submit_content/upload HTTP/1.1" 500 80116
[WARNING] 2025-10-22 13:09:10,317 | django.server | "GET /static/frontend/css/style_contro.css HTTP/1.1" 404 1901
[WARNING] 2025-10-22 13:09:10,317 | django.server | "GET /static/frontend/js/contributor.js HTTP/1.1" 404 1892
[WARNING] 2025-10-22 13:09:10,317 | django.server | "GET /static/frontend/images/high-five.jpg HTTP/1.1" 404 1901
[INFO] 2025-10-22 13:09:25,590 | googleapiclient.discovery_cache | file_cache is only supported with oauth2client<4.0.0
[INFO] 2025-10-22 13:09:26,087 | google_auth_httplib2 | Refreshing credentials due to a 401 response. Attempt 1/2.
[ERROR] 2025-10-22 13:09:38,799 | django.request | Internal Server Error: /dashboard/contributor/submit_content/upload
Traceback (most recent call last):
  File "C:\Users\gauri\AppData\Local\Programs\Python\Python310\lib\site-packages\django\core\handlers\exception.py", line 55, in inner
    response = get_response(request)
  File "C:\Users\gauri\AppData\Local\Programs\Python\Python310\lib\site-packages\django\core\handlers\base.py", line 197, in _get_response
    response = wrapped_callback(request, *callback_args, **callback_kwargs)
  File "C:\Users\gauri\IdeaProjects\oer\accounts\views\contributor\submit_content.py", line 133, in upload_files
    os.remove(temp_path)
PermissionError: [WinError 32] The process cannot access the file because it is being used by another process: 'C:\\Users\\gauri\\AppData\\Local\\Temp\\Login Page - Google Chrome 2024-05-07 11-59-26.mp4'
[ERROR] 2025-10-22 13:09:38,811 | django.server | "POST /dashboard/contributor/submit_content/upload HTTP/1.1" 500 80109
[WARNING] 2025-10-22 13:37:01,611 | django.server | "GET /static/frontend/css/style_contro.css HTTP/1.1" 404 1901
[WARNING] 2025-10-22 13:37:01,611 | django.server | "GET /static/frontend/js/contributor.js HTTP/1.1" 404 1892
[WARNING] 2025-10-22 13:37:01,611 | django.server | "GET /static/frontend/images/high-five.jpg HTTP/1.1" 404 1901
[WARNING] 2025-10-22 13:37:12,641 | django.server | "GET /static/frontend/css/style_contro.css HTTP/1.1" 404 1901
[WARNING] 2025-10-22 13:37:12,651 | django.server | "GET /static/frontend/js/contributor.js HTTP/1.1" 404 1892
[WARNING] 2025-10-22 13:37:12,668 | django.server | "GET /static/frontend/images/high-five.jpg HTTP/1.1" 404 1901
[INFO] 2025-10-22 13:37:25,522 | googleapiclient.discovery_cache | file_cache is only supported with oauth2client<4.0.0
[INFO] 2025-10-22 13:37:26,120 | google_auth_httplib2 | Refreshing credentials due to a 401 response. Attempt 1/2.
[ERROR] 2025-10-22 13:37:34,256 | django.request | Internal Server Error: /dashboard/contributor/submit_content/upload
Traceback (most recent call last):
  File "C:\Users\gauri\AppData\Local\Programs\Python\Python310\lib\site-packages\django\core\handlers\exception.py", line 55, in inner
    response = get_response(request)
  File "C:\Users\gauri\AppData\Local\Programs\Python\Python310\lib\site-packages\django\core\handlers\base.py", line 197, in _get_response
    response = wrapped_callback(request, *callback_args, **callback_kwargs)
  File "C:\Users\gauri\IdeaProjects\oer\accounts\views\contributor\submit_content.py", line 114, in upload_files
    os.remove(temp_path)
PermissionError: [WinError 32] The process cannot access the file because it is being used by another process: 'C:\\Users\\gauri\\AppData\\Local\\Temp\\Checkpoints DB recovery.pdf'
[ERROR] 2025-10-22 13:37:34,256 | django.server | "POST /dashboard/contributor/submit_content/upload HTTP/1.1" 500 80171
[WARNING] 2025-10-22 13:52:27,714 | django.server | "GET /static/frontend/images/high-five.jpg HTTP/1.1" 404 1901
[WARNING] 2025-10-22 13:52:27,714 | django.server | "GET /static/frontend/css/style_contro.css HTTP/1.1" 404 1901
[WARNING] 2025-10-22 13:52:27,720 | django.server | "GET /static/frontend/js/contributor.js HTTP/1.1" 404 1892
[WARNING] 2025-10-22 13:52:33,271 | django.server | "GET /static/frontend/css/style_contro.css HTTP/1.1" 404 1901
[WARNING] 2025-10-22 13:52:33,271 | django.server | "GET /static/frontend/images/high-five.jpg HTTP/1.1" 404 1901
[WARNING] 2025-10-22 13:52:33,271 | django.server | "GET /static/frontend/js/contributor.js HTTP/1.1" 404 1892
[INFO] 2025-10-22 13:52:43,981 | googleapiclient.discovery_cache | file_cache is only supported with oauth2client<4.0.0
[INFO] 2025-10-22 13:52:44,479 | google_auth_httplib2 | Refreshing credentials due to a 401 response. Attempt 1/2.
[WARNING] 2025-10-22 13:55:58,891 | django.server | "GET /static/frontend/js/contributor.js HTTP/1.1" 404 1892
[WARNING] 2025-10-22 13:55:58,899 | django.server | "GET /static/frontend/css/style_contro.css HTTP/1.1" 404 1901
[WARNING] 2025-10-22 13:55:58,899 | django.server | "GET /static/frontend/images/high-five.jpg HTTP/1.1" 404 1901
[WARNING] 2025-10-22 13:56:16,395 | django.server | "GET /static/frontend/css/style_contro.css HTTP/1.1" 404 1901
[WARNING] 2025-10-22 13:56:23,698 | django.server | "GET /static/frontend/images/high-five.jpg HTTP/1.1" 404 1901
[WARNING] 2025-10-22 13:56:23,698 | django.server | "GET /static/frontend/css/style_contro.css HTTP/1.1" 404 1901
[WARNING] 2025-10-22 13:56:23,979 | django.server | "GET /static/frontend/js/contributor.js HTTP/1.1" 404 1892
[INFO] 2025-10-22 13:56:37,135 | googleapiclient.discovery_cache | file_cache is only supported with oauth2client<4.0.0
[INFO] 2025-10-22 13:56:37,727 | google_auth_httplib2 | Refreshing credentials due to a 401 response. Attempt 1/2.
[INFO] 2025-10-22 13:57:26,383 | googleapiclient.discovery_cache | file_cache is only supported with oauth2client<4.0.0
[INFO] 2025-10-22 13:57:26,434 | googleapiclient.discovery_cache | file_cache is only supported with oauth2client<4.0.0
[INFO] 2025-10-22 13:57:26,981 | google_auth_httplib2 | Refreshing credentials due to a 401 response. Attempt 1/2.
[INFO] 2025-10-22 13:57:26,984 | google_auth_httplib2 | Refreshing credentials due to a 401 response. Attempt 1/2.
[WARNING] 2025-10-22 14:03:52,707 | django.server | "GET /static/frontend/js/contributor.js HTTP/1.1" 404 1892
[WARNING] 2025-10-22 14:03:52,710 | django.server | "GET /static/frontend/css/style_contro.css HTTP/1.1" 404 1901
[WARNING] 2025-10-22 14:03:52,711 | django.server | "GET /static/frontend/images/high-five.jpg HTTP/1.1" 404 1901
[INFO] 2025-10-22 14:04:27,535 | googleapiclient.discovery_cache | file_cache is only supported with oauth2client<4.0.0
[INFO] 2025-10-22 14:04:28,059 | google_auth_httplib2 | Refreshing credentials due to a 401 response. Attempt 1/2.
[INFO] 2025-10-22 14:04:38,109 | googleapiclient.discovery_cache | file_cache is only supported with oauth2client<4.0.0
[INFO] 2025-10-22 14:04:38,607 | google_auth_httplib2 | Refreshing credentials due to a 401 response. Attempt 1/2.
[INFO] 2025-10-22 14:06:22,076 | googleapiclient.discovery_cache | file_cache is only supported with oauth2client<4.0.0
[INFO] 2025-10-22 14:06:23,237 | google_auth_httplib2 | Refreshing credentials due to a 401 response. Attempt 1/2.
[INFO] 2025-10-22 14:08:11,481 | googleapiclient.discovery_cache | file_cache is only supported with oauth2client<4.0.0
[INFO] 2025-10-22 14:08:11,994 | google_auth_httplib2 | Refreshing credentials due to a 401 response. Attempt 1/2.
[INFO] 2025-10-22 14:08:12,681 | googleapiclient.discovery_cache | file_cache is only supported with oauth2client<4.0.0
[INFO] 2025-10-22 14:08:13,141 | google_auth_httplib2 | Refreshing credentials due to a 401 response. Attempt 1/2.
[INFO] 2025-10-22 14:08:15,179 | googleapiclient.discovery_cache | file_cache is only supported with oauth2client<4.0.0
[INFO] 2025-10-22 14:08:15,599 | google_auth_httplib2 | Refreshing credentials due to a 401 response. Attempt 1/2.
[WARNING] 2025-10-22 19:03:08,344 | django.request | Not Found: /favicon.ico
[WARNING] 2025-10-22 19:03:08,349 | django.server | "GET /favicon.ico HTTP/1.1" 404 4912
[WARNING] 2025-10-22 19:03:15,648 | django.server | "GET /static/frontend/css/style_contro.css HTTP/1.1" 404 1901
[WARNING] 2025-10-22 19:03:21,427 | django.server | "GET /static/frontend/css/style_contro.css HTTP/1.1" 404 1901
[WARNING] 2025-10-22 19:03:21,429 | django.server | "GET /static/frontend/js/contributor.js HTTP/1.1" 404 1892
[WARNING] 2025-10-22 19:03:21,435 | django.server | "GET /static/frontend/images/high-five.jpg HTTP/1.1" 404 1901
[INFO] 2025-10-22 19:03:42,258 | googleapiclient.discovery_cache | file_cache is only supported with oauth2client<4.0.0
[INFO] 2025-10-22 19:03:42,905 | google_auth_httplib2 | Refreshing credentials due to a 401 response. Attempt 1/2.
[INFO] 2025-10-22 19:03:48,330 | googleapiclient.discovery_cache | file_cache is only supported with oauth2client<4.0.0
[INFO] 2025-10-22 19:03:48,794 | google_auth_httplib2 | Refreshing credentials due to a 401 response. Attempt 1/2.
[ERROR] 2025-10-22 19:05:43,753 | django.request | Internal Server Error: /dashboard/contributor/submit_content/upload
Traceback (most recent call last):
  File "C:\Users\gauri\AppData\Local\Programs\Python\Python310\lib\site-packages\django\core\handlers\exception.py", line 55, in inner
    response = get_response(request)
  File "C:\Users\gauri\AppData\Local\Programs\Python\Python310\lib\site-packages\django\core\handlers\base.py", line 197, in _get_response
    response = wrapped_callback(request, *callback_args, **callback_kwargs)
  File "C:\Users\gauri\AppData\Local\Programs\Python\Python310\lib\site-packages\django\views\decorators\csrf.py", line 65, in _view_wrapper
    return view_func(request, *args, **kwargs)
  File "C:\Users\gauri\IdeaProjects\oer\accounts\views\contributor\submit_content.py", line 121, in upload_files
    service.files().create(
  File "C:\Users\gauri\AppData\Local\Programs\Python\Python310\lib\site-packages\googleapiclient\discovery.py", line 1242, in method
    payload = media_upload.getbytes(0, media_upload.size())
  File "C:\Users\gauri\AppData\Local\Programs\Python\Python310\lib\site-packages\googleapiclient\http.py", line 524, in getbytes
    return self._fd.read(length)
OSError: [Errno 22] Invalid argument
[ERROR] 2025-10-22 19:05:43,872 | django.server | "POST /dashboard/contributor/submit_content/upload HTTP/1.1" 500 103599
[ERROR] 2025-10-22 19:05:45,726 | django.request | Internal Server Error: /dashboard/contributor/submit_content/upload
Traceback (most recent call last):
  File "C:\Users\gauri\AppData\Local\Programs\Python\Python310\lib\site-packages\django\core\handlers\exception.py", line 55, in inner
    response = get_response(request)
  File "C:\Users\gauri\AppData\Local\Programs\Python\Python310\lib\site-packages\django\core\handlers\base.py", line 197, in _get_response
    response = wrapped_callback(request, *callback_args, **callback_kwargs)
  File "C:\Users\gauri\AppData\Local\Programs\Python\Python310\lib\site-packages\django\views\decorators\csrf.py", line 65, in _view_wrapper
    return view_func(request, *args, **kwargs)
  File "C:\Users\gauri\IdeaProjects\oer\accounts\views\contributor\submit_content.py", line 121, in upload_files
    service.files().create(
  File "C:\Users\gauri\AppData\Local\Programs\Python\Python310\lib\site-packages\googleapiclient\discovery.py", line 1242, in method
    payload = media_upload.getbytes(0, media_upload.size())
  File "C:\Users\gauri\AppData\Local\Programs\Python\Python310\lib\site-packages\googleapiclient\http.py", line 524, in getbytes
    return self._fd.read(length)
OSError: [Errno 22] Invalid argument
[ERROR] 2025-10-22 19:05:45,726 | django.server | "POST /dashboard/contributor/submit_content/upload HTTP/1.1" 500 103599
[WARNING] 2025-10-22 19:08:44,952 | django.server | "GET /static/frontend/images/high-five.jpg HTTP/1.1" 404 1901
[WARNING] 2025-10-22 19:08:44,954 | django.server | "GET /static/frontend/css/style_contro.css HTTP/1.1" 404 1901
[WARNING] 2025-10-22 19:08:44,954 | django.server | "GET /static/frontend/js/contributor.js HTTP/1.1" 404 1892
[INFO] 2025-10-22 19:09:05,306 | googleapiclient.discovery_cache | file_cache is only supported with oauth2client<4.0.0
[INFO] 2025-10-22 19:09:05,839 | google_auth_httplib2 | Refreshing credentials due to a 401 response. Attempt 1/2.
[ERROR] 2025-10-22 19:10:32,860 | django.request | Internal Server Error: /dashboard/contributor/submit_content/upload
Traceback (most recent call last):
  File "C:\Users\gauri\AppData\Local\Programs\Python\Python310\lib\site-packages\django\core\handlers\exception.py", line 55, in inner
    response = get_response(request)
  File "C:\Users\gauri\AppData\Local\Programs\Python\Python310\lib\site-packages\django\core\handlers\base.py", line 197, in _get_response
    response = wrapped_callback(request, *callback_args, **callback_kwargs)
  File "C:\Users\gauri\AppData\Local\Programs\Python\Python310\lib\site-packages\django\views\decorators\csrf.py", line 65, in _view_wrapper
    return view_func(request, *args, **kwargs)
  File "C:\Users\gauri\IdeaProjects\oer\accounts\views\contributor\submit_content.py", line 106, in upload_files
    service.files().create(
  File "C:\Users\gauri\AppData\Local\Programs\Python\Python310\lib\site-packages\googleapiclient\discovery.py", line 1249, in method
    g.flatten(msgRoot, unixfrom=False)
  File "C:\Users\gauri\AppData\Local\Programs\Python\Python310\lib\email\generator.py", line 116, in flatten
    self._write(msg)
  File "C:\Users\gauri\AppData\Local\Programs\Python\Python310\lib\email\generator.py", line 181, in _write
    self._dispatch(msg)
  File "C:\Users\gauri\AppData\Local\Programs\Python\Python310\lib\email\generator.py", line 218, in _dispatch
    meth(msg)
  File "C:\Users\gauri\AppData\Local\Programs\Python\Python310\lib\email\generator.py", line 276, in _handle_multipart
    g.flatten(part, unixfrom=False, linesep=self._NL)
  File "C:\Users\gauri\AppData\Local\Programs\Python\Python310\lib\email\generator.py", line 116, in flatten
    self._write(msg)
  File "C:\Users\gauri\AppData\Local\Programs\Python\Python310\lib\email\generator.py", line 181, in _write
    self._dispatch(msg)
  File "C:\Users\gauri\AppData\Local\Programs\Python\Python310\lib\email\generator.py", line 218, in _dispatch
    meth(msg)
  File "C:\Users\gauri\AppData\Local\Programs\Python\Python310\lib\email\generator.py", line 431, in _handle_text
    if _has_surrogates(msg._payload) and not self.policy.cte_type=='7bit':
  File "C:\Users\gauri\AppData\Local\Programs\Python\Python310\lib\email\utils.py", line 57, in _has_surrogates
    s.encode()
MemoryError
[ERROR] 2025-10-22 19:10:32,972 | django.server | "POST /dashboard/contributor/submit_content/upload HTTP/1.1" 500 141108
[INFO] 2025-10-22 19:11:29,556 | googleapiclient.discovery_cache | file_cache is only supported with oauth2client<4.0.0
[INFO] 2025-10-22 19:11:29,556 | googleapiclient.discovery_cache | file_cache is only supported with oauth2client<4.0.0
[INFO] 2025-10-22 19:11:30,187 | google_auth_httplib2 | Refreshing credentials due to a 401 response. Attempt 1/2.
[INFO] 2025-10-22 19:11:30,187 | google_auth_httplib2 | Refreshing credentials due to a 401 response. Attempt 1/2.
[ERROR] 2025-10-22 19:11:53,822 | django.request | Internal Server Error: /dashboard/contributor/submit_content/upload
Traceback (most recent call last):
  File "C:\Users\gauri\AppData\Local\Programs\Python\Python310\lib\site-packages\django\core\handlers\exception.py", line 55, in inner
    response = get_response(request)
  File "C:\Users\gauri\AppData\Local\Programs\Python\Python310\lib\site-packages\django\core\handlers\base.py", line 197, in _get_response
    response = wrapped_callback(request, *callback_args, **callback_kwargs)
  File "C:\Users\gauri\AppData\Local\Programs\Python\Python310\lib\site-packages\django\views\decorators\csrf.py", line 65, in _view_wrapper
    return view_func(request, *args, **kwargs)
  File "C:\Users\gauri\IdeaProjects\oer\accounts\views\contributor\submit_content.py", line 68, in upload_files
    pdf_files = request.FILES.getlist('pdf_file')
  File "C:\Users\gauri\AppData\Local\Programs\Python\Python310\lib\site-packages\django\core\handlers\wsgi.py", line 107, in FILES
    self._load_post_and_files()
  File "C:\Users\gauri\AppData\Local\Programs\Python\Python310\lib\site-packages\django\http\request.py", line 425, in _load_post_and_files
    self._post, self._files = self.parse_file_upload(self.META, data)
  File "C:\Users\gauri\AppData\Local\Programs\Python\Python310\lib\site-packages\django\http\request.py", line 373, in parse_file_upload
    return parser.parse()
  File "C:\Users\gauri\AppData\Local\Programs\Python\Python310\lib\site-packages\django\http\multipartparser.py", line 125, in parse
    return self._parse()
  File "C:\Users\gauri\AppData\Local\Programs\Python\Python310\lib\site-packages\django\http\multipartparser.py", line 328, in _parse
    chunk = handler.receive_data_chunk(chunk, counters[i])
  File "C:\Users\gauri\AppData\Local\Programs\Python\Python310\lib\site-packages\django\core\files\uploadhandler.py", line 176, in receive_data_chunk
    self.file.write(raw_data)
OSError: [Errno 28] No space left on device
[ERROR] 2025-10-22 19:11:53,822 | django.request | Internal Server Error: /dashboard/contributor/submit_content/upload
Traceback (most recent call last):
  File "C:\Users\gauri\AppData\Local\Programs\Python\Python310\lib\site-packages\django\core\handlers\exception.py", line 55, in inner
    response = get_response(request)
  File "C:\Users\gauri\AppData\Local\Programs\Python\Python310\lib\site-packages\django\core\handlers\base.py", line 197, in _get_response
    response = wrapped_callback(request, *callback_args, **callback_kwargs)
  File "C:\Users\gauri\AppData\Local\Programs\Python\Python310\lib\site-packages\django\views\decorators\csrf.py", line 65, in _view_wrapper
    return view_func(request, *args, **kwargs)
  File "C:\Users\gauri\IdeaProjects\oer\accounts\views\contributor\submit_content.py", line 68, in upload_files
    pdf_files = request.FILES.getlist('pdf_file')
  File "C:\Users\gauri\AppData\Local\Programs\Python\Python310\lib\site-packages\django\core\handlers\wsgi.py", line 107, in FILES
    self._load_post_and_files()
  File "C:\Users\gauri\AppData\Local\Programs\Python\Python310\lib\site-packages\django\http\request.py", line 425, in _load_post_and_files
    self._post, self._files = self.parse_file_upload(self.META, data)
  File "C:\Users\gauri\AppData\Local\Programs\Python\Python310\lib\site-packages\django\http\request.py", line 373, in parse_file_upload
    return parser.parse()
  File "C:\Users\gauri\AppData\Local\Programs\Python\Python310\lib\site-packages\django\http\multipartparser.py", line 125, in parse
    return self._parse()
  File "C:\Users\gauri\AppData\Local\Programs\Python\Python310\lib\site-packages\django\http\multipartparser.py", line 328, in _parse
    chunk = handler.receive_data_chunk(chunk, counters[i])
  File "C:\Users\gauri\AppData\Local\Programs\Python\Python310\lib\site-packages\django\core\files\uploadhandler.py", line 176, in receive_data_chunk
    self.file.write(raw_data)
OSError: [Errno 28] No space left on device
[ERROR] 2025-10-22 19:12:23,629 | django.server | "POST /dashboard/contributor/submit_content/upload HTTP/1.1" 500 119515
[ERROR] 2025-10-22 19:12:23,630 | django.server | "POST /dashboard/contributor/submit_content/upload HTTP/1.1" 500 119515
[WARNING] 2025-10-22 19:19:51,563 | django.server | "GET /static/frontend/css/style_contro.css HTTP/1.1" 404 1901
[WARNING] 2025-10-22 19:19:51,579 | django.server | "GET /static/frontend/js/contributor.js HTTP/1.1" 404 1892
[WARNING] 2025-10-22 19:19:51,579 | django.server | "GET /static/frontend/images/high-five.jpg HTTP/1.1" 404 1901
[INFO] 2025-10-22 19:20:06,290 | googleapiclient.discovery_cache | file_cache is only supported with oauth2client<4.0.0
[INFO] 2025-10-22 19:20:06,982 | google_auth_httplib2 | Refreshing credentials due to a 401 response. Attempt 1/2.
[INFO] 2025-10-22 19:22:18,137 | googleapiclient.discovery_cache | file_cache is only supported with oauth2client<4.0.0
[INFO] 2025-10-22 19:22:21,439 | google_auth_httplib2 | Refreshing credentials due to a 401 response. Attempt 1/2.
[INFO] 2025-10-22 19:22:47,519 | googleapiclient.discovery_cache | file_cache is only supported with oauth2client<4.0.0
[INFO] 2025-10-22 19:22:48,034 | google_auth_httplib2 | Refreshing credentials due to a 401 response. Attempt 1/2.
[INFO] 2025-10-22 19:22:48,435 | googleapiclient.discovery_cache | file_cache is only supported with oauth2client<4.0.0
[INFO] 2025-10-22 19:22:48,567 | googleapiclient.discovery_cache | file_cache is only supported with oauth2client<4.0.0
[INFO] 2025-10-22 19:22:48,836 | google_auth_httplib2 | Refreshing credentials due to a 401 response. Attempt 1/2.
[INFO] 2025-10-22 19:22:49,184 | googleapiclient.discovery_cache | file_cache is only supported with oauth2client<4.0.0
[INFO] 2025-10-22 19:22:49,231 | google_auth_httplib2 | Refreshing credentials due to a 401 response. Attempt 1/2.
[INFO] 2025-10-22 19:22:49,727 | google_auth_httplib2 | Refreshing credentials due to a 401 response. Attempt 1/2.
[INFO] 2025-10-22 19:24:46,869 | googleapiclient.discovery_cache | file_cache is only supported with oauth2client<4.0.0
