[ERROR] 2025-10-28 00:23:16,084 | django.request | Internal Server Error: /forum/
Traceback (most recent call last):
  File "D:\IT\_OER\gauri oer\oer\venv\Lib\site-packages\django\template\backends\django.py", line 107, in render
    return self.template.render(context)
           ^^^^^^^^^^^^^^^^^^^^^^^^^^^^^
  File "D:\IT\_OER\gauri oer\oer\venv\Lib\site-packages\django\template\base.py", line 171, in render
    return self._render(context)
           ^^^^^^^^^^^^^^^^^^^^^
  File "D:\IT\_OER\gauri oer\oer\venv\Lib\site-packages\django\template\base.py", line 163, in _render
    return self.nodelist.render(context)
           ^^^^^^^^^^^^^^^^^^^^^^^^^^^^^
  File "D:\IT\_OER\gauri oer\oer\venv\Lib\site-packages\django\template\base.py", line 1016, in render
    return SafeString("".join([node.render_annotated(context) for node in self]))
                               ^^^^^^^^^^^^^^^^^^^^^^^^^^^^^^
  File "D:\IT\_OER\gauri oer\oer\venv\Lib\site-packages\django\template\base.py", line 977, in render_annotated
    return self.render(context)
           ^^^^^^^^^^^^^^^^^^^^
  File "D:\IT\_OER\gauri oer\oer\venv\Lib\site-packages\django\template\defaulttags.py", line 243, in render
    nodelist.append(node.render_annotated(context))
                    ^^^^^^^^^^^^^^^^^^^^^^^^^^^^^^
  File "D:\IT\_OER\gauri oer\oer\venv\Lib\site-packages\django\template\base.py", line 977, in render_annotated
    return self.render(context)
           ^^^^^^^^^^^^^^^^^^^^
  File "D:\IT\_OER\gauri oer\oer\venv\Lib\site-packages\django\template\defaulttags.py", line 243, in render
    nodelist.append(node.render_annotated(context))
                    ^^^^^^^^^^^^^^^^^^^^^^^^^^^^^^
  File "D:\IT\_OER\gauri oer\oer\venv\Lib\site-packages\django\template\base.py", line 977, in render_annotated
    return self.render(context)
           ^^^^^^^^^^^^^^^^^^^^
  File "D:\IT\_OER\gauri oer\oer\venv\Lib\site-packages\django\template\loader_tags.py", line 210, in render
    return template.render(context)
           ^^^^^^^^^^^^^^^^^^^^^^^^
  File "D:\IT\_OER\gauri oer\oer\venv\Lib\site-packages\django\template\base.py", line 173, in render
    return self._render(context)
           ^^^^^^^^^^^^^^^^^^^^^
  File "D:\IT\_OER\gauri oer\oer\venv\Lib\site-packages\django\template\base.py", line 163, in _render
    return self.nodelist.render(context)
           ^^^^^^^^^^^^^^^^^^^^^^^^^^^^^
  File "D:\IT\_OER\gauri oer\oer\venv\Lib\site-packages\django\template\base.py", line 1016, in render
    return SafeString("".join([node.render_annotated(context) for node in self]))
                               ^^^^^^^^^^^^^^^^^^^^^^^^^^^^^^
  File "D:\IT\_OER\gauri oer\oer\venv\Lib\site-packages\django\template\base.py", line 977, in render_annotated
    return self.render(context)
           ^^^^^^^^^^^^^^^^^^^^
  File "D:\IT\_OER\gauri oer\oer\venv\Lib\site-packages\django\template\defaulttags.py", line 550, in render
    return self.nodelist.render(context)
           ^^^^^^^^^^^^^^^^^^^^^^^^^^^^^
  File "D:\IT\_OER\gauri oer\oer\venv\Lib\site-packages\django\template\base.py", line 1016, in render
    return SafeString("".join([node.render_annotated(context) for node in self]))
                               ^^^^^^^^^^^^^^^^^^^^^^^^^^^^^^
  File "D:\IT\_OER\gauri oer\oer\venv\Lib\site-packages\django\template\base.py", line 977, in render_annotated
    return self.render(context)
           ^^^^^^^^^^^^^^^^^^^^
  File "D:\IT\_OER\gauri oer\oer\venv\Lib\site-packages\django\template\defaulttags.py", line 327, in render
    return nodelist.render(context)
           ^^^^^^^^^^^^^^^^^^^^^^^^
  File "D:\IT\_OER\gauri oer\oer\venv\Lib\site-packages\django\template\base.py", line 1016, in render
    return SafeString("".join([node.render_annotated(context) for node in self]))
                               ^^^^^^^^^^^^^^^^^^^^^^^^^^^^^^
  File "D:\IT\_OER\gauri oer\oer\venv\Lib\site-packages\django\template\base.py", line 977, in render_annotated
    return self.render(context)
           ^^^^^^^^^^^^^^^^^^^^
  File "D:\IT\_OER\gauri oer\oer\venv\Lib\site-packages\django\template\defaulttags.py", line 243, in render
    nodelist.append(node.render_annotated(context))
                    ^^^^^^^^^^^^^^^^^^^^^^^^^^^^^^
  File "D:\IT\_OER\gauri oer\oer\venv\Lib\site-packages\django\template\base.py", line 977, in render_annotated
    return self.render(context)
           ^^^^^^^^^^^^^^^^^^^^
  File "D:\IT\_OER\gauri oer\oer\venv\Lib\site-packages\django\template\loader_tags.py", line 199, in render
    template = context.template.engine.select_template(template_name)
               ^^^^^^^^^^^^^^^^^^^^^^^^^^^^^^^^^^^^^^^^^^^^^^^^^^^^^^
  File "D:\IT\_OER\gauri oer\oer\venv\Lib\site-packages\django\template\engine.py", line 214, in select_template
    raise TemplateDoesNotExist(", ".join(not_found))
django.template.exceptions.TemplateDoesNotExist: accounts\templates\forum\partials\answer.html

The above exception was the direct cause of the following exception:

Traceback (most recent call last):
  File "D:\IT\_OER\gauri oer\oer\venv\Lib\site-packages\django\core\handlers\exception.py", line 55, in inner
    response = get_response(request)
               ^^^^^^^^^^^^^^^^^^^^^
  File "D:\IT\_OER\gauri oer\oer\venv\Lib\site-packages\django\core\handlers\base.py", line 197, in _get_response
    response = wrapped_callback(request, *callback_args, **callback_kwargs)
               ^^^^^^^^^^^^^^^^^^^^^^^^^^^^^^^^^^^^^^^^^^^^^^^^^^^^^^^^^^^^
  File "D:\IT\_OER\gauri oer\oer\accounts\views\forum.py", line 28, in forum_home
    return render(request, "forum/list.html", context)
           ^^^^^^^^^^^^^^^^^^^^^^^^^^^^^^^^^^^^^^^^^^^
  File "D:\IT\_OER\gauri oer\oer\venv\Lib\site-packages\django\shortcuts.py", line 25, in render
    content = loader.render_to_string(template_name, context, request, using=using)
              ^^^^^^^^^^^^^^^^^^^^^^^^^^^^^^^^^^^^^^^^^^^^^^^^^^^^^^^^^^^^^^^^^^^^^
  File "D:\IT\_OER\gauri oer\oer\venv\Lib\site-packages\django\template\loader.py", line 62, in render_to_string
    return template.render(context, request)
           ^^^^^^^^^^^^^^^^^^^^^^^^^^^^^^^^^
  File "D:\IT\_OER\gauri oer\oer\venv\Lib\site-packages\django\template\backends\django.py", line 109, in render
    reraise(exc, self.backend)
  File "D:\IT\_OER\gauri oer\oer\venv\Lib\site-packages\django\template\backends\django.py", line 130, in reraise
    raise new from exc
django.template.exceptions.TemplateDoesNotExist: accounts\templates\forum\partials\answer.html
[ERROR] 2025-10-28 00:23:16,091 | django.server | "GET /forum/ HTTP/1.1" 500 216260
[WARNING] 2025-10-28 00:23:17,632 | django.request | Not Found: /favicon.ico
[WARNING] 2025-10-28 00:23:17,633 | django.server | "GET /favicon.ico HTTP/1.1" 404 7902
[ERROR] 2025-10-28 00:28:09,879 | django.request | Internal Server Error: /forum/
Traceback (most recent call last):
  File "D:\IT\_OER\gauri oer\oer\venv\Lib\site-packages\django\template\base.py", line 510, in parse
    compile_func = self.tags[command]
                   ~~~~~~~~~^^^^^^^^^
KeyError: 'endfor'

During handling of the above exception, another exception occurred:

Traceback (most recent call last):
  File "D:\IT\_OER\gauri oer\oer\venv\Lib\site-packages\django\core\handlers\exception.py", line 55, in inner
    response = get_response(request)
               ^^^^^^^^^^^^^^^^^^^^^
  File "D:\IT\_OER\gauri oer\oer\venv\Lib\site-packages\django\core\handlers\base.py", line 197, in _get_response
    response = wrapped_callback(request, *callback_args, **callback_kwargs)
               ^^^^^^^^^^^^^^^^^^^^^^^^^^^^^^^^^^^^^^^^^^^^^^^^^^^^^^^^^^^^
  File "D:\IT\_OER\gauri oer\oer\accounts\views\forum.py", line 28, in forum_home
    return render(request, "forum/list.html", context)
           ^^^^^^^^^^^^^^^^^^^^^^^^^^^^^^^^^^^^^^^^^^^
  File "D:\IT\_OER\gauri oer\oer\venv\Lib\site-packages\django\shortcuts.py", line 25, in render
    content = loader.render_to_string(template_name, context, request, using=using)
              ^^^^^^^^^^^^^^^^^^^^^^^^^^^^^^^^^^^^^^^^^^^^^^^^^^^^^^^^^^^^^^^^^^^^^
  File "D:\IT\_OER\gauri oer\oer\venv\Lib\site-packages\django\template\loader.py", line 61, in render_to_string
    template = get_template(template_name, using=using)
               ^^^^^^^^^^^^^^^^^^^^^^^^^^^^^^^^^^^^^^^^
  File "D:\IT\_OER\gauri oer\oer\venv\Lib\site-packages\django\template\loader.py", line 15, in get_template
    return engine.get_template(template_name)
           ^^^^^^^^^^^^^^^^^^^^^^^^^^^^^^^^^^
  File "D:\IT\_OER\gauri oer\oer\venv\Lib\site-packages\django\template\backends\django.py", line 79, in get_template
    return Template(self.engine.get_template(template_name), self)
                    ^^^^^^^^^^^^^^^^^^^^^^^^^^^^^^^^^^^^^^^
  File "D:\IT\_OER\gauri oer\oer\venv\Lib\site-packages\django\template\engine.py", line 177, in get_template
    template, origin = self.find_template(template_name)
                       ^^^^^^^^^^^^^^^^^^^^^^^^^^^^^^^^^
  File "D:\IT\_OER\gauri oer\oer\venv\Lib\site-packages\django\template\engine.py", line 159, in find_template
    template = loader.get_template(name, skip=skip)
               ^^^^^^^^^^^^^^^^^^^^^^^^^^^^^^^^^^^^
  File "D:\IT\_OER\gauri oer\oer\venv\Lib\site-packages\django\template\loaders\cached.py", line 57, in get_template
    template = super().get_template(template_name, skip)
               ^^^^^^^^^^^^^^^^^^^^^^^^^^^^^^^^^^^^^^^^^
  File "D:\IT\_OER\gauri oer\oer\venv\Lib\site-packages\django\template\loaders\base.py", line 28, in get_template
    return Template(
           ^^^^^^^^^
  File "D:\IT\_OER\gauri oer\oer\venv\Lib\site-packages\django\template\base.py", line 154, in __init__
    self.nodelist = self.compile_nodelist()
                    ^^^^^^^^^^^^^^^^^^^^^^^
  File "D:\IT\_OER\gauri oer\oer\venv\Lib\site-packages\django\template\base.py", line 196, in compile_nodelist
    nodelist = parser.parse()
               ^^^^^^^^^^^^^^
  File "D:\IT\_OER\gauri oer\oer\venv\Lib\site-packages\django\template\base.py", line 518, in parse
    raise self.error(token, e)
  File "D:\IT\_OER\gauri oer\oer\venv\Lib\site-packages\django\template\base.py", line 516, in parse
    compiled_result = compile_func(self, token)
                      ^^^^^^^^^^^^^^^^^^^^^^^^^
  File "D:\IT\_OER\gauri oer\oer\venv\Lib\site-packages\django\template\defaulttags.py", line 862, in do_for
    nodelist_loop = parser.parse(
                    ^^^^^^^^^^^^^
  File "D:\IT\_OER\gauri oer\oer\venv\Lib\site-packages\django\template\base.py", line 518, in parse
    raise self.error(token, e)
  File "D:\IT\_OER\gauri oer\oer\venv\Lib\site-packages\django\template\base.py", line 516, in parse
    compiled_result = compile_func(self, token)
                      ^^^^^^^^^^^^^^^^^^^^^^^^^
  File "D:\IT\_OER\gauri oer\oer\venv\Lib\site-packages\django\template\defaulttags.py", line 962, in do_if
    nodelist = parser.parse(("elif", "else", "endif"))
               ^^^^^^^^^^^^^^^^^^^^^^^^^^^^^^^^^^^^^^^
  File "D:\IT\_OER\gauri oer\oer\venv\Lib\site-packages\django\template\base.py", line 512, in parse
    self.invalid_block_tag(token, command, parse_until)
  File "D:\IT\_OER\gauri oer\oer\venv\Lib\site-packages\django\template\base.py", line 567, in invalid_block_tag
    raise self.error(
django.template.exceptions.TemplateSyntaxError: Invalid block tag on line 56: 'endfor', expected 'elif', 'else' or 'endif'. Did you forget to register or load this tag?
[ERROR] 2025-10-28 00:28:09,893 | django.server | "GET /forum/ HTTP/1.1" 500 203312
[WARNING] 2025-10-28 00:28:10,284 | django.request | Not Found: /favicon.ico
[WARNING] 2025-10-28 00:28:10,285 | django.server | "GET /favicon.ico HTTP/1.1" 404 7902
[WARNING] 2025-10-28 00:28:44,608 | django.request | Not Found: /favicon.ico
[WARNING] 2025-10-28 00:28:44,610 | django.server | "GET /favicon.ico HTTP/1.1" 404 7902
[ERROR] 2025-10-28 00:33:00,577 | django.request | Internal Server Error: /forum/3/answer/
Traceback (most recent call last):
  File "D:\IT\_OER\gauri oer\oer\venv\Lib\site-packages\django\core\handlers\exception.py", line 55, in inner
    response = get_response(request)
               ^^^^^^^^^^^^^^^^^^^^^
  File "D:\IT\_OER\gauri oer\oer\venv\Lib\site-packages\django\core\handlers\base.py", line 197, in _get_response
    response = wrapped_callback(request, *callback_args, **callback_kwargs)
               ^^^^^^^^^^^^^^^^^^^^^^^^^^^^^^^^^^^^^^^^^^^^^^^^^^^^^^^^^^^^
  File "D:\IT\_OER\gauri oer\oer\venv\Lib\site-packages\django\contrib\auth\decorators.py", line 59, in _view_wrapper
    return view_func(request, *args, **kwargs)
           ^^^^^^^^^^^^^^^^^^^^^^^^^^^^^^^^^^^
  File "D:\IT\_OER\gauri oer\oer\accounts\views\forum.py", line 56, in post_answer
    return redirect("forum_home")
           ^^^^^^^^^^^^^^^^^^^^^^
  File "D:\IT\_OER\gauri oer\oer\venv\Lib\site-packages\django\shortcuts.py", line 51, in redirect
    resolve_url(to, *args, **kwargs),
    ^^^^^^^^^^^^^^^^^^^^^^^^^^^^^^^^
  File "D:\IT\_OER\gauri oer\oer\venv\Lib\site-packages\django\shortcuts.py", line 184, in resolve_url
    return reverse(to, args=args, kwargs=kwargs)
           ^^^^^^^^^^^^^^^^^^^^^^^^^^^^^^^^^^^^^
  File "D:\IT\_OER\gauri oer\oer\venv\Lib\site-packages\django\urls\base.py", line 98, in reverse
    resolved_url = resolver._reverse_with_prefix(view, prefix, *args, **kwargs)
                   ^^^^^^^^^^^^^^^^^^^^^^^^^^^^^^^^^^^^^^^^^^^^^^^^^^^^^^^^^^^^
  File "D:\IT\_OER\gauri oer\oer\venv\Lib\site-packages\django\urls\resolvers.py", line 831, in _reverse_with_prefix
    raise NoReverseMatch(msg)
django.urls.exceptions.NoReverseMatch: Reverse for 'forum_home' not found. 'forum_home' is not a valid view function or pattern name.
[ERROR] 2025-10-28 00:33:00,583 | django.server | "POST /forum/3/answer/ HTTP/1.1" 500 98738
[ERROR] 2025-10-28 00:36:15,311 | django.request | Internal Server Error: /forum/2/answer/
Traceback (most recent call last):
  File "D:\IT\_OER\gauri oer\oer\venv\Lib\site-packages\django\core\handlers\exception.py", line 55, in inner
    response = get_response(request)
               ^^^^^^^^^^^^^^^^^^^^^
  File "D:\IT\_OER\gauri oer\oer\venv\Lib\site-packages\django\core\handlers\base.py", line 197, in _get_response
    response = wrapped_callback(request, *callback_args, **callback_kwargs)
               ^^^^^^^^^^^^^^^^^^^^^^^^^^^^^^^^^^^^^^^^^^^^^^^^^^^^^^^^^^^^
  File "D:\IT\_OER\gauri oer\oer\venv\Lib\site-packages\django\contrib\auth\decorators.py", line 59, in _view_wrapper
    return view_func(request, *args, **kwargs)
           ^^^^^^^^^^^^^^^^^^^^^^^^^^^^^^^^^^^
  File "D:\IT\_OER\gauri oer\oer\accounts\views\forum.py", line 56, in post_answer
    return redirect("forum_home")
           ^^^^^^^^^^^^^^^^^^^^^^
  File "D:\IT\_OER\gauri oer\oer\venv\Lib\site-packages\django\shortcuts.py", line 51, in redirect
    resolve_url(to, *args, **kwargs),
    ^^^^^^^^^^^^^^^^^^^^^^^^^^^^^^^^
  File "D:\IT\_OER\gauri oer\oer\venv\Lib\site-packages\django\shortcuts.py", line 184, in resolve_url
    return reverse(to, args=args, kwargs=kwargs)
           ^^^^^^^^^^^^^^^^^^^^^^^^^^^^^^^^^^^^^
  File "D:\IT\_OER\gauri oer\oer\venv\Lib\site-packages\django\urls\base.py", line 98, in reverse
    resolved_url = resolver._reverse_with_prefix(view, prefix, *args, **kwargs)
                   ^^^^^^^^^^^^^^^^^^^^^^^^^^^^^^^^^^^^^^^^^^^^^^^^^^^^^^^^^^^^
  File "D:\IT\_OER\gauri oer\oer\venv\Lib\site-packages\django\urls\resolvers.py", line 831, in _reverse_with_prefix
    raise NoReverseMatch(msg)
django.urls.exceptions.NoReverseMatch: Reverse for 'forum_home' not found. 'forum_home' is not a valid view function or pattern name.
[ERROR] 2025-10-28 00:36:15,326 | django.server | "POST /forum/2/answer/ HTTP/1.1" 500 98730
[WARNING] 2025-10-28 00:56:21,578 | django.request | Not Found: /favicon.ico
[WARNING] 2025-10-28 00:56:21,579 | django.server | "GET /favicon.ico HTTP/1.1" 404 8177
[WARNING] 2025-10-28 01:10:49,574 | django.request | Not Found: /favicon.ico
[WARNING] 2025-10-28 01:10:49,574 | django.server | "GET /favicon.ico HTTP/1.1" 404 8764
[ERROR] 2025-10-28 01:15:29,543 | django.request | Internal Server Error: /forum/3/
Traceback (most recent call last):
  File "D:\IT\_OER\gauri oer\oer\venv\Lib\site-packages\django\template\backends\django.py", line 107, in render
    return self.template.render(context)
           ^^^^^^^^^^^^^^^^^^^^^^^^^^^^^
  File "D:\IT\_OER\gauri oer\oer\venv\Lib\site-packages\django\template\base.py", line 171, in render
    return self._render(context)
           ^^^^^^^^^^^^^^^^^^^^^
  File "D:\IT\_OER\gauri oer\oer\venv\Lib\site-packages\django\template\base.py", line 163, in _render
    return self.nodelist.render(context)
           ^^^^^^^^^^^^^^^^^^^^^^^^^^^^^
  File "D:\IT\_OER\gauri oer\oer\venv\Lib\site-packages\django\template\base.py", line 1016, in render
    return SafeString("".join([node.render_annotated(context) for node in self]))
                               ^^^^^^^^^^^^^^^^^^^^^^^^^^^^^^
  File "D:\IT\_OER\gauri oer\oer\venv\Lib\site-packages\django\template\base.py", line 977, in render_annotated
    return self.render(context)
           ^^^^^^^^^^^^^^^^^^^^
  File "D:\IT\_OER\gauri oer\oer\venv\Lib\site-packages\django\template\defaulttags.py", line 243, in render
    nodelist.append(node.render_annotated(context))
                    ^^^^^^^^^^^^^^^^^^^^^^^^^^^^^^
  File "D:\IT\_OER\gauri oer\oer\venv\Lib\site-packages\django\template\base.py", line 977, in render_annotated
    return self.render(context)
           ^^^^^^^^^^^^^^^^^^^^
  File "D:\IT\_OER\gauri oer\oer\venv\Lib\site-packages\django\template\loader_tags.py", line 199, in render
    template = context.template.engine.select_template(template_name)
               ^^^^^^^^^^^^^^^^^^^^^^^^^^^^^^^^^^^^^^^^^^^^^^^^^^^^^^
  File "D:\IT\_OER\gauri oer\oer\venv\Lib\site-packages\django\template\engine.py", line 214, in select_template
    raise TemplateDoesNotExist(", ".join(not_found))
django.template.exceptions.TemplateDoesNotExist: accounts/forum/partials/answer.html

The above exception was the direct cause of the following exception:

Traceback (most recent call last):
  File "D:\IT\_OER\gauri oer\oer\venv\Lib\site-packages\django\core\handlers\exception.py", line 55, in inner
    response = get_response(request)
               ^^^^^^^^^^^^^^^^^^^^^
  File "D:\IT\_OER\gauri oer\oer\venv\Lib\site-packages\django\core\handlers\base.py", line 197, in _get_response
    response = wrapped_callback(request, *callback_args, **callback_kwargs)
               ^^^^^^^^^^^^^^^^^^^^^^^^^^^^^^^^^^^^^^^^^^^^^^^^^^^^^^^^^^^^
  File "D:\IT\_OER\gauri oer\oer\accounts\views\forum.py", line 61, in forum_detail
    return render(request, "forum/detail.html", {"question": question, "a_form": ForumAnswerForm()})
           ^^^^^^^^^^^^^^^^^^^^^^^^^^^^^^^^^^^^^^^^^^^^^^^^^^^^^^^^^^^^^^^^^^^^^^^^^^^^^^^^^^^^^^^^^
  File "D:\IT\_OER\gauri oer\oer\venv\Lib\site-packages\django\shortcuts.py", line 25, in render
    content = loader.render_to_string(template_name, context, request, using=using)
              ^^^^^^^^^^^^^^^^^^^^^^^^^^^^^^^^^^^^^^^^^^^^^^^^^^^^^^^^^^^^^^^^^^^^^
  File "D:\IT\_OER\gauri oer\oer\venv\Lib\site-packages\django\template\loader.py", line 62, in render_to_string
    return template.render(context, request)
           ^^^^^^^^^^^^^^^^^^^^^^^^^^^^^^^^^
  File "D:\IT\_OER\gauri oer\oer\venv\Lib\site-packages\django\template\backends\django.py", line 109, in render
    reraise(exc, self.backend)
  File "D:\IT\_OER\gauri oer\oer\venv\Lib\site-packages\django\template\backends\django.py", line 130, in reraise
    raise new from exc
django.template.exceptions.TemplateDoesNotExist: accounts/forum/partials/answer.html
[ERROR] 2025-10-28 01:15:29,551 | django.server | "GET /forum/3/ HTTP/1.1" 500 137468
[WARNING] 2025-10-28 01:15:30,112 | django.request | Not Found: /favicon.ico
[WARNING] 2025-10-28 01:15:30,113 | django.server | "GET /favicon.ico HTTP/1.1" 404 8764
[WARNING] 2025-10-28 01:15:38,635 | django.request | Not Found: /favicon.ico
[WARNING] 2025-10-28 01:15:38,636 | django.server | "GET /favicon.ico HTTP/1.1" 404 8764
[ERROR] 2025-10-28 01:15:40,060 | django.request | Internal Server Error: /forum/3/
Traceback (most recent call last):
  File "D:\IT\_OER\gauri oer\oer\venv\Lib\site-packages\django\template\backends\django.py", line 107, in render
    return self.template.render(context)
           ^^^^^^^^^^^^^^^^^^^^^^^^^^^^^
  File "D:\IT\_OER\gauri oer\oer\venv\Lib\site-packages\django\template\base.py", line 171, in render
    return self._render(context)
           ^^^^^^^^^^^^^^^^^^^^^
  File "D:\IT\_OER\gauri oer\oer\venv\Lib\site-packages\django\template\base.py", line 163, in _render
    return self.nodelist.render(context)
           ^^^^^^^^^^^^^^^^^^^^^^^^^^^^^
  File "D:\IT\_OER\gauri oer\oer\venv\Lib\site-packages\django\template\base.py", line 1016, in render
    return SafeString("".join([node.render_annotated(context) for node in self]))
                               ^^^^^^^^^^^^^^^^^^^^^^^^^^^^^^
  File "D:\IT\_OER\gauri oer\oer\venv\Lib\site-packages\django\template\base.py", line 977, in render_annotated
    return self.render(context)
           ^^^^^^^^^^^^^^^^^^^^
  File "D:\IT\_OER\gauri oer\oer\venv\Lib\site-packages\django\template\defaulttags.py", line 243, in render
    nodelist.append(node.render_annotated(context))
                    ^^^^^^^^^^^^^^^^^^^^^^^^^^^^^^
  File "D:\IT\_OER\gauri oer\oer\venv\Lib\site-packages\django\template\base.py", line 977, in render_annotated
    return self.render(context)
           ^^^^^^^^^^^^^^^^^^^^
  File "D:\IT\_OER\gauri oer\oer\venv\Lib\site-packages\django\template\loader_tags.py", line 199, in render
    template = context.template.engine.select_template(template_name)
               ^^^^^^^^^^^^^^^^^^^^^^^^^^^^^^^^^^^^^^^^^^^^^^^^^^^^^^
  File "D:\IT\_OER\gauri oer\oer\venv\Lib\site-packages\django\template\engine.py", line 214, in select_template
    raise TemplateDoesNotExist(", ".join(not_found))
django.template.exceptions.TemplateDoesNotExist: accounts/forum/partials/answer.html

The above exception was the direct cause of the following exception:

Traceback (most recent call last):
  File "D:\IT\_OER\gauri oer\oer\venv\Lib\site-packages\django\core\handlers\exception.py", line 55, in inner
    response = get_response(request)
               ^^^^^^^^^^^^^^^^^^^^^
  File "D:\IT\_OER\gauri oer\oer\venv\Lib\site-packages\django\core\handlers\base.py", line 197, in _get_response
    response = wrapped_callback(request, *callback_args, **callback_kwargs)
               ^^^^^^^^^^^^^^^^^^^^^^^^^^^^^^^^^^^^^^^^^^^^^^^^^^^^^^^^^^^^
  File "D:\IT\_OER\gauri oer\oer\accounts\views\forum.py", line 61, in forum_detail
    return render(request, "forum/detail.html", {"question": question, "a_form": ForumAnswerForm()})
           ^^^^^^^^^^^^^^^^^^^^^^^^^^^^^^^^^^^^^^^^^^^^^^^^^^^^^^^^^^^^^^^^^^^^^^^^^^^^^^^^^^^^^^^^^
  File "D:\IT\_OER\gauri oer\oer\venv\Lib\site-packages\django\shortcuts.py", line 25, in render
    content = loader.render_to_string(template_name, context, request, using=using)
              ^^^^^^^^^^^^^^^^^^^^^^^^^^^^^^^^^^^^^^^^^^^^^^^^^^^^^^^^^^^^^^^^^^^^^
  File "D:\IT\_OER\gauri oer\oer\venv\Lib\site-packages\django\template\loader.py", line 62, in render_to_string
    return template.render(context, request)
           ^^^^^^^^^^^^^^^^^^^^^^^^^^^^^^^^^
  File "D:\IT\_OER\gauri oer\oer\venv\Lib\site-packages\django\template\backends\django.py", line 109, in render
    reraise(exc, self.backend)
  File "D:\IT\_OER\gauri oer\oer\venv\Lib\site-packages\django\template\backends\django.py", line 130, in reraise
    raise new from exc
django.template.exceptions.TemplateDoesNotExist: accounts/forum/partials/answer.html
[ERROR] 2025-10-28 01:15:40,076 | django.server | "GET /forum/3/ HTTP/1.1" 500 137203
[ERROR] 2025-10-28 01:16:04,402 | django.request | Internal Server Error: /forum/3/
Traceback (most recent call last):
  File "D:\IT\_OER\gauri oer\oer\venv\Lib\site-packages\django\template\backends\django.py", line 107, in render
    return self.template.render(context)
           ^^^^^^^^^^^^^^^^^^^^^^^^^^^^^
  File "D:\IT\_OER\gauri oer\oer\venv\Lib\site-packages\django\template\base.py", line 171, in render
    return self._render(context)
           ^^^^^^^^^^^^^^^^^^^^^
  File "D:\IT\_OER\gauri oer\oer\venv\Lib\site-packages\django\template\base.py", line 163, in _render
    return self.nodelist.render(context)
           ^^^^^^^^^^^^^^^^^^^^^^^^^^^^^
  File "D:\IT\_OER\gauri oer\oer\venv\Lib\site-packages\django\template\base.py", line 1016, in render
    return SafeString("".join([node.render_annotated(context) for node in self]))
                               ^^^^^^^^^^^^^^^^^^^^^^^^^^^^^^
  File "D:\IT\_OER\gauri oer\oer\venv\Lib\site-packages\django\template\base.py", line 977, in render_annotated
    return self.render(context)
           ^^^^^^^^^^^^^^^^^^^^
  File "D:\IT\_OER\gauri oer\oer\venv\Lib\site-packages\django\template\defaulttags.py", line 243, in render
    nodelist.append(node.render_annotated(context))
                    ^^^^^^^^^^^^^^^^^^^^^^^^^^^^^^
  File "D:\IT\_OER\gauri oer\oer\venv\Lib\site-packages\django\template\base.py", line 977, in render_annotated
    return self.render(context)
           ^^^^^^^^^^^^^^^^^^^^
  File "D:\IT\_OER\gauri oer\oer\venv\Lib\site-packages\django\template\loader_tags.py", line 199, in render
    template = context.template.engine.select_template(template_name)
               ^^^^^^^^^^^^^^^^^^^^^^^^^^^^^^^^^^^^^^^^^^^^^^^^^^^^^^
  File "D:\IT\_OER\gauri oer\oer\venv\Lib\site-packages\django\template\engine.py", line 214, in select_template
    raise TemplateDoesNotExist(", ".join(not_found))
django.template.exceptions.TemplateDoesNotExist: accounts/forum/partials/answer.html

The above exception was the direct cause of the following exception:

Traceback (most recent call last):
  File "D:\IT\_OER\gauri oer\oer\venv\Lib\site-packages\django\core\handlers\exception.py", line 55, in inner
    response = get_response(request)
               ^^^^^^^^^^^^^^^^^^^^^
  File "D:\IT\_OER\gauri oer\oer\venv\Lib\site-packages\django\core\handlers\base.py", line 197, in _get_response
    response = wrapped_callback(request, *callback_args, **callback_kwargs)
               ^^^^^^^^^^^^^^^^^^^^^^^^^^^^^^^^^^^^^^^^^^^^^^^^^^^^^^^^^^^^
  File "D:\IT\_OER\gauri oer\oer\accounts\views\forum.py", line 61, in forum_detail
    return render(request, "forum/detail.html", {"question": question, "a_form": ForumAnswerForm()})
           ^^^^^^^^^^^^^^^^^^^^^^^^^^^^^^^^^^^^^^^^^^^^^^^^^^^^^^^^^^^^^^^^^^^^^^^^^^^^^^^^^^^^^^^^^
  File "D:\IT\_OER\gauri oer\oer\venv\Lib\site-packages\django\shortcuts.py", line 25, in render
    content = loader.render_to_string(template_name, context, request, using=using)
              ^^^^^^^^^^^^^^^^^^^^^^^^^^^^^^^^^^^^^^^^^^^^^^^^^^^^^^^^^^^^^^^^^^^^^
  File "D:\IT\_OER\gauri oer\oer\venv\Lib\site-packages\django\template\loader.py", line 62, in render_to_string
    return template.render(context, request)
           ^^^^^^^^^^^^^^^^^^^^^^^^^^^^^^^^^
  File "D:\IT\_OER\gauri oer\oer\venv\Lib\site-packages\django\template\backends\django.py", line 109, in render
    reraise(exc, self.backend)
  File "D:\IT\_OER\gauri oer\oer\venv\Lib\site-packages\django\template\backends\django.py", line 130, in reraise
    raise new from exc
django.template.exceptions.TemplateDoesNotExist: accounts/forum/partials/answer.html
[ERROR] 2025-10-28 01:16:04,402 | django.server | "GET /forum/3/ HTTP/1.1" 500 137468
[WARNING] 2025-10-28 01:16:04,757 | django.request | Not Found: /favicon.ico
[WARNING] 2025-10-28 01:16:04,758 | django.server | "GET /favicon.ico HTTP/1.1" 404 8764
[ERROR] 2025-10-28 01:16:05,369 | django.request | Internal Server Error: /forum/3/
Traceback (most recent call last):
  File "D:\IT\_OER\gauri oer\oer\venv\Lib\site-packages\django\template\backends\django.py", line 107, in render
    return self.template.render(context)
           ^^^^^^^^^^^^^^^^^^^^^^^^^^^^^
  File "D:\IT\_OER\gauri oer\oer\venv\Lib\site-packages\django\template\base.py", line 171, in render
    return self._render(context)
           ^^^^^^^^^^^^^^^^^^^^^
  File "D:\IT\_OER\gauri oer\oer\venv\Lib\site-packages\django\template\base.py", line 163, in _render
    return self.nodelist.render(context)
           ^^^^^^^^^^^^^^^^^^^^^^^^^^^^^
  File "D:\IT\_OER\gauri oer\oer\venv\Lib\site-packages\django\template\base.py", line 1016, in render
    return SafeString("".join([node.render_annotated(context) for node in self]))
                               ^^^^^^^^^^^^^^^^^^^^^^^^^^^^^^
  File "D:\IT\_OER\gauri oer\oer\venv\Lib\site-packages\django\template\base.py", line 977, in render_annotated
    return self.render(context)
           ^^^^^^^^^^^^^^^^^^^^
  File "D:\IT\_OER\gauri oer\oer\venv\Lib\site-packages\django\template\defaulttags.py", line 243, in render
    nodelist.append(node.render_annotated(context))
                    ^^^^^^^^^^^^^^^^^^^^^^^^^^^^^^
  File "D:\IT\_OER\gauri oer\oer\venv\Lib\site-packages\django\template\base.py", line 977, in render_annotated
    return self.render(context)
           ^^^^^^^^^^^^^^^^^^^^
  File "D:\IT\_OER\gauri oer\oer\venv\Lib\site-packages\django\template\loader_tags.py", line 199, in render
    template = context.template.engine.select_template(template_name)
               ^^^^^^^^^^^^^^^^^^^^^^^^^^^^^^^^^^^^^^^^^^^^^^^^^^^^^^
  File "D:\IT\_OER\gauri oer\oer\venv\Lib\site-packages\django\template\engine.py", line 214, in select_template
    raise TemplateDoesNotExist(", ".join(not_found))
django.template.exceptions.TemplateDoesNotExist: accounts/forum/partials/answer.html

The above exception was the direct cause of the following exception:

Traceback (most recent call last):
  File "D:\IT\_OER\gauri oer\oer\venv\Lib\site-packages\django\core\handlers\exception.py", line 55, in inner
    response = get_response(request)
               ^^^^^^^^^^^^^^^^^^^^^
  File "D:\IT\_OER\gauri oer\oer\venv\Lib\site-packages\django\core\handlers\base.py", line 197, in _get_response
    response = wrapped_callback(request, *callback_args, **callback_kwargs)
               ^^^^^^^^^^^^^^^^^^^^^^^^^^^^^^^^^^^^^^^^^^^^^^^^^^^^^^^^^^^^
  File "D:\IT\_OER\gauri oer\oer\accounts\views\forum.py", line 61, in forum_detail
    return render(request, "forum/detail.html", {"question": question, "a_form": ForumAnswerForm()})
           ^^^^^^^^^^^^^^^^^^^^^^^^^^^^^^^^^^^^^^^^^^^^^^^^^^^^^^^^^^^^^^^^^^^^^^^^^^^^^^^^^^^^^^^^^
  File "D:\IT\_OER\gauri oer\oer\venv\Lib\site-packages\django\shortcuts.py", line 25, in render
    content = loader.render_to_string(template_name, context, request, using=using)
              ^^^^^^^^^^^^^^^^^^^^^^^^^^^^^^^^^^^^^^^^^^^^^^^^^^^^^^^^^^^^^^^^^^^^^
  File "D:\IT\_OER\gauri oer\oer\venv\Lib\site-packages\django\template\loader.py", line 62, in render_to_string
    return template.render(context, request)
           ^^^^^^^^^^^^^^^^^^^^^^^^^^^^^^^^^
  File "D:\IT\_OER\gauri oer\oer\venv\Lib\site-packages\django\template\backends\django.py", line 109, in render
    reraise(exc, self.backend)
  File "D:\IT\_OER\gauri oer\oer\venv\Lib\site-packages\django\template\backends\django.py", line 130, in reraise
    raise new from exc
django.template.exceptions.TemplateDoesNotExist: accounts/forum/partials/answer.html
[ERROR] 2025-10-28 01:16:05,369 | django.server | "GET /forum/3/ HTTP/1.1" 500 137468
[ERROR] 2025-10-28 01:16:05,665 | django.request | Internal Server Error: /forum/3/
Traceback (most recent call last):
  File "D:\IT\_OER\gauri oer\oer\venv\Lib\site-packages\django\template\backends\django.py", line 107, in render
    return self.template.render(context)
           ^^^^^^^^^^^^^^^^^^^^^^^^^^^^^
  File "D:\IT\_OER\gauri oer\oer\venv\Lib\site-packages\django\template\base.py", line 171, in render
    return self._render(context)
           ^^^^^^^^^^^^^^^^^^^^^
  File "D:\IT\_OER\gauri oer\oer\venv\Lib\site-packages\django\template\base.py", line 163, in _render
    return self.nodelist.render(context)
           ^^^^^^^^^^^^^^^^^^^^^^^^^^^^^
  File "D:\IT\_OER\gauri oer\oer\venv\Lib\site-packages\django\template\base.py", line 1016, in render
    return SafeString("".join([node.render_annotated(context) for node in self]))
                               ^^^^^^^^^^^^^^^^^^^^^^^^^^^^^^
  File "D:\IT\_OER\gauri oer\oer\venv\Lib\site-packages\django\template\base.py", line 977, in render_annotated
    return self.render(context)
           ^^^^^^^^^^^^^^^^^^^^
  File "D:\IT\_OER\gauri oer\oer\venv\Lib\site-packages\django\template\defaulttags.py", line 243, in render
    nodelist.append(node.render_annotated(context))
                    ^^^^^^^^^^^^^^^^^^^^^^^^^^^^^^
  File "D:\IT\_OER\gauri oer\oer\venv\Lib\site-packages\django\template\base.py", line 977, in render_annotated
    return self.render(context)
           ^^^^^^^^^^^^^^^^^^^^
  File "D:\IT\_OER\gauri oer\oer\venv\Lib\site-packages\django\template\loader_tags.py", line 199, in render
    template = context.template.engine.select_template(template_name)
               ^^^^^^^^^^^^^^^^^^^^^^^^^^^^^^^^^^^^^^^^^^^^^^^^^^^^^^
  File "D:\IT\_OER\gauri oer\oer\venv\Lib\site-packages\django\template\engine.py", line 214, in select_template
    raise TemplateDoesNotExist(", ".join(not_found))
django.template.exceptions.TemplateDoesNotExist: accounts/forum/partials/answer.html

The above exception was the direct cause of the following exception:

Traceback (most recent call last):
  File "D:\IT\_OER\gauri oer\oer\venv\Lib\site-packages\django\core\handlers\exception.py", line 55, in inner
    response = get_response(request)
               ^^^^^^^^^^^^^^^^^^^^^
  File "D:\IT\_OER\gauri oer\oer\venv\Lib\site-packages\django\core\handlers\base.py", line 197, in _get_response
    response = wrapped_callback(request, *callback_args, **callback_kwargs)
               ^^^^^^^^^^^^^^^^^^^^^^^^^^^^^^^^^^^^^^^^^^^^^^^^^^^^^^^^^^^^
  File "D:\IT\_OER\gauri oer\oer\accounts\views\forum.py", line 61, in forum_detail
    return render(request, "forum/detail.html", {"question": question, "a_form": ForumAnswerForm()})
           ^^^^^^^^^^^^^^^^^^^^^^^^^^^^^^^^^^^^^^^^^^^^^^^^^^^^^^^^^^^^^^^^^^^^^^^^^^^^^^^^^^^^^^^^^
  File "D:\IT\_OER\gauri oer\oer\venv\Lib\site-packages\django\shortcuts.py", line 25, in render
    content = loader.render_to_string(template_name, context, request, using=using)
              ^^^^^^^^^^^^^^^^^^^^^^^^^^^^^^^^^^^^^^^^^^^^^^^^^^^^^^^^^^^^^^^^^^^^^
  File "D:\IT\_OER\gauri oer\oer\venv\Lib\site-packages\django\template\loader.py", line 62, in render_to_string
    return template.render(context, request)
           ^^^^^^^^^^^^^^^^^^^^^^^^^^^^^^^^^
  File "D:\IT\_OER\gauri oer\oer\venv\Lib\site-packages\django\template\backends\django.py", line 109, in render
    reraise(exc, self.backend)
  File "D:\IT\_OER\gauri oer\oer\venv\Lib\site-packages\django\template\backends\django.py", line 130, in reraise
    raise new from exc
django.template.exceptions.TemplateDoesNotExist: accounts/forum/partials/answer.html
[ERROR] 2025-10-28 01:16:05,715 | django.request | Internal Server Error: /forum/3/
Traceback (most recent call last):
  File "D:\IT\_OER\gauri oer\oer\venv\Lib\site-packages\django\template\backends\django.py", line 107, in render
    return self.template.render(context)
           ^^^^^^^^^^^^^^^^^^^^^^^^^^^^^
  File "D:\IT\_OER\gauri oer\oer\venv\Lib\site-packages\django\template\base.py", line 171, in render
    return self._render(context)
           ^^^^^^^^^^^^^^^^^^^^^
  File "D:\IT\_OER\gauri oer\oer\venv\Lib\site-packages\django\template\base.py", line 163, in _render
    return self.nodelist.render(context)
           ^^^^^^^^^^^^^^^^^^^^^^^^^^^^^
  File "D:\IT\_OER\gauri oer\oer\venv\Lib\site-packages\django\template\base.py", line 1016, in render
    return SafeString("".join([node.render_annotated(context) for node in self]))
                               ^^^^^^^^^^^^^^^^^^^^^^^^^^^^^^
  File "D:\IT\_OER\gauri oer\oer\venv\Lib\site-packages\django\template\base.py", line 977, in render_annotated
    return self.render(context)
           ^^^^^^^^^^^^^^^^^^^^
  File "D:\IT\_OER\gauri oer\oer\venv\Lib\site-packages\django\template\defaulttags.py", line 243, in render
    nodelist.append(node.render_annotated(context))
                    ^^^^^^^^^^^^^^^^^^^^^^^^^^^^^^
  File "D:\IT\_OER\gauri oer\oer\venv\Lib\site-packages\django\template\base.py", line 977, in render_annotated
    return self.render(context)
           ^^^^^^^^^^^^^^^^^^^^
  File "D:\IT\_OER\gauri oer\oer\venv\Lib\site-packages\django\template\loader_tags.py", line 199, in render
    template = context.template.engine.select_template(template_name)
               ^^^^^^^^^^^^^^^^^^^^^^^^^^^^^^^^^^^^^^^^^^^^^^^^^^^^^^
  File "D:\IT\_OER\gauri oer\oer\venv\Lib\site-packages\django\template\engine.py", line 214, in select_template
    raise TemplateDoesNotExist(", ".join(not_found))
django.template.exceptions.TemplateDoesNotExist: accounts/forum/partials/answer.html

The above exception was the direct cause of the following exception:

Traceback (most recent call last):
  File "D:\IT\_OER\gauri oer\oer\venv\Lib\site-packages\django\core\handlers\exception.py", line 55, in inner
    response = get_response(request)
               ^^^^^^^^^^^^^^^^^^^^^
  File "D:\IT\_OER\gauri oer\oer\venv\Lib\site-packages\django\core\handlers\base.py", line 197, in _get_response
    response = wrapped_callback(request, *callback_args, **callback_kwargs)
               ^^^^^^^^^^^^^^^^^^^^^^^^^^^^^^^^^^^^^^^^^^^^^^^^^^^^^^^^^^^^
  File "D:\IT\_OER\gauri oer\oer\accounts\views\forum.py", line 61, in forum_detail
    return render(request, "forum/detail.html", {"question": question, "a_form": ForumAnswerForm()})
           ^^^^^^^^^^^^^^^^^^^^^^^^^^^^^^^^^^^^^^^^^^^^^^^^^^^^^^^^^^^^^^^^^^^^^^^^^^^^^^^^^^^^^^^^^
  File "D:\IT\_OER\gauri oer\oer\venv\Lib\site-packages\django\shortcuts.py", line 25, in render
    content = loader.render_to_string(template_name, context, request, using=using)
              ^^^^^^^^^^^^^^^^^^^^^^^^^^^^^^^^^^^^^^^^^^^^^^^^^^^^^^^^^^^^^^^^^^^^^
  File "D:\IT\_OER\gauri oer\oer\venv\Lib\site-packages\django\template\loader.py", line 62, in render_to_string
    return template.render(context, request)
           ^^^^^^^^^^^^^^^^^^^^^^^^^^^^^^^^^
  File "D:\IT\_OER\gauri oer\oer\venv\Lib\site-packages\django\template\backends\django.py", line 109, in render
    reraise(exc, self.backend)
  File "D:\IT\_OER\gauri oer\oer\venv\Lib\site-packages\django\template\backends\django.py", line 130, in reraise
    raise new from exc
django.template.exceptions.TemplateDoesNotExist: accounts/forum/partials/answer.html
[WARNING] 2025-10-28 01:16:05,722 | django.request | Not Found: /favicon.ico
[WARNING] 2025-10-28 01:16:05,728 | django.server | "GET /favicon.ico HTTP/1.1" 404 8764
[ERROR] 2025-10-28 01:16:05,728 | django.server | "GET /forum/3/ HTTP/1.1" 500 137468
[WARNING] 2025-10-28 01:16:06,046 | django.request | Not Found: /favicon.ico
[WARNING] 2025-10-28 01:16:06,046 | django.server | "GET /favicon.ico HTTP/1.1" 404 8764
[ERROR] 2025-10-28 01:19:08,140 | django.request | Internal Server Error: /forum/3/
Traceback (most recent call last):
  File "D:\IT\_OER\gauri oer\oer\venv\Lib\site-packages\django\template\backends\django.py", line 107, in render
    return self.template.render(context)
           ^^^^^^^^^^^^^^^^^^^^^^^^^^^^^
  File "D:\IT\_OER\gauri oer\oer\venv\Lib\site-packages\django\template\base.py", line 171, in render
    return self._render(context)
           ^^^^^^^^^^^^^^^^^^^^^
  File "D:\IT\_OER\gauri oer\oer\venv\Lib\site-packages\django\template\base.py", line 163, in _render
    return self.nodelist.render(context)
           ^^^^^^^^^^^^^^^^^^^^^^^^^^^^^
  File "D:\IT\_OER\gauri oer\oer\venv\Lib\site-packages\django\template\base.py", line 1016, in render
    return SafeString("".join([node.render_annotated(context) for node in self]))
                               ^^^^^^^^^^^^^^^^^^^^^^^^^^^^^^
  File "D:\IT\_OER\gauri oer\oer\venv\Lib\site-packages\django\template\base.py", line 977, in render_annotated
    return self.render(context)
           ^^^^^^^^^^^^^^^^^^^^
  File "D:\IT\_OER\gauri oer\oer\venv\Lib\site-packages\django\template\defaulttags.py", line 243, in render
    nodelist.append(node.render_annotated(context))
                    ^^^^^^^^^^^^^^^^^^^^^^^^^^^^^^
  File "D:\IT\_OER\gauri oer\oer\venv\Lib\site-packages\django\template\base.py", line 977, in render_annotated
    return self.render(context)
           ^^^^^^^^^^^^^^^^^^^^
  File "D:\IT\_OER\gauri oer\oer\venv\Lib\site-packages\django\template\loader_tags.py", line 210, in render
    return template.render(context)
           ^^^^^^^^^^^^^^^^^^^^^^^^
  File "D:\IT\_OER\gauri oer\oer\venv\Lib\site-packages\django\template\base.py", line 173, in render
    return self._render(context)
           ^^^^^^^^^^^^^^^^^^^^^
  File "D:\IT\_OER\gauri oer\oer\venv\Lib\site-packages\django\template\base.py", line 163, in _render
    return self.nodelist.render(context)
           ^^^^^^^^^^^^^^^^^^^^^^^^^^^^^
  File "D:\IT\_OER\gauri oer\oer\venv\Lib\site-packages\django\template\base.py", line 1016, in render
    return SafeString("".join([node.render_annotated(context) for node in self]))
                               ^^^^^^^^^^^^^^^^^^^^^^^^^^^^^^
  File "D:\IT\_OER\gauri oer\oer\venv\Lib\site-packages\django\template\base.py", line 977, in render_annotated
    return self.render(context)
           ^^^^^^^^^^^^^^^^^^^^
  File "D:\IT\_OER\gauri oer\oer\venv\Lib\site-packages\django\template\defaulttags.py", line 550, in render
    return self.nodelist.render(context)
           ^^^^^^^^^^^^^^^^^^^^^^^^^^^^^
  File "D:\IT\_OER\gauri oer\oer\venv\Lib\site-packages\django\template\base.py", line 1016, in render
    return SafeString("".join([node.render_annotated(context) for node in self]))
                               ^^^^^^^^^^^^^^^^^^^^^^^^^^^^^^
  File "D:\IT\_OER\gauri oer\oer\venv\Lib\site-packages\django\template\base.py", line 977, in render_annotated
    return self.render(context)
           ^^^^^^^^^^^^^^^^^^^^
  File "D:\IT\_OER\gauri oer\oer\venv\Lib\site-packages\django\template\defaulttags.py", line 327, in render
    return nodelist.render(context)
           ^^^^^^^^^^^^^^^^^^^^^^^^
  File "D:\IT\_OER\gauri oer\oer\venv\Lib\site-packages\django\template\base.py", line 1016, in render
    return SafeString("".join([node.render_annotated(context) for node in self]))
                               ^^^^^^^^^^^^^^^^^^^^^^^^^^^^^^
  File "D:\IT\_OER\gauri oer\oer\venv\Lib\site-packages\django\template\base.py", line 977, in render_annotated
    return self.render(context)
           ^^^^^^^^^^^^^^^^^^^^
  File "D:\IT\_OER\gauri oer\oer\venv\Lib\site-packages\django\template\defaulttags.py", line 243, in render
    nodelist.append(node.render_annotated(context))
                    ^^^^^^^^^^^^^^^^^^^^^^^^^^^^^^
  File "D:\IT\_OER\gauri oer\oer\venv\Lib\site-packages\django\template\base.py", line 977, in render_annotated
    return self.render(context)
           ^^^^^^^^^^^^^^^^^^^^
  File "D:\IT\_OER\gauri oer\oer\venv\Lib\site-packages\django\template\loader_tags.py", line 199, in render
    template = context.template.engine.select_template(template_name)
               ^^^^^^^^^^^^^^^^^^^^^^^^^^^^^^^^^^^^^^^^^^^^^^^^^^^^^^
  File "D:\IT\_OER\gauri oer\oer\venv\Lib\site-packages\django\template\engine.py", line 214, in select_template
    raise TemplateDoesNotExist(", ".join(not_found))
django.template.exceptions.TemplateDoesNotExist: accounts/forum/partials/answer.html

The above exception was the direct cause of the following exception:

Traceback (most recent call last):
  File "D:\IT\_OER\gauri oer\oer\venv\Lib\site-packages\django\core\handlers\exception.py", line 55, in inner
    response = get_response(request)
               ^^^^^^^^^^^^^^^^^^^^^
  File "D:\IT\_OER\gauri oer\oer\venv\Lib\site-packages\django\core\handlers\base.py", line 197, in _get_response
    response = wrapped_callback(request, *callback_args, **callback_kwargs)
               ^^^^^^^^^^^^^^^^^^^^^^^^^^^^^^^^^^^^^^^^^^^^^^^^^^^^^^^^^^^^
  File "D:\IT\_OER\gauri oer\oer\accounts\views\forum.py", line 61, in forum_detail
    return render(request, "forum/detail.html", {"question": question, "a_form": ForumAnswerForm()})
           ^^^^^^^^^^^^^^^^^^^^^^^^^^^^^^^^^^^^^^^^^^^^^^^^^^^^^^^^^^^^^^^^^^^^^^^^^^^^^^^^^^^^^^^^^
  File "D:\IT\_OER\gauri oer\oer\venv\Lib\site-packages\django\shortcuts.py", line 25, in render
    content = loader.render_to_string(template_name, context, request, using=using)
              ^^^^^^^^^^^^^^^^^^^^^^^^^^^^^^^^^^^^^^^^^^^^^^^^^^^^^^^^^^^^^^^^^^^^^
  File "D:\IT\_OER\gauri oer\oer\venv\Lib\site-packages\django\template\loader.py", line 62, in render_to_string
    return template.render(context, request)
           ^^^^^^^^^^^^^^^^^^^^^^^^^^^^^^^^^
  File "D:\IT\_OER\gauri oer\oer\venv\Lib\site-packages\django\template\backends\django.py", line 109, in render
    reraise(exc, self.backend)
  File "D:\IT\_OER\gauri oer\oer\venv\Lib\site-packages\django\template\backends\django.py", line 130, in reraise
    raise new from exc
django.template.exceptions.TemplateDoesNotExist: accounts/forum/partials/answer.html
[ERROR] 2025-10-28 01:19:08,159 | django.server | "GET /forum/3/ HTTP/1.1" 500 197099
[WARNING] 2025-10-28 01:19:09,166 | django.request | Not Found: /favicon.ico
[WARNING] 2025-10-28 01:19:09,167 | django.server | "GET /favicon.ico HTTP/1.1" 404 8764
[ERROR] 2025-10-28 01:19:10,238 | django.request | Internal Server Error: /forum/3/
Traceback (most recent call last):
  File "D:\IT\_OER\gauri oer\oer\venv\Lib\site-packages\django\template\backends\django.py", line 107, in render
    return self.template.render(context)
           ^^^^^^^^^^^^^^^^^^^^^^^^^^^^^
  File "D:\IT\_OER\gauri oer\oer\venv\Lib\site-packages\django\template\base.py", line 171, in render
    return self._render(context)
           ^^^^^^^^^^^^^^^^^^^^^
  File "D:\IT\_OER\gauri oer\oer\venv\Lib\site-packages\django\template\base.py", line 163, in _render
    return self.nodelist.render(context)
           ^^^^^^^^^^^^^^^^^^^^^^^^^^^^^
  File "D:\IT\_OER\gauri oer\oer\venv\Lib\site-packages\django\template\base.py", line 1016, in render
    return SafeString("".join([node.render_annotated(context) for node in self]))
                               ^^^^^^^^^^^^^^^^^^^^^^^^^^^^^^
  File "D:\IT\_OER\gauri oer\oer\venv\Lib\site-packages\django\template\base.py", line 977, in render_annotated
    return self.render(context)
           ^^^^^^^^^^^^^^^^^^^^
  File "D:\IT\_OER\gauri oer\oer\venv\Lib\site-packages\django\template\defaulttags.py", line 243, in render
    nodelist.append(node.render_annotated(context))
                    ^^^^^^^^^^^^^^^^^^^^^^^^^^^^^^
  File "D:\IT\_OER\gauri oer\oer\venv\Lib\site-packages\django\template\base.py", line 977, in render_annotated
    return self.render(context)
           ^^^^^^^^^^^^^^^^^^^^
  File "D:\IT\_OER\gauri oer\oer\venv\Lib\site-packages\django\template\loader_tags.py", line 210, in render
    return template.render(context)
           ^^^^^^^^^^^^^^^^^^^^^^^^
  File "D:\IT\_OER\gauri oer\oer\venv\Lib\site-packages\django\template\base.py", line 173, in render
    return self._render(context)
           ^^^^^^^^^^^^^^^^^^^^^
  File "D:\IT\_OER\gauri oer\oer\venv\Lib\site-packages\django\template\base.py", line 163, in _render
    return self.nodelist.render(context)
           ^^^^^^^^^^^^^^^^^^^^^^^^^^^^^
  File "D:\IT\_OER\gauri oer\oer\venv\Lib\site-packages\django\template\base.py", line 1016, in render
    return SafeString("".join([node.render_annotated(context) for node in self]))
                               ^^^^^^^^^^^^^^^^^^^^^^^^^^^^^^
  File "D:\IT\_OER\gauri oer\oer\venv\Lib\site-packages\django\template\base.py", line 977, in render_annotated
    return self.render(context)
           ^^^^^^^^^^^^^^^^^^^^
  File "D:\IT\_OER\gauri oer\oer\venv\Lib\site-packages\django\template\defaulttags.py", line 550, in render
    return self.nodelist.render(context)
           ^^^^^^^^^^^^^^^^^^^^^^^^^^^^^
  File "D:\IT\_OER\gauri oer\oer\venv\Lib\site-packages\django\template\base.py", line 1016, in render
    return SafeString("".join([node.render_annotated(context) for node in self]))
                               ^^^^^^^^^^^^^^^^^^^^^^^^^^^^^^
  File "D:\IT\_OER\gauri oer\oer\venv\Lib\site-packages\django\template\base.py", line 977, in render_annotated
    return self.render(context)
           ^^^^^^^^^^^^^^^^^^^^
  File "D:\IT\_OER\gauri oer\oer\venv\Lib\site-packages\django\template\defaulttags.py", line 327, in render
    return nodelist.render(context)
           ^^^^^^^^^^^^^^^^^^^^^^^^
  File "D:\IT\_OER\gauri oer\oer\venv\Lib\site-packages\django\template\base.py", line 1016, in render
    return SafeString("".join([node.render_annotated(context) for node in self]))
                               ^^^^^^^^^^^^^^^^^^^^^^^^^^^^^^
  File "D:\IT\_OER\gauri oer\oer\venv\Lib\site-packages\django\template\base.py", line 977, in render_annotated
    return self.render(context)
           ^^^^^^^^^^^^^^^^^^^^
  File "D:\IT\_OER\gauri oer\oer\venv\Lib\site-packages\django\template\defaulttags.py", line 243, in render
    nodelist.append(node.render_annotated(context))
                    ^^^^^^^^^^^^^^^^^^^^^^^^^^^^^^
  File "D:\IT\_OER\gauri oer\oer\venv\Lib\site-packages\django\template\base.py", line 977, in render_annotated
    return self.render(context)
           ^^^^^^^^^^^^^^^^^^^^
  File "D:\IT\_OER\gauri oer\oer\venv\Lib\site-packages\django\template\loader_tags.py", line 199, in render
    template = context.template.engine.select_template(template_name)
               ^^^^^^^^^^^^^^^^^^^^^^^^^^^^^^^^^^^^^^^^^^^^^^^^^^^^^^
  File "D:\IT\_OER\gauri oer\oer\venv\Lib\site-packages\django\template\engine.py", line 214, in select_template
    raise TemplateDoesNotExist(", ".join(not_found))
django.template.exceptions.TemplateDoesNotExist: accounts/forum/partials/answer.html

The above exception was the direct cause of the following exception:

Traceback (most recent call last):
  File "D:\IT\_OER\gauri oer\oer\venv\Lib\site-packages\django\core\handlers\exception.py", line 55, in inner
    response = get_response(request)
               ^^^^^^^^^^^^^^^^^^^^^
  File "D:\IT\_OER\gauri oer\oer\venv\Lib\site-packages\django\core\handlers\base.py", line 197, in _get_response
    response = wrapped_callback(request, *callback_args, **callback_kwargs)
               ^^^^^^^^^^^^^^^^^^^^^^^^^^^^^^^^^^^^^^^^^^^^^^^^^^^^^^^^^^^^
  File "D:\IT\_OER\gauri oer\oer\accounts\views\forum.py", line 61, in forum_detail
    return render(request, "forum/detail.html", {"question": question, "a_form": ForumAnswerForm()})
           ^^^^^^^^^^^^^^^^^^^^^^^^^^^^^^^^^^^^^^^^^^^^^^^^^^^^^^^^^^^^^^^^^^^^^^^^^^^^^^^^^^^^^^^^^
  File "D:\IT\_OER\gauri oer\oer\venv\Lib\site-packages\django\shortcuts.py", line 25, in render
    content = loader.render_to_string(template_name, context, request, using=using)
              ^^^^^^^^^^^^^^^^^^^^^^^^^^^^^^^^^^^^^^^^^^^^^^^^^^^^^^^^^^^^^^^^^^^^^
  File "D:\IT\_OER\gauri oer\oer\venv\Lib\site-packages\django\template\loader.py", line 62, in render_to_string
    return template.render(context, request)
           ^^^^^^^^^^^^^^^^^^^^^^^^^^^^^^^^^
  File "D:\IT\_OER\gauri oer\oer\venv\Lib\site-packages\django\template\backends\django.py", line 109, in render
    reraise(exc, self.backend)
  File "D:\IT\_OER\gauri oer\oer\venv\Lib\site-packages\django\template\backends\django.py", line 130, in reraise
    raise new from exc
django.template.exceptions.TemplateDoesNotExist: accounts/forum/partials/answer.html
[ERROR] 2025-10-28 01:19:10,242 | django.server | "GET /forum/3/ HTTP/1.1" 500 197099
[ERROR] 2025-10-28 01:19:10,382 | django.request | Internal Server Error: /forum/3/
Traceback (most recent call last):
  File "D:\IT\_OER\gauri oer\oer\venv\Lib\site-packages\django\template\backends\django.py", line 107, in render
    return self.template.render(context)
           ^^^^^^^^^^^^^^^^^^^^^^^^^^^^^
  File "D:\IT\_OER\gauri oer\oer\venv\Lib\site-packages\django\template\base.py", line 171, in render
    return self._render(context)
           ^^^^^^^^^^^^^^^^^^^^^
  File "D:\IT\_OER\gauri oer\oer\venv\Lib\site-packages\django\template\base.py", line 163, in _render
    return self.nodelist.render(context)
           ^^^^^^^^^^^^^^^^^^^^^^^^^^^^^
  File "D:\IT\_OER\gauri oer\oer\venv\Lib\site-packages\django\template\base.py", line 1016, in render
    return SafeString("".join([node.render_annotated(context) for node in self]))
                               ^^^^^^^^^^^^^^^^^^^^^^^^^^^^^^
  File "D:\IT\_OER\gauri oer\oer\venv\Lib\site-packages\django\template\base.py", line 977, in render_annotated
    return self.render(context)
           ^^^^^^^^^^^^^^^^^^^^
  File "D:\IT\_OER\gauri oer\oer\venv\Lib\site-packages\django\template\defaulttags.py", line 243, in render
    nodelist.append(node.render_annotated(context))
                    ^^^^^^^^^^^^^^^^^^^^^^^^^^^^^^
  File "D:\IT\_OER\gauri oer\oer\venv\Lib\site-packages\django\template\base.py", line 977, in render_annotated
    return self.render(context)
           ^^^^^^^^^^^^^^^^^^^^
  File "D:\IT\_OER\gauri oer\oer\venv\Lib\site-packages\django\template\loader_tags.py", line 210, in render
    return template.render(context)
           ^^^^^^^^^^^^^^^^^^^^^^^^
  File "D:\IT\_OER\gauri oer\oer\venv\Lib\site-packages\django\template\base.py", line 173, in render
    return self._render(context)
           ^^^^^^^^^^^^^^^^^^^^^
  File "D:\IT\_OER\gauri oer\oer\venv\Lib\site-packages\django\template\base.py", line 163, in _render
    return self.nodelist.render(context)
           ^^^^^^^^^^^^^^^^^^^^^^^^^^^^^
  File "D:\IT\_OER\gauri oer\oer\venv\Lib\site-packages\django\template\base.py", line 1016, in render
    return SafeString("".join([node.render_annotated(context) for node in self]))
                               ^^^^^^^^^^^^^^^^^^^^^^^^^^^^^^
  File "D:\IT\_OER\gauri oer\oer\venv\Lib\site-packages\django\template\base.py", line 977, in render_annotated
    return self.render(context)
           ^^^^^^^^^^^^^^^^^^^^
  File "D:\IT\_OER\gauri oer\oer\venv\Lib\site-packages\django\template\defaulttags.py", line 550, in render
    return self.nodelist.render(context)
           ^^^^^^^^^^^^^^^^^^^^^^^^^^^^^
  File "D:\IT\_OER\gauri oer\oer\venv\Lib\site-packages\django\template\base.py", line 1016, in render
    return SafeString("".join([node.render_annotated(context) for node in self]))
                               ^^^^^^^^^^^^^^^^^^^^^^^^^^^^^^
  File "D:\IT\_OER\gauri oer\oer\venv\Lib\site-packages\django\template\base.py", line 977, in render_annotated
    return self.render(context)
           ^^^^^^^^^^^^^^^^^^^^
  File "D:\IT\_OER\gauri oer\oer\venv\Lib\site-packages\django\template\defaulttags.py", line 327, in render
    return nodelist.render(context)
           ^^^^^^^^^^^^^^^^^^^^^^^^
  File "D:\IT\_OER\gauri oer\oer\venv\Lib\site-packages\django\template\base.py", line 1016, in render
    return SafeString("".join([node.render_annotated(context) for node in self]))
                               ^^^^^^^^^^^^^^^^^^^^^^^^^^^^^^
  File "D:\IT\_OER\gauri oer\oer\venv\Lib\site-packages\django\template\base.py", line 977, in render_annotated
    return self.render(context)
           ^^^^^^^^^^^^^^^^^^^^
  File "D:\IT\_OER\gauri oer\oer\venv\Lib\site-packages\django\template\defaulttags.py", line 243, in render
    nodelist.append(node.render_annotated(context))
                    ^^^^^^^^^^^^^^^^^^^^^^^^^^^^^^
  File "D:\IT\_OER\gauri oer\oer\venv\Lib\site-packages\django\template\base.py", line 977, in render_annotated
    return self.render(context)
           ^^^^^^^^^^^^^^^^^^^^
  File "D:\IT\_OER\gauri oer\oer\venv\Lib\site-packages\django\template\loader_tags.py", line 199, in render
    template = context.template.engine.select_template(template_name)
               ^^^^^^^^^^^^^^^^^^^^^^^^^^^^^^^^^^^^^^^^^^^^^^^^^^^^^^
  File "D:\IT\_OER\gauri oer\oer\venv\Lib\site-packages\django\template\engine.py", line 214, in select_template
    raise TemplateDoesNotExist(", ".join(not_found))
django.template.exceptions.TemplateDoesNotExist: accounts/forum/partials/answer.html

The above exception was the direct cause of the following exception:

Traceback (most recent call last):
  File "D:\IT\_OER\gauri oer\oer\venv\Lib\site-packages\django\core\handlers\exception.py", line 55, in inner
    response = get_response(request)
               ^^^^^^^^^^^^^^^^^^^^^
  File "D:\IT\_OER\gauri oer\oer\venv\Lib\site-packages\django\core\handlers\base.py", line 197, in _get_response
    response = wrapped_callback(request, *callback_args, **callback_kwargs)
               ^^^^^^^^^^^^^^^^^^^^^^^^^^^^^^^^^^^^^^^^^^^^^^^^^^^^^^^^^^^^
  File "D:\IT\_OER\gauri oer\oer\accounts\views\forum.py", line 61, in forum_detail
    return render(request, "forum/detail.html", {"question": question, "a_form": ForumAnswerForm()})
           ^^^^^^^^^^^^^^^^^^^^^^^^^^^^^^^^^^^^^^^^^^^^^^^^^^^^^^^^^^^^^^^^^^^^^^^^^^^^^^^^^^^^^^^^^
  File "D:\IT\_OER\gauri oer\oer\venv\Lib\site-packages\django\shortcuts.py", line 25, in render
    content = loader.render_to_string(template_name, context, request, using=using)
              ^^^^^^^^^^^^^^^^^^^^^^^^^^^^^^^^^^^^^^^^^^^^^^^^^^^^^^^^^^^^^^^^^^^^^
  File "D:\IT\_OER\gauri oer\oer\venv\Lib\site-packages\django\template\loader.py", line 62, in render_to_string
    return template.render(context, request)
           ^^^^^^^^^^^^^^^^^^^^^^^^^^^^^^^^^
  File "D:\IT\_OER\gauri oer\oer\venv\Lib\site-packages\django\template\backends\django.py", line 109, in render
    reraise(exc, self.backend)
  File "D:\IT\_OER\gauri oer\oer\venv\Lib\site-packages\django\template\backends\django.py", line 130, in reraise
    raise new from exc
django.template.exceptions.TemplateDoesNotExist: accounts/forum/partials/answer.html
[ERROR] 2025-10-28 01:19:10,389 | django.server | "GET /forum/3/ HTTP/1.1" 500 197099
[ERROR] 2025-10-28 01:19:10,581 | django.request | Internal Server Error: /forum/3/
Traceback (most recent call last):
  File "D:\IT\_OER\gauri oer\oer\venv\Lib\site-packages\django\template\backends\django.py", line 107, in render
    return self.template.render(context)
           ^^^^^^^^^^^^^^^^^^^^^^^^^^^^^
  File "D:\IT\_OER\gauri oer\oer\venv\Lib\site-packages\django\template\base.py", line 171, in render
    return self._render(context)
           ^^^^^^^^^^^^^^^^^^^^^
  File "D:\IT\_OER\gauri oer\oer\venv\Lib\site-packages\django\template\base.py", line 163, in _render
    return self.nodelist.render(context)
           ^^^^^^^^^^^^^^^^^^^^^^^^^^^^^
  File "D:\IT\_OER\gauri oer\oer\venv\Lib\site-packages\django\template\base.py", line 1016, in render
    return SafeString("".join([node.render_annotated(context) for node in self]))
                               ^^^^^^^^^^^^^^^^^^^^^^^^^^^^^^
  File "D:\IT\_OER\gauri oer\oer\venv\Lib\site-packages\django\template\base.py", line 977, in render_annotated
    return self.render(context)
           ^^^^^^^^^^^^^^^^^^^^
  File "D:\IT\_OER\gauri oer\oer\venv\Lib\site-packages\django\template\defaulttags.py", line 243, in render
    nodelist.append(node.render_annotated(context))
                    ^^^^^^^^^^^^^^^^^^^^^^^^^^^^^^
  File "D:\IT\_OER\gauri oer\oer\venv\Lib\site-packages\django\template\base.py", line 977, in render_annotated
    return self.render(context)
           ^^^^^^^^^^^^^^^^^^^^
  File "D:\IT\_OER\gauri oer\oer\venv\Lib\site-packages\django\template\loader_tags.py", line 210, in render
    return template.render(context)
           ^^^^^^^^^^^^^^^^^^^^^^^^
  File "D:\IT\_OER\gauri oer\oer\venv\Lib\site-packages\django\template\base.py", line 173, in render
    return self._render(context)
           ^^^^^^^^^^^^^^^^^^^^^
  File "D:\IT\_OER\gauri oer\oer\venv\Lib\site-packages\django\template\base.py", line 163, in _render
    return self.nodelist.render(context)
           ^^^^^^^^^^^^^^^^^^^^^^^^^^^^^
  File "D:\IT\_OER\gauri oer\oer\venv\Lib\site-packages\django\template\base.py", line 1016, in render
    return SafeString("".join([node.render_annotated(context) for node in self]))
                               ^^^^^^^^^^^^^^^^^^^^^^^^^^^^^^
  File "D:\IT\_OER\gauri oer\oer\venv\Lib\site-packages\django\template\base.py", line 977, in render_annotated
    return self.render(context)
           ^^^^^^^^^^^^^^^^^^^^
  File "D:\IT\_OER\gauri oer\oer\venv\Lib\site-packages\django\template\defaulttags.py", line 550, in render
    return self.nodelist.render(context)
           ^^^^^^^^^^^^^^^^^^^^^^^^^^^^^
  File "D:\IT\_OER\gauri oer\oer\venv\Lib\site-packages\django\template\base.py", line 1016, in render
    return SafeString("".join([node.render_annotated(context) for node in self]))
                               ^^^^^^^^^^^^^^^^^^^^^^^^^^^^^^
  File "D:\IT\_OER\gauri oer\oer\venv\Lib\site-packages\django\template\base.py", line 977, in render_annotated
    return self.render(context)
           ^^^^^^^^^^^^^^^^^^^^
  File "D:\IT\_OER\gauri oer\oer\venv\Lib\site-packages\django\template\defaulttags.py", line 327, in render
    return nodelist.render(context)
           ^^^^^^^^^^^^^^^^^^^^^^^^
  File "D:\IT\_OER\gauri oer\oer\venv\Lib\site-packages\django\template\base.py", line 1016, in render
    return SafeString("".join([node.render_annotated(context) for node in self]))
                               ^^^^^^^^^^^^^^^^^^^^^^^^^^^^^^
  File "D:\IT\_OER\gauri oer\oer\venv\Lib\site-packages\django\template\base.py", line 977, in render_annotated
    return self.render(context)
           ^^^^^^^^^^^^^^^^^^^^
  File "D:\IT\_OER\gauri oer\oer\venv\Lib\site-packages\django\template\defaulttags.py", line 243, in render
    nodelist.append(node.render_annotated(context))
                    ^^^^^^^^^^^^^^^^^^^^^^^^^^^^^^
  File "D:\IT\_OER\gauri oer\oer\venv\Lib\site-packages\django\template\base.py", line 977, in render_annotated
    return self.render(context)
           ^^^^^^^^^^^^^^^^^^^^
  File "D:\IT\_OER\gauri oer\oer\venv\Lib\site-packages\django\template\loader_tags.py", line 199, in render
    template = context.template.engine.select_template(template_name)
               ^^^^^^^^^^^^^^^^^^^^^^^^^^^^^^^^^^^^^^^^^^^^^^^^^^^^^^
  File "D:\IT\_OER\gauri oer\oer\venv\Lib\site-packages\django\template\engine.py", line 214, in select_template
    raise TemplateDoesNotExist(", ".join(not_found))
django.template.exceptions.TemplateDoesNotExist: accounts/forum/partials/answer.html

The above exception was the direct cause of the following exception:

Traceback (most recent call last):
  File "D:\IT\_OER\gauri oer\oer\venv\Lib\site-packages\django\core\handlers\exception.py", line 55, in inner
    response = get_response(request)
               ^^^^^^^^^^^^^^^^^^^^^
  File "D:\IT\_OER\gauri oer\oer\venv\Lib\site-packages\django\core\handlers\base.py", line 197, in _get_response
    response = wrapped_callback(request, *callback_args, **callback_kwargs)
               ^^^^^^^^^^^^^^^^^^^^^^^^^^^^^^^^^^^^^^^^^^^^^^^^^^^^^^^^^^^^
  File "D:\IT\_OER\gauri oer\oer\accounts\views\forum.py", line 61, in forum_detail
    return render(request, "forum/detail.html", {"question": question, "a_form": ForumAnswerForm()})
           ^^^^^^^^^^^^^^^^^^^^^^^^^^^^^^^^^^^^^^^^^^^^^^^^^^^^^^^^^^^^^^^^^^^^^^^^^^^^^^^^^^^^^^^^^
  File "D:\IT\_OER\gauri oer\oer\venv\Lib\site-packages\django\shortcuts.py", line 25, in render
    content = loader.render_to_string(template_name, context, request, using=using)
              ^^^^^^^^^^^^^^^^^^^^^^^^^^^^^^^^^^^^^^^^^^^^^^^^^^^^^^^^^^^^^^^^^^^^^
  File "D:\IT\_OER\gauri oer\oer\venv\Lib\site-packages\django\template\loader.py", line 62, in render_to_string
    return template.render(context, request)
           ^^^^^^^^^^^^^^^^^^^^^^^^^^^^^^^^^
  File "D:\IT\_OER\gauri oer\oer\venv\Lib\site-packages\django\template\backends\django.py", line 109, in render
    reraise(exc, self.backend)
  File "D:\IT\_OER\gauri oer\oer\venv\Lib\site-packages\django\template\backends\django.py", line 130, in reraise
    raise new from exc
django.template.exceptions.TemplateDoesNotExist: accounts/forum/partials/answer.html
[ERROR] 2025-10-28 01:19:10,588 | django.server | "GET /forum/3/ HTTP/1.1" 500 197099
[WARNING] 2025-10-28 01:19:10,885 | django.request | Not Found: /favicon.ico
[WARNING] 2025-10-28 01:19:10,888 | django.server | "GET /favicon.ico HTTP/1.1" 404 8764
[ERROR] 2025-10-28 01:19:55,673 | django.request | Internal Server Error: /forum/3/
Traceback (most recent call last):
  File "D:\IT\_OER\gauri oer\oer\venv\Lib\site-packages\django\template\backends\django.py", line 107, in render
    return self.template.render(context)
           ^^^^^^^^^^^^^^^^^^^^^^^^^^^^^
  File "D:\IT\_OER\gauri oer\oer\venv\Lib\site-packages\django\template\base.py", line 171, in render
    return self._render(context)
           ^^^^^^^^^^^^^^^^^^^^^
  File "D:\IT\_OER\gauri oer\oer\venv\Lib\site-packages\django\template\base.py", line 163, in _render
    return self.nodelist.render(context)
           ^^^^^^^^^^^^^^^^^^^^^^^^^^^^^
  File "D:\IT\_OER\gauri oer\oer\venv\Lib\site-packages\django\template\base.py", line 1016, in render
    return SafeString("".join([node.render_annotated(context) for node in self]))
                               ^^^^^^^^^^^^^^^^^^^^^^^^^^^^^^
  File "D:\IT\_OER\gauri oer\oer\venv\Lib\site-packages\django\template\base.py", line 977, in render_annotated
    return self.render(context)
           ^^^^^^^^^^^^^^^^^^^^
  File "D:\IT\_OER\gauri oer\oer\venv\Lib\site-packages\django\template\defaulttags.py", line 243, in render
    nodelist.append(node.render_annotated(context))
                    ^^^^^^^^^^^^^^^^^^^^^^^^^^^^^^
  File "D:\IT\_OER\gauri oer\oer\venv\Lib\site-packages\django\template\base.py", line 977, in render_annotated
    return self.render(context)
           ^^^^^^^^^^^^^^^^^^^^
  File "D:\IT\_OER\gauri oer\oer\venv\Lib\site-packages\django\template\loader_tags.py", line 210, in render
    return template.render(context)
           ^^^^^^^^^^^^^^^^^^^^^^^^
  File "D:\IT\_OER\gauri oer\oer\venv\Lib\site-packages\django\template\base.py", line 173, in render
    return self._render(context)
           ^^^^^^^^^^^^^^^^^^^^^
  File "D:\IT\_OER\gauri oer\oer\venv\Lib\site-packages\django\template\base.py", line 163, in _render
    return self.nodelist.render(context)
           ^^^^^^^^^^^^^^^^^^^^^^^^^^^^^
  File "D:\IT\_OER\gauri oer\oer\venv\Lib\site-packages\django\template\base.py", line 1016, in render
    return SafeString("".join([node.render_annotated(context) for node in self]))
                               ^^^^^^^^^^^^^^^^^^^^^^^^^^^^^^
  File "D:\IT\_OER\gauri oer\oer\venv\Lib\site-packages\django\template\base.py", line 977, in render_annotated
    return self.render(context)
           ^^^^^^^^^^^^^^^^^^^^
  File "D:\IT\_OER\gauri oer\oer\venv\Lib\site-packages\django\template\defaulttags.py", line 550, in render
    return self.nodelist.render(context)
           ^^^^^^^^^^^^^^^^^^^^^^^^^^^^^
  File "D:\IT\_OER\gauri oer\oer\venv\Lib\site-packages\django\template\base.py", line 1016, in render
    return SafeString("".join([node.render_annotated(context) for node in self]))
                               ^^^^^^^^^^^^^^^^^^^^^^^^^^^^^^
  File "D:\IT\_OER\gauri oer\oer\venv\Lib\site-packages\django\template\base.py", line 977, in render_annotated
    return self.render(context)
           ^^^^^^^^^^^^^^^^^^^^
  File "D:\IT\_OER\gauri oer\oer\venv\Lib\site-packages\django\template\defaulttags.py", line 327, in render
    return nodelist.render(context)
           ^^^^^^^^^^^^^^^^^^^^^^^^
  File "D:\IT\_OER\gauri oer\oer\venv\Lib\site-packages\django\template\base.py", line 1016, in render
    return SafeString("".join([node.render_annotated(context) for node in self]))
                               ^^^^^^^^^^^^^^^^^^^^^^^^^^^^^^
  File "D:\IT\_OER\gauri oer\oer\venv\Lib\site-packages\django\template\base.py", line 977, in render_annotated
    return self.render(context)
           ^^^^^^^^^^^^^^^^^^^^
  File "D:\IT\_OER\gauri oer\oer\venv\Lib\site-packages\django\template\defaulttags.py", line 243, in render
    nodelist.append(node.render_annotated(context))
                    ^^^^^^^^^^^^^^^^^^^^^^^^^^^^^^
  File "D:\IT\_OER\gauri oer\oer\venv\Lib\site-packages\django\template\base.py", line 977, in render_annotated
    return self.render(context)
           ^^^^^^^^^^^^^^^^^^^^
  File "D:\IT\_OER\gauri oer\oer\venv\Lib\site-packages\django\template\loader_tags.py", line 199, in render
    template = context.template.engine.select_template(template_name)
               ^^^^^^^^^^^^^^^^^^^^^^^^^^^^^^^^^^^^^^^^^^^^^^^^^^^^^^
  File "D:\IT\_OER\gauri oer\oer\venv\Lib\site-packages\django\template\engine.py", line 214, in select_template
    raise TemplateDoesNotExist(", ".join(not_found))
django.template.exceptions.TemplateDoesNotExist: accounts/forum/partials/answer.html

The above exception was the direct cause of the following exception:

Traceback (most recent call last):
  File "D:\IT\_OER\gauri oer\oer\venv\Lib\site-packages\django\core\handlers\exception.py", line 55, in inner
    response = get_response(request)
               ^^^^^^^^^^^^^^^^^^^^^
  File "D:\IT\_OER\gauri oer\oer\venv\Lib\site-packages\django\core\handlers\base.py", line 197, in _get_response
    response = wrapped_callback(request, *callback_args, **callback_kwargs)
               ^^^^^^^^^^^^^^^^^^^^^^^^^^^^^^^^^^^^^^^^^^^^^^^^^^^^^^^^^^^^
  File "D:\IT\_OER\gauri oer\oer\accounts\views\forum.py", line 61, in forum_detail
    return render(request, "forum/detail.html", {"question": question, "a_form": ForumAnswerForm()})
           ^^^^^^^^^^^^^^^^^^^^^^^^^^^^^^^^^^^^^^^^^^^^^^^^^^^^^^^^^^^^^^^^^^^^^^^^^^^^^^^^^^^^^^^^^
  File "D:\IT\_OER\gauri oer\oer\venv\Lib\site-packages\django\shortcuts.py", line 25, in render
    content = loader.render_to_string(template_name, context, request, using=using)
              ^^^^^^^^^^^^^^^^^^^^^^^^^^^^^^^^^^^^^^^^^^^^^^^^^^^^^^^^^^^^^^^^^^^^^
  File "D:\IT\_OER\gauri oer\oer\venv\Lib\site-packages\django\template\loader.py", line 62, in render_to_string
    return template.render(context, request)
           ^^^^^^^^^^^^^^^^^^^^^^^^^^^^^^^^^
  File "D:\IT\_OER\gauri oer\oer\venv\Lib\site-packages\django\template\backends\django.py", line 109, in render
    reraise(exc, self.backend)
  File "D:\IT\_OER\gauri oer\oer\venv\Lib\site-packages\django\template\backends\django.py", line 130, in reraise
    raise new from exc
django.template.exceptions.TemplateDoesNotExist: accounts/forum/partials/answer.html
[ERROR] 2025-10-28 01:19:55,673 | django.server | "GET /forum/3/ HTTP/1.1" 500 196971
[WARNING] 2025-10-28 01:19:58,618 | django.request | Not Found: /favicon.ico
[WARNING] 2025-10-28 01:19:58,619 | django.server | "GET /favicon.ico HTTP/1.1" 404 8764
[ERROR] 2025-10-28 01:20:03,400 | django.request | Internal Server Error: /forum/2/
Traceback (most recent call last):
  File "D:\IT\_OER\gauri oer\oer\venv\Lib\site-packages\django\template\backends\django.py", line 107, in render
    return self.template.render(context)
           ^^^^^^^^^^^^^^^^^^^^^^^^^^^^^
  File "D:\IT\_OER\gauri oer\oer\venv\Lib\site-packages\django\template\base.py", line 171, in render
    return self._render(context)
           ^^^^^^^^^^^^^^^^^^^^^
  File "D:\IT\_OER\gauri oer\oer\venv\Lib\site-packages\django\template\base.py", line 163, in _render
    return self.nodelist.render(context)
           ^^^^^^^^^^^^^^^^^^^^^^^^^^^^^
  File "D:\IT\_OER\gauri oer\oer\venv\Lib\site-packages\django\template\base.py", line 1016, in render
    return SafeString("".join([node.render_annotated(context) for node in self]))
                               ^^^^^^^^^^^^^^^^^^^^^^^^^^^^^^
  File "D:\IT\_OER\gauri oer\oer\venv\Lib\site-packages\django\template\base.py", line 977, in render_annotated
    return self.render(context)
           ^^^^^^^^^^^^^^^^^^^^
  File "D:\IT\_OER\gauri oer\oer\venv\Lib\site-packages\django\template\defaulttags.py", line 243, in render
    nodelist.append(node.render_annotated(context))
                    ^^^^^^^^^^^^^^^^^^^^^^^^^^^^^^
  File "D:\IT\_OER\gauri oer\oer\venv\Lib\site-packages\django\template\base.py", line 977, in render_annotated
    return self.render(context)
           ^^^^^^^^^^^^^^^^^^^^
  File "D:\IT\_OER\gauri oer\oer\venv\Lib\site-packages\django\template\loader_tags.py", line 210, in render
    return template.render(context)
           ^^^^^^^^^^^^^^^^^^^^^^^^
  File "D:\IT\_OER\gauri oer\oer\venv\Lib\site-packages\django\template\base.py", line 173, in render
    return self._render(context)
           ^^^^^^^^^^^^^^^^^^^^^
  File "D:\IT\_OER\gauri oer\oer\venv\Lib\site-packages\django\template\base.py", line 163, in _render
    return self.nodelist.render(context)
           ^^^^^^^^^^^^^^^^^^^^^^^^^^^^^
  File "D:\IT\_OER\gauri oer\oer\venv\Lib\site-packages\django\template\base.py", line 1016, in render
    return SafeString("".join([node.render_annotated(context) for node in self]))
                               ^^^^^^^^^^^^^^^^^^^^^^^^^^^^^^
  File "D:\IT\_OER\gauri oer\oer\venv\Lib\site-packages\django\template\base.py", line 977, in render_annotated
    return self.render(context)
           ^^^^^^^^^^^^^^^^^^^^
  File "D:\IT\_OER\gauri oer\oer\venv\Lib\site-packages\django\template\defaulttags.py", line 550, in render
    return self.nodelist.render(context)
           ^^^^^^^^^^^^^^^^^^^^^^^^^^^^^
  File "D:\IT\_OER\gauri oer\oer\venv\Lib\site-packages\django\template\base.py", line 1016, in render
    return SafeString("".join([node.render_annotated(context) for node in self]))
                               ^^^^^^^^^^^^^^^^^^^^^^^^^^^^^^
  File "D:\IT\_OER\gauri oer\oer\venv\Lib\site-packages\django\template\base.py", line 977, in render_annotated
    return self.render(context)
           ^^^^^^^^^^^^^^^^^^^^
  File "D:\IT\_OER\gauri oer\oer\venv\Lib\site-packages\django\template\defaulttags.py", line 327, in render
    return nodelist.render(context)
           ^^^^^^^^^^^^^^^^^^^^^^^^
  File "D:\IT\_OER\gauri oer\oer\venv\Lib\site-packages\django\template\base.py", line 1016, in render
    return SafeString("".join([node.render_annotated(context) for node in self]))
                               ^^^^^^^^^^^^^^^^^^^^^^^^^^^^^^
  File "D:\IT\_OER\gauri oer\oer\venv\Lib\site-packages\django\template\base.py", line 977, in render_annotated
    return self.render(context)
           ^^^^^^^^^^^^^^^^^^^^
  File "D:\IT\_OER\gauri oer\oer\venv\Lib\site-packages\django\template\defaulttags.py", line 243, in render
    nodelist.append(node.render_annotated(context))
                    ^^^^^^^^^^^^^^^^^^^^^^^^^^^^^^
  File "D:\IT\_OER\gauri oer\oer\venv\Lib\site-packages\django\template\base.py", line 977, in render_annotated
    return self.render(context)
           ^^^^^^^^^^^^^^^^^^^^
  File "D:\IT\_OER\gauri oer\oer\venv\Lib\site-packages\django\template\loader_tags.py", line 199, in render
    template = context.template.engine.select_template(template_name)
               ^^^^^^^^^^^^^^^^^^^^^^^^^^^^^^^^^^^^^^^^^^^^^^^^^^^^^^
  File "D:\IT\_OER\gauri oer\oer\venv\Lib\site-packages\django\template\engine.py", line 214, in select_template
    raise TemplateDoesNotExist(", ".join(not_found))
django.template.exceptions.TemplateDoesNotExist: accounts/forum/partials/answer.html

The above exception was the direct cause of the following exception:

Traceback (most recent call last):
  File "D:\IT\_OER\gauri oer\oer\venv\Lib\site-packages\django\core\handlers\exception.py", line 55, in inner
    response = get_response(request)
               ^^^^^^^^^^^^^^^^^^^^^
  File "D:\IT\_OER\gauri oer\oer\venv\Lib\site-packages\django\core\handlers\base.py", line 197, in _get_response
    response = wrapped_callback(request, *callback_args, **callback_kwargs)
               ^^^^^^^^^^^^^^^^^^^^^^^^^^^^^^^^^^^^^^^^^^^^^^^^^^^^^^^^^^^^
  File "D:\IT\_OER\gauri oer\oer\accounts\views\forum.py", line 61, in forum_detail
    return render(request, "forum/detail.html", {"question": question, "a_form": ForumAnswerForm()})
           ^^^^^^^^^^^^^^^^^^^^^^^^^^^^^^^^^^^^^^^^^^^^^^^^^^^^^^^^^^^^^^^^^^^^^^^^^^^^^^^^^^^^^^^^^
  File "D:\IT\_OER\gauri oer\oer\venv\Lib\site-packages\django\shortcuts.py", line 25, in render
    content = loader.render_to_string(template_name, context, request, using=using)
              ^^^^^^^^^^^^^^^^^^^^^^^^^^^^^^^^^^^^^^^^^^^^^^^^^^^^^^^^^^^^^^^^^^^^^
  File "D:\IT\_OER\gauri oer\oer\venv\Lib\site-packages\django\template\loader.py", line 62, in render_to_string
    return template.render(context, request)
           ^^^^^^^^^^^^^^^^^^^^^^^^^^^^^^^^^
  File "D:\IT\_OER\gauri oer\oer\venv\Lib\site-packages\django\template\backends\django.py", line 109, in render
    reraise(exc, self.backend)
  File "D:\IT\_OER\gauri oer\oer\venv\Lib\site-packages\django\template\backends\django.py", line 130, in reraise
    raise new from exc
django.template.exceptions.TemplateDoesNotExist: accounts/forum/partials/answer.html
[ERROR] 2025-10-28 01:20:03,405 | django.server | "GET /forum/2/ HTTP/1.1" 500 196788
[WARNING] 2025-10-28 01:24:20,269 | django.request | Not Found: /favicon.ico
[WARNING] 2025-10-28 01:24:20,270 | django.server | "GET /favicon.ico HTTP/1.1" 404 8764
[WARNING] 2025-10-28 10:54:29,178 | django.request | Not Found: /favicon.ico
[WARNING] 2025-10-28 10:54:29,178 | django.server | "GET /favicon.ico HTTP/1.1" 404 8764
[WARNING] 2025-10-28 13:19:45,208 | django.request | Not Found: /favicon.ico
[WARNING] 2025-10-28 13:19:45,210 | django.server | "GET /favicon.ico HTTP/1.1" 404 8764
[ERROR] 2025-10-28 13:26:16,953 | django.request | Internal Server Error: /
Traceback (most recent call last):
  File "D:\IT\_OER\gauri oer\oer\venv\Lib\site-packages\django\core\handlers\exception.py", line 55, in inner
    response = get_response(request)
               ^^^^^^^^^^^^^^^^^^^^^
  File "D:\IT\_OER\gauri oer\oer\venv\Lib\site-packages\django\core\handlers\base.py", line 197, in _get_response
    response = wrapped_callback(request, *callback_args, **callback_kwargs)
               ^^^^^^^^^^^^^^^^^^^^^^^^^^^^^^^^^^^^^^^^^^^^^^^^^^^^^^^^^^^^
  File "D:\IT\_OER\gauri oer\oer\accounts\views\views.py", line 22, in home_view
    return render(request, 'home/index.html')
           ^^^^^^^^^^^^^^^^^^^^^^^^^^^^^^^^^^
  File "D:\IT\_OER\gauri oer\oer\venv\Lib\site-packages\django\shortcuts.py", line 25, in render
    content = loader.render_to_string(template_name, context, request, using=using)
              ^^^^^^^^^^^^^^^^^^^^^^^^^^^^^^^^^^^^^^^^^^^^^^^^^^^^^^^^^^^^^^^^^^^^^
  File "D:\IT\_OER\gauri oer\oer\venv\Lib\site-packages\django\template\loader.py", line 62, in render_to_string
    return template.render(context, request)
           ^^^^^^^^^^^^^^^^^^^^^^^^^^^^^^^^^
  File "D:\IT\_OER\gauri oer\oer\venv\Lib\site-packages\django\template\backends\django.py", line 107, in render
    return self.template.render(context)
           ^^^^^^^^^^^^^^^^^^^^^^^^^^^^^
  File "D:\IT\_OER\gauri oer\oer\venv\Lib\site-packages\django\template\base.py", line 171, in render
    return self._render(context)
           ^^^^^^^^^^^^^^^^^^^^^
  File "D:\IT\_OER\gauri oer\oer\venv\Lib\site-packages\django\template\base.py", line 163, in _render
    return self.nodelist.render(context)
           ^^^^^^^^^^^^^^^^^^^^^^^^^^^^^
  File "D:\IT\_OER\gauri oer\oer\venv\Lib\site-packages\django\template\base.py", line 1016, in render
    return SafeString("".join([node.render_annotated(context) for node in self]))
                               ^^^^^^^^^^^^^^^^^^^^^^^^^^^^^^
  File "D:\IT\_OER\gauri oer\oer\venv\Lib\site-packages\django\template\base.py", line 977, in render_annotated
    return self.render(context)
           ^^^^^^^^^^^^^^^^^^^^
  File "D:\IT\_OER\gauri oer\oer\venv\Lib\site-packages\django\template\defaulttags.py", line 480, in render
    url = reverse(view_name, args=args, kwargs=kwargs, current_app=current_app)
          ^^^^^^^^^^^^^^^^^^^^^^^^^^^^^^^^^^^^^^^^^^^^^^^^^^^^^^^^^^^^^^^^^^^^^
  File "D:\IT\_OER\gauri oer\oer\venv\Lib\site-packages\django\urls\base.py", line 98, in reverse
    resolved_url = resolver._reverse_with_prefix(view, prefix, *args, **kwargs)
                   ^^^^^^^^^^^^^^^^^^^^^^^^^^^^^^^^^^^^^^^^^^^^^^^^^^^^^^^^^^^^
  File "D:\IT\_OER\gauri oer\oer\venv\Lib\site-packages\django\urls\resolvers.py", line 831, in _reverse_with_prefix
    raise NoReverseMatch(msg)
django.urls.exceptions.NoReverseMatch: Reverse for 'contributor_dashboard' not found. 'contributor_dashboard' is not a valid view function or pattern name.
[ERROR] 2025-10-28 13:26:16,958 | django.server | "GET / HTTP/1.1" 500 122222
[ERROR] 2025-10-28 13:27:43,718 | django.request | Internal Server Error: /
Traceback (most recent call last):
  File "D:\IT\_OER\gauri oer\oer\venv\Lib\site-packages\django\core\handlers\exception.py", line 55, in inner
    response = get_response(request)
               ^^^^^^^^^^^^^^^^^^^^^
  File "D:\IT\_OER\gauri oer\oer\venv\Lib\site-packages\django\core\handlers\base.py", line 197, in _get_response
    response = wrapped_callback(request, *callback_args, **callback_kwargs)
               ^^^^^^^^^^^^^^^^^^^^^^^^^^^^^^^^^^^^^^^^^^^^^^^^^^^^^^^^^^^^
  File "D:\IT\_OER\gauri oer\oer\accounts\views\views.py", line 22, in home_view
    return render(request, 'home/index.html')
           ^^^^^^^^^^^^^^^^^^^^^^^^^^^^^^^^^^
  File "D:\IT\_OER\gauri oer\oer\venv\Lib\site-packages\django\shortcuts.py", line 25, in render
    content = loader.render_to_string(template_name, context, request, using=using)
              ^^^^^^^^^^^^^^^^^^^^^^^^^^^^^^^^^^^^^^^^^^^^^^^^^^^^^^^^^^^^^^^^^^^^^
  File "D:\IT\_OER\gauri oer\oer\venv\Lib\site-packages\django\template\loader.py", line 62, in render_to_string
    return template.render(context, request)
           ^^^^^^^^^^^^^^^^^^^^^^^^^^^^^^^^^
  File "D:\IT\_OER\gauri oer\oer\venv\Lib\site-packages\django\template\backends\django.py", line 107, in render
    return self.template.render(context)
           ^^^^^^^^^^^^^^^^^^^^^^^^^^^^^
  File "D:\IT\_OER\gauri oer\oer\venv\Lib\site-packages\django\template\base.py", line 171, in render
    return self._render(context)
           ^^^^^^^^^^^^^^^^^^^^^
  File "D:\IT\_OER\gauri oer\oer\venv\Lib\site-packages\django\template\base.py", line 163, in _render
    return self.nodelist.render(context)
           ^^^^^^^^^^^^^^^^^^^^^^^^^^^^^
  File "D:\IT\_OER\gauri oer\oer\venv\Lib\site-packages\django\template\base.py", line 1016, in render
    return SafeString("".join([node.render_annotated(context) for node in self]))
                               ^^^^^^^^^^^^^^^^^^^^^^^^^^^^^^
  File "D:\IT\_OER\gauri oer\oer\venv\Lib\site-packages\django\template\base.py", line 977, in render_annotated
    return self.render(context)
           ^^^^^^^^^^^^^^^^^^^^
  File "D:\IT\_OER\gauri oer\oer\venv\Lib\site-packages\django\template\defaulttags.py", line 480, in render
    url = reverse(view_name, args=args, kwargs=kwargs, current_app=current_app)
          ^^^^^^^^^^^^^^^^^^^^^^^^^^^^^^^^^^^^^^^^^^^^^^^^^^^^^^^^^^^^^^^^^^^^^
  File "D:\IT\_OER\gauri oer\oer\venv\Lib\site-packages\django\urls\base.py", line 98, in reverse
    resolved_url = resolver._reverse_with_prefix(view, prefix, *args, **kwargs)
                   ^^^^^^^^^^^^^^^^^^^^^^^^^^^^^^^^^^^^^^^^^^^^^^^^^^^^^^^^^^^^
  File "D:\IT\_OER\gauri oer\oer\venv\Lib\site-packages\django\urls\resolvers.py", line 831, in _reverse_with_prefix
    raise NoReverseMatch(msg)
django.urls.exceptions.NoReverseMatch: Reverse for 'contributor_dashboard' not found. 'contributor_dashboard' is not a valid view function or pattern name.
[ERROR] 2025-10-28 13:27:43,726 | django.server | "GET / HTTP/1.1" 500 122487
[WARNING] 2025-10-28 13:27:44,126 | django.request | Not Found: /favicon.ico
[WARNING] 2025-10-28 13:27:44,127 | django.server | "GET /favicon.ico HTTP/1.1" 404 8764
[ERROR] 2025-10-28 13:31:59,524 | django.request | Internal Server Error: /
Traceback (most recent call last):
  File "D:\IT\_OER\gauri oer\oer\venv\Lib\site-packages\django\core\handlers\exception.py", line 55, in inner
    response = get_response(request)
               ^^^^^^^^^^^^^^^^^^^^^
  File "D:\IT\_OER\gauri oer\oer\venv\Lib\site-packages\django\core\handlers\base.py", line 197, in _get_response
    response = wrapped_callback(request, *callback_args, **callback_kwargs)
               ^^^^^^^^^^^^^^^^^^^^^^^^^^^^^^^^^^^^^^^^^^^^^^^^^^^^^^^^^^^^
  File "D:\IT\_OER\gauri oer\oer\accounts\views\views.py", line 22, in home_view
    return render(request, 'home/index.html')
           ^^^^^^^^^^^^^^^^^^^^^^^^^^^^^^^^^^
  File "D:\IT\_OER\gauri oer\oer\venv\Lib\site-packages\django\shortcuts.py", line 25, in render
    content = loader.render_to_string(template_name, context, request, using=using)
              ^^^^^^^^^^^^^^^^^^^^^^^^^^^^^^^^^^^^^^^^^^^^^^^^^^^^^^^^^^^^^^^^^^^^^
  File "D:\IT\_OER\gauri oer\oer\venv\Lib\site-packages\django\template\loader.py", line 62, in render_to_string
    return template.render(context, request)
           ^^^^^^^^^^^^^^^^^^^^^^^^^^^^^^^^^
  File "D:\IT\_OER\gauri oer\oer\venv\Lib\site-packages\django\template\backends\django.py", line 107, in render
    return self.template.render(context)
           ^^^^^^^^^^^^^^^^^^^^^^^^^^^^^
  File "D:\IT\_OER\gauri oer\oer\venv\Lib\site-packages\django\template\base.py", line 171, in render
    return self._render(context)
           ^^^^^^^^^^^^^^^^^^^^^
  File "D:\IT\_OER\gauri oer\oer\venv\Lib\site-packages\django\template\base.py", line 163, in _render
    return self.nodelist.render(context)
           ^^^^^^^^^^^^^^^^^^^^^^^^^^^^^
  File "D:\IT\_OER\gauri oer\oer\venv\Lib\site-packages\django\template\base.py", line 1016, in render
    return SafeString("".join([node.render_annotated(context) for node in self]))
                               ^^^^^^^^^^^^^^^^^^^^^^^^^^^^^^
  File "D:\IT\_OER\gauri oer\oer\venv\Lib\site-packages\django\template\base.py", line 977, in render_annotated
    return self.render(context)
           ^^^^^^^^^^^^^^^^^^^^
  File "D:\IT\_OER\gauri oer\oer\venv\Lib\site-packages\django\template\defaulttags.py", line 480, in render
    url = reverse(view_name, args=args, kwargs=kwargs, current_app=current_app)
          ^^^^^^^^^^^^^^^^^^^^^^^^^^^^^^^^^^^^^^^^^^^^^^^^^^^^^^^^^^^^^^^^^^^^^
  File "D:\IT\_OER\gauri oer\oer\venv\Lib\site-packages\django\urls\base.py", line 98, in reverse
    resolved_url = resolver._reverse_with_prefix(view, prefix, *args, **kwargs)
                   ^^^^^^^^^^^^^^^^^^^^^^^^^^^^^^^^^^^^^^^^^^^^^^^^^^^^^^^^^^^^
  File "D:\IT\_OER\gauri oer\oer\venv\Lib\site-packages\django\urls\resolvers.py", line 831, in _reverse_with_prefix
    raise NoReverseMatch(msg)
django.urls.exceptions.NoReverseMatch: Reverse for 'student_dashboard' not found. 'student_dashboard' is not a valid view function or pattern name.
[ERROR] 2025-10-28 13:31:59,529 | django.server | "GET / HTTP/1.1" 500 122155
[WARNING] 2025-10-28 13:31:59,884 | django.request | Not Found: /favicon.ico
[WARNING] 2025-10-28 13:31:59,884 | django.server | "GET /favicon.ico HTTP/1.1" 404 8764
[WARNING] 2025-10-28 13:32:06,616 | django.server | "GET /static/frontend/css/style.css HTTP/1.1" 404 1880
[WARNING] 2025-10-28 13:32:06,979 | django.request | Not Found: /favicon.ico
[WARNING] 2025-10-28 13:32:06,980 | django.server | "GET /favicon.ico HTTP/1.1" 404 8764
[WARNING] 2025-10-28 13:37:00,820 | django.request | Not Found: /favicon.ico
[WARNING] 2025-10-28 13:37:00,820 | django.server | "GET /favicon.ico HTTP/1.1" 404 8764
[WARNING] 2025-10-28 13:37:04,304 | django.request | Not Found: /favicon.ico
[WARNING] 2025-10-28 13:37:04,305 | django.server | "GET /favicon.ico HTTP/1.1" 404 8764
[WARNING] 2025-10-28 13:50:32,311 | django.request | Not Found: /favicon.ico
[WARNING] 2025-10-28 13:50:32,312 | django.server | "GET /favicon.ico HTTP/1.1" 404 8764
[ERROR] 2025-10-28 14:40:39,575 | django.request | Internal Server Error: /forum/
Traceback (most recent call last):
  File "D:\IT\_OER\gauri oer\oer\venv\Lib\site-packages\django\core\handlers\exception.py", line 55, in inner
    response = get_response(request)
               ^^^^^^^^^^^^^^^^^^^^^
  File "D:\IT\_OER\gauri oer\oer\venv\Lib\site-packages\django\core\handlers\base.py", line 197, in _get_response
    response = wrapped_callback(request, *callback_args, **callback_kwargs)
               ^^^^^^^^^^^^^^^^^^^^^^^^^^^^^^^^^^^^^^^^^^^^^^^^^^^^^^^^^^^^
  File "D:\IT\_OER\gauri oer\oer\accounts\views\forum.py", line 83, in forum_home
    return render(request, "forum/list.html", context)
           ^^^^^^^^^^^^^^^^^^^^^^^^^^^^^^^^^^^^^^^^^^^
  File "D:\IT\_OER\gauri oer\oer\venv\Lib\site-packages\django\shortcuts.py", line 25, in render
    content = loader.render_to_string(template_name, context, request, using=using)
              ^^^^^^^^^^^^^^^^^^^^^^^^^^^^^^^^^^^^^^^^^^^^^^^^^^^^^^^^^^^^^^^^^^^^^
  File "D:\IT\_OER\gauri oer\oer\venv\Lib\site-packages\django\template\loader.py", line 62, in render_to_string
    return template.render(context, request)
           ^^^^^^^^^^^^^^^^^^^^^^^^^^^^^^^^^
  File "D:\IT\_OER\gauri oer\oer\venv\Lib\site-packages\django\template\backends\django.py", line 107, in render
    return self.template.render(context)
           ^^^^^^^^^^^^^^^^^^^^^^^^^^^^^
  File "D:\IT\_OER\gauri oer\oer\venv\Lib\site-packages\django\template\base.py", line 171, in render
    return self._render(context)
           ^^^^^^^^^^^^^^^^^^^^^
  File "D:\IT\_OER\gauri oer\oer\venv\Lib\site-packages\django\template\base.py", line 163, in _render
    return self.nodelist.render(context)
           ^^^^^^^^^^^^^^^^^^^^^^^^^^^^^
  File "D:\IT\_OER\gauri oer\oer\venv\Lib\site-packages\django\template\base.py", line 1016, in render
    return SafeString("".join([node.render_annotated(context) for node in self]))
                               ^^^^^^^^^^^^^^^^^^^^^^^^^^^^^^
  File "D:\IT\_OER\gauri oer\oer\venv\Lib\site-packages\django\template\base.py", line 977, in render_annotated
    return self.render(context)
           ^^^^^^^^^^^^^^^^^^^^
  File "D:\IT\_OER\gauri oer\oer\venv\Lib\site-packages\django\template\defaulttags.py", line 327, in render
    return nodelist.render(context)
           ^^^^^^^^^^^^^^^^^^^^^^^^
  File "D:\IT\_OER\gauri oer\oer\venv\Lib\site-packages\django\template\base.py", line 1016, in render
    return SafeString("".join([node.render_annotated(context) for node in self]))
                               ^^^^^^^^^^^^^^^^^^^^^^^^^^^^^^
  File "D:\IT\_OER\gauri oer\oer\venv\Lib\site-packages\django\template\base.py", line 977, in render_annotated
    return self.render(context)
           ^^^^^^^^^^^^^^^^^^^^
  File "D:\IT\_OER\gauri oer\oer\venv\Lib\site-packages\django\template\defaulttags.py", line 480, in render
    url = reverse(view_name, args=args, kwargs=kwargs, current_app=current_app)
          ^^^^^^^^^^^^^^^^^^^^^^^^^^^^^^^^^^^^^^^^^^^^^^^^^^^^^^^^^^^^^^^^^^^^^
  File "D:\IT\_OER\gauri oer\oer\venv\Lib\site-packages\django\urls\base.py", line 98, in reverse
    resolved_url = resolver._reverse_with_prefix(view, prefix, *args, **kwargs)
                   ^^^^^^^^^^^^^^^^^^^^^^^^^^^^^^^^^^^^^^^^^^^^^^^^^^^^^^^^^^^^
  File "D:\IT\_OER\gauri oer\oer\venv\Lib\site-packages\django\urls\resolvers.py", line 831, in _reverse_with_prefix
    raise NoReverseMatch(msg)
django.urls.exceptions.NoReverseMatch: Reverse for 'dm_inbox' not found. 'dm_inbox' is not a valid view function or pattern name.
[ERROR] 2025-10-28 14:40:39,585 | django.server | "GET /forum/ HTTP/1.1" 500 150133
[WARNING] 2025-10-28 14:40:41,072 | django.request | Not Found: /favicon.ico
[WARNING] 2025-10-28 14:40:41,074 | django.server | "GET /favicon.ico HTTP/1.1" 404 8764
[WARNING] 2025-10-28 14:43:57,250 | django.request | Not Found: /favicon.ico
[WARNING] 2025-10-28 14:43:57,250 | django.server | "GET /favicon.ico HTTP/1.1" 404 9303
[WARNING] 2025-10-28 14:44:05,560 | django.request | Not Found: /favicon.ico
[WARNING] 2025-10-28 14:44:05,561 | django.server | "GET /favicon.ico HTTP/1.1" 404 9303
[WARNING] 2025-10-28 14:44:11,909 | django.request | Not Found: /favicon.ico
[WARNING] 2025-10-28 14:44:11,910 | django.server | "GET /favicon.ico HTTP/1.1" 404 9303
[WARNING] 2025-10-28 15:01:25,441 | django.request | Not Found: /favicon.ico
[WARNING] 2025-10-28 15:01:25,442 | django.server | "GET /favicon.ico HTTP/1.1" 404 9303
[ERROR] 2025-10-28 15:01:33,813 | django.request | Internal Server Error: /messages/
Traceback (most recent call last):
  File "D:\IT\_OER\gauri oer\oer\venv\Lib\site-packages\django\core\handlers\exception.py", line 55, in inner
    response = get_response(request)
               ^^^^^^^^^^^^^^^^^^^^^
  File "D:\IT\_OER\gauri oer\oer\venv\Lib\site-packages\django\core\handlers\base.py", line 197, in _get_response
    response = wrapped_callback(request, *callback_args, **callback_kwargs)
               ^^^^^^^^^^^^^^^^^^^^^^^^^^^^^^^^^^^^^^^^^^^^^^^^^^^^^^^^^^^^
  File "D:\IT\_OER\gauri oer\oer\venv\Lib\site-packages\django\contrib\auth\decorators.py", line 59, in _view_wrapper
    return view_func(request, *args, **kwargs)
           ^^^^^^^^^^^^^^^^^^^^^^^^^^^^^^^^^^^
  File "D:\IT\_OER\gauri oer\oer\accounts\views\forum.py", line 192, in dm_inbox
    return render(request, "forum/dm_inbox.html", {"threads": threads})
           ^^^^^^^^^^^^^^^^^^^^^^^^^^^^^^^^^^^^^^^^^^^^^^^^^^^^^^^^^^^^
  File "D:\IT\_OER\gauri oer\oer\venv\Lib\site-packages\django\shortcuts.py", line 25, in render
    content = loader.render_to_string(template_name, context, request, using=using)
              ^^^^^^^^^^^^^^^^^^^^^^^^^^^^^^^^^^^^^^^^^^^^^^^^^^^^^^^^^^^^^^^^^^^^^
  File "D:\IT\_OER\gauri oer\oer\venv\Lib\site-packages\django\template\loader.py", line 61, in render_to_string
    template = get_template(template_name, using=using)
               ^^^^^^^^^^^^^^^^^^^^^^^^^^^^^^^^^^^^^^^^
  File "D:\IT\_OER\gauri oer\oer\venv\Lib\site-packages\django\template\loader.py", line 15, in get_template
    return engine.get_template(template_name)
           ^^^^^^^^^^^^^^^^^^^^^^^^^^^^^^^^^^
  File "D:\IT\_OER\gauri oer\oer\venv\Lib\site-packages\django\template\backends\django.py", line 79, in get_template
    return Template(self.engine.get_template(template_name), self)
                    ^^^^^^^^^^^^^^^^^^^^^^^^^^^^^^^^^^^^^^^
  File "D:\IT\_OER\gauri oer\oer\venv\Lib\site-packages\django\template\engine.py", line 177, in get_template
    template, origin = self.find_template(template_name)
                       ^^^^^^^^^^^^^^^^^^^^^^^^^^^^^^^^^
  File "D:\IT\_OER\gauri oer\oer\venv\Lib\site-packages\django\template\engine.py", line 159, in find_template
    template = loader.get_template(name, skip=skip)
               ^^^^^^^^^^^^^^^^^^^^^^^^^^^^^^^^^^^^
  File "D:\IT\_OER\gauri oer\oer\venv\Lib\site-packages\django\template\loaders\cached.py", line 57, in get_template
    template = super().get_template(template_name, skip)
               ^^^^^^^^^^^^^^^^^^^^^^^^^^^^^^^^^^^^^^^^^
  File "D:\IT\_OER\gauri oer\oer\venv\Lib\site-packages\django\template\loaders\base.py", line 28, in get_template
    return Template(
           ^^^^^^^^^
  File "D:\IT\_OER\gauri oer\oer\venv\Lib\site-packages\django\template\base.py", line 154, in __init__
    self.nodelist = self.compile_nodelist()
                    ^^^^^^^^^^^^^^^^^^^^^^^
  File "D:\IT\_OER\gauri oer\oer\venv\Lib\site-packages\django\template\base.py", line 196, in compile_nodelist
    nodelist = parser.parse()
               ^^^^^^^^^^^^^^
  File "D:\IT\_OER\gauri oer\oer\venv\Lib\site-packages\django\template\base.py", line 518, in parse
    raise self.error(token, e)
  File "D:\IT\_OER\gauri oer\oer\venv\Lib\site-packages\django\template\base.py", line 516, in parse
    compiled_result = compile_func(self, token)
                      ^^^^^^^^^^^^^^^^^^^^^^^^^
  File "D:\IT\_OER\gauri oer\oer\venv\Lib\site-packages\django\template\defaulttags.py", line 862, in do_for
    nodelist_loop = parser.parse(
                    ^^^^^^^^^^^^^
  File "D:\IT\_OER\gauri oer\oer\venv\Lib\site-packages\django\template\base.py", line 518, in parse
    raise self.error(token, e)
  File "D:\IT\_OER\gauri oer\oer\venv\Lib\site-packages\django\template\base.py", line 516, in parse
    compiled_result = compile_func(self, token)
                      ^^^^^^^^^^^^^^^^^^^^^^^^^
  File "D:\IT\_OER\gauri oer\oer\venv\Lib\site-packages\django\template\defaulttags.py", line 1438, in url
    args.append(parser.compile_filter(value))
                ^^^^^^^^^^^^^^^^^^^^^^^^^^^^
  File "D:\IT\_OER\gauri oer\oer\venv\Lib\site-packages\django\template\base.py", line 609, in compile_filter
    return FilterExpression(token, self)
           ^^^^^^^^^^^^^^^^^^^^^^^^^^^^^
  File "D:\IT\_OER\gauri oer\oer\venv\Lib\site-packages\django\template\base.py", line 710, in __init__
    raise TemplateSyntaxError(
django.template.exceptions.TemplateSyntaxError: Could not parse the remainder: '(request.user).id' from 't.other_of(request.user).id'
[ERROR] 2025-10-28 15:01:33,820 | django.server | "GET /messages/ HTTP/1.1" 500 181911
[ERROR] 2025-10-28 15:03:14,075 | django.request | Internal Server Error: /messages/
Traceback (most recent call last):
  File "D:\IT\_OER\gauri oer\oer\venv\Lib\site-packages\django\core\handlers\exception.py", line 55, in inner
    response = get_response(request)
               ^^^^^^^^^^^^^^^^^^^^^
  File "D:\IT\_OER\gauri oer\oer\venv\Lib\site-packages\django\core\handlers\base.py", line 197, in _get_response
    response = wrapped_callback(request, *callback_args, **callback_kwargs)
               ^^^^^^^^^^^^^^^^^^^^^^^^^^^^^^^^^^^^^^^^^^^^^^^^^^^^^^^^^^^^
  File "D:\IT\_OER\gauri oer\oer\venv\Lib\site-packages\django\contrib\auth\decorators.py", line 59, in _view_wrapper
    return view_func(request, *args, **kwargs)
           ^^^^^^^^^^^^^^^^^^^^^^^^^^^^^^^^^^^
  File "D:\IT\_OER\gauri oer\oer\accounts\views\forum.py", line 192, in dm_inbox
    return render(request, "forum/dm_inbox.html", {"threads": threads})
           ^^^^^^^^^^^^^^^^^^^^^^^^^^^^^^^^^^^^^^^^^^^^^^^^^^^^^^^^^^^^
  File "D:\IT\_OER\gauri oer\oer\venv\Lib\site-packages\django\shortcuts.py", line 25, in render
    content = loader.render_to_string(template_name, context, request, using=using)
              ^^^^^^^^^^^^^^^^^^^^^^^^^^^^^^^^^^^^^^^^^^^^^^^^^^^^^^^^^^^^^^^^^^^^^
  File "D:\IT\_OER\gauri oer\oer\venv\Lib\site-packages\django\template\loader.py", line 61, in render_to_string
    template = get_template(template_name, using=using)
               ^^^^^^^^^^^^^^^^^^^^^^^^^^^^^^^^^^^^^^^^
  File "D:\IT\_OER\gauri oer\oer\venv\Lib\site-packages\django\template\loader.py", line 15, in get_template
    return engine.get_template(template_name)
           ^^^^^^^^^^^^^^^^^^^^^^^^^^^^^^^^^^
  File "D:\IT\_OER\gauri oer\oer\venv\Lib\site-packages\django\template\backends\django.py", line 79, in get_template
    return Template(self.engine.get_template(template_name), self)
                    ^^^^^^^^^^^^^^^^^^^^^^^^^^^^^^^^^^^^^^^
  File "D:\IT\_OER\gauri oer\oer\venv\Lib\site-packages\django\template\engine.py", line 177, in get_template
    template, origin = self.find_template(template_name)
                       ^^^^^^^^^^^^^^^^^^^^^^^^^^^^^^^^^
  File "D:\IT\_OER\gauri oer\oer\venv\Lib\site-packages\django\template\engine.py", line 159, in find_template
    template = loader.get_template(name, skip=skip)
               ^^^^^^^^^^^^^^^^^^^^^^^^^^^^^^^^^^^^
  File "D:\IT\_OER\gauri oer\oer\venv\Lib\site-packages\django\template\loaders\cached.py", line 57, in get_template
    template = super().get_template(template_name, skip)
               ^^^^^^^^^^^^^^^^^^^^^^^^^^^^^^^^^^^^^^^^^
  File "D:\IT\_OER\gauri oer\oer\venv\Lib\site-packages\django\template\loaders\base.py", line 28, in get_template
    return Template(
           ^^^^^^^^^
  File "D:\IT\_OER\gauri oer\oer\venv\Lib\site-packages\django\template\base.py", line 154, in __init__
    self.nodelist = self.compile_nodelist()
                    ^^^^^^^^^^^^^^^^^^^^^^^
  File "D:\IT\_OER\gauri oer\oer\venv\Lib\site-packages\django\template\base.py", line 196, in compile_nodelist
    nodelist = parser.parse()
               ^^^^^^^^^^^^^^
  File "D:\IT\_OER\gauri oer\oer\venv\Lib\site-packages\django\template\base.py", line 518, in parse
    raise self.error(token, e)
  File "D:\IT\_OER\gauri oer\oer\venv\Lib\site-packages\django\template\base.py", line 516, in parse
    compiled_result = compile_func(self, token)
                      ^^^^^^^^^^^^^^^^^^^^^^^^^
  File "D:\IT\_OER\gauri oer\oer\venv\Lib\site-packages\django\template\defaulttags.py", line 862, in do_for
    nodelist_loop = parser.parse(
                    ^^^^^^^^^^^^^
  File "D:\IT\_OER\gauri oer\oer\venv\Lib\site-packages\django\template\base.py", line 518, in parse
    raise self.error(token, e)
  File "D:\IT\_OER\gauri oer\oer\venv\Lib\site-packages\django\template\base.py", line 516, in parse
    compiled_result = compile_func(self, token)
                      ^^^^^^^^^^^^^^^^^^^^^^^^^
  File "D:\IT\_OER\gauri oer\oer\venv\Lib\site-packages\django\template\defaulttags.py", line 1438, in url
    args.append(parser.compile_filter(value))
                ^^^^^^^^^^^^^^^^^^^^^^^^^^^^
  File "D:\IT\_OER\gauri oer\oer\venv\Lib\site-packages\django\template\base.py", line 609, in compile_filter
    return FilterExpression(token, self)
           ^^^^^^^^^^^^^^^^^^^^^^^^^^^^^
  File "D:\IT\_OER\gauri oer\oer\venv\Lib\site-packages\django\template\base.py", line 710, in __init__
    raise TemplateSyntaxError(
django.template.exceptions.TemplateSyntaxError: Could not parse the remainder: '(request.user).id' from 't.other_of(request.user).id'
[ERROR] 2025-10-28 15:03:14,084 | django.server | "GET /messages/ HTTP/1.1" 500 181029
[WARNING] 2025-10-28 15:03:14,468 | django.request | Not Found: /favicon.ico
[WARNING] 2025-10-28 15:03:14,469 | django.server | "GET /favicon.ico HTTP/1.1" 404 9303
[ERROR] 2025-10-28 15:03:46,050 | django.request | Internal Server Error: /messages/
Traceback (most recent call last):
  File "D:\IT\_OER\gauri oer\oer\venv\Lib\site-packages\django\core\handlers\exception.py", line 55, in inner
    response = get_response(request)
               ^^^^^^^^^^^^^^^^^^^^^
  File "D:\IT\_OER\gauri oer\oer\venv\Lib\site-packages\django\core\handlers\base.py", line 197, in _get_response
    response = wrapped_callback(request, *callback_args, **callback_kwargs)
               ^^^^^^^^^^^^^^^^^^^^^^^^^^^^^^^^^^^^^^^^^^^^^^^^^^^^^^^^^^^^
  File "D:\IT\_OER\gauri oer\oer\venv\Lib\site-packages\django\contrib\auth\decorators.py", line 59, in _view_wrapper
    return view_func(request, *args, **kwargs)
           ^^^^^^^^^^^^^^^^^^^^^^^^^^^^^^^^^^^
  File "D:\IT\_OER\gauri oer\oer\accounts\views\forum.py", line 192, in dm_inbox
    return render(request, "forum/dm_inbox.html", {"threads": threads})
           ^^^^^^^^^^^^^^^^^^^^^^^^^^^^^^^^^^^^^^^^^^^^^^^^^^^^^^^^^^^^
  File "D:\IT\_OER\gauri oer\oer\venv\Lib\site-packages\django\shortcuts.py", line 25, in render
    content = loader.render_to_string(template_name, context, request, using=using)
              ^^^^^^^^^^^^^^^^^^^^^^^^^^^^^^^^^^^^^^^^^^^^^^^^^^^^^^^^^^^^^^^^^^^^^
  File "D:\IT\_OER\gauri oer\oer\venv\Lib\site-packages\django\template\loader.py", line 61, in render_to_string
    template = get_template(template_name, using=using)
               ^^^^^^^^^^^^^^^^^^^^^^^^^^^^^^^^^^^^^^^^
  File "D:\IT\_OER\gauri oer\oer\venv\Lib\site-packages\django\template\loader.py", line 15, in get_template
    return engine.get_template(template_name)
           ^^^^^^^^^^^^^^^^^^^^^^^^^^^^^^^^^^
  File "D:\IT\_OER\gauri oer\oer\venv\Lib\site-packages\django\template\backends\django.py", line 79, in get_template
    return Template(self.engine.get_template(template_name), self)
                    ^^^^^^^^^^^^^^^^^^^^^^^^^^^^^^^^^^^^^^^
  File "D:\IT\_OER\gauri oer\oer\venv\Lib\site-packages\django\template\engine.py", line 177, in get_template
    template, origin = self.find_template(template_name)
                       ^^^^^^^^^^^^^^^^^^^^^^^^^^^^^^^^^
  File "D:\IT\_OER\gauri oer\oer\venv\Lib\site-packages\django\template\engine.py", line 159, in find_template
    template = loader.get_template(name, skip=skip)
               ^^^^^^^^^^^^^^^^^^^^^^^^^^^^^^^^^^^^
  File "D:\IT\_OER\gauri oer\oer\venv\Lib\site-packages\django\template\loaders\cached.py", line 57, in get_template
    template = super().get_template(template_name, skip)
               ^^^^^^^^^^^^^^^^^^^^^^^^^^^^^^^^^^^^^^^^^
  File "D:\IT\_OER\gauri oer\oer\venv\Lib\site-packages\django\template\loaders\base.py", line 28, in get_template
    return Template(
           ^^^^^^^^^
  File "D:\IT\_OER\gauri oer\oer\venv\Lib\site-packages\django\template\base.py", line 154, in __init__
    self.nodelist = self.compile_nodelist()
                    ^^^^^^^^^^^^^^^^^^^^^^^
  File "D:\IT\_OER\gauri oer\oer\venv\Lib\site-packages\django\template\base.py", line 196, in compile_nodelist
    nodelist = parser.parse()
               ^^^^^^^^^^^^^^
  File "D:\IT\_OER\gauri oer\oer\venv\Lib\site-packages\django\template\base.py", line 518, in parse
    raise self.error(token, e)
  File "D:\IT\_OER\gauri oer\oer\venv\Lib\site-packages\django\template\base.py", line 516, in parse
    compiled_result = compile_func(self, token)
                      ^^^^^^^^^^^^^^^^^^^^^^^^^
  File "D:\IT\_OER\gauri oer\oer\venv\Lib\site-packages\django\template\defaulttags.py", line 862, in do_for
    nodelist_loop = parser.parse(
                    ^^^^^^^^^^^^^
  File "D:\IT\_OER\gauri oer\oer\venv\Lib\site-packages\django\template\base.py", line 518, in parse
    raise self.error(token, e)
  File "D:\IT\_OER\gauri oer\oer\venv\Lib\site-packages\django\template\base.py", line 516, in parse
    compiled_result = compile_func(self, token)
                      ^^^^^^^^^^^^^^^^^^^^^^^^^
  File "D:\IT\_OER\gauri oer\oer\venv\Lib\site-packages\django\template\defaulttags.py", line 1438, in url
    args.append(parser.compile_filter(value))
                ^^^^^^^^^^^^^^^^^^^^^^^^^^^^
  File "D:\IT\_OER\gauri oer\oer\venv\Lib\site-packages\django\template\base.py", line 609, in compile_filter
    return FilterExpression(token, self)
           ^^^^^^^^^^^^^^^^^^^^^^^^^^^^^
  File "D:\IT\_OER\gauri oer\oer\venv\Lib\site-packages\django\template\base.py", line 710, in __init__
    raise TemplateSyntaxError(
django.template.exceptions.TemplateSyntaxError: Could not parse the remainder: '(request.user).id' from 't.other_of(request.user).id'
[ERROR] 2025-10-28 15:03:46,057 | django.server | "GET /messages/ HTTP/1.1" 500 180764
[ERROR] 2025-10-28 15:04:19,667 | django.request | Internal Server Error: /messages/
Traceback (most recent call last):
  File "D:\IT\_OER\gauri oer\oer\venv\Lib\site-packages\django\core\handlers\exception.py", line 55, in inner
    response = get_response(request)
               ^^^^^^^^^^^^^^^^^^^^^
  File "D:\IT\_OER\gauri oer\oer\venv\Lib\site-packages\django\core\handlers\base.py", line 197, in _get_response
    response = wrapped_callback(request, *callback_args, **callback_kwargs)
               ^^^^^^^^^^^^^^^^^^^^^^^^^^^^^^^^^^^^^^^^^^^^^^^^^^^^^^^^^^^^
  File "D:\IT\_OER\gauri oer\oer\venv\Lib\site-packages\django\contrib\auth\decorators.py", line 59, in _view_wrapper
    return view_func(request, *args, **kwargs)
           ^^^^^^^^^^^^^^^^^^^^^^^^^^^^^^^^^^^
  File "D:\IT\_OER\gauri oer\oer\accounts\views\forum.py", line 192, in dm_inbox
    return render(request, "forum/dm_inbox.html", {"threads": threads})
           ^^^^^^^^^^^^^^^^^^^^^^^^^^^^^^^^^^^^^^^^^^^^^^^^^^^^^^^^^^^^
  File "D:\IT\_OER\gauri oer\oer\venv\Lib\site-packages\django\shortcuts.py", line 25, in render
    content = loader.render_to_string(template_name, context, request, using=using)
              ^^^^^^^^^^^^^^^^^^^^^^^^^^^^^^^^^^^^^^^^^^^^^^^^^^^^^^^^^^^^^^^^^^^^^
  File "D:\IT\_OER\gauri oer\oer\venv\Lib\site-packages\django\template\loader.py", line 61, in render_to_string
    template = get_template(template_name, using=using)
               ^^^^^^^^^^^^^^^^^^^^^^^^^^^^^^^^^^^^^^^^
  File "D:\IT\_OER\gauri oer\oer\venv\Lib\site-packages\django\template\loader.py", line 15, in get_template
    return engine.get_template(template_name)
           ^^^^^^^^^^^^^^^^^^^^^^^^^^^^^^^^^^
  File "D:\IT\_OER\gauri oer\oer\venv\Lib\site-packages\django\template\backends\django.py", line 79, in get_template
    return Template(self.engine.get_template(template_name), self)
                    ^^^^^^^^^^^^^^^^^^^^^^^^^^^^^^^^^^^^^^^
  File "D:\IT\_OER\gauri oer\oer\venv\Lib\site-packages\django\template\engine.py", line 177, in get_template
    template, origin = self.find_template(template_name)
                       ^^^^^^^^^^^^^^^^^^^^^^^^^^^^^^^^^
  File "D:\IT\_OER\gauri oer\oer\venv\Lib\site-packages\django\template\engine.py", line 159, in find_template
    template = loader.get_template(name, skip=skip)
               ^^^^^^^^^^^^^^^^^^^^^^^^^^^^^^^^^^^^
  File "D:\IT\_OER\gauri oer\oer\venv\Lib\site-packages\django\template\loaders\cached.py", line 57, in get_template
    template = super().get_template(template_name, skip)
               ^^^^^^^^^^^^^^^^^^^^^^^^^^^^^^^^^^^^^^^^^
  File "D:\IT\_OER\gauri oer\oer\venv\Lib\site-packages\django\template\loaders\base.py", line 28, in get_template
    return Template(
           ^^^^^^^^^
  File "D:\IT\_OER\gauri oer\oer\venv\Lib\site-packages\django\template\base.py", line 154, in __init__
    self.nodelist = self.compile_nodelist()
                    ^^^^^^^^^^^^^^^^^^^^^^^
  File "D:\IT\_OER\gauri oer\oer\venv\Lib\site-packages\django\template\base.py", line 196, in compile_nodelist
    nodelist = parser.parse()
               ^^^^^^^^^^^^^^
  File "D:\IT\_OER\gauri oer\oer\venv\Lib\site-packages\django\template\base.py", line 518, in parse
    raise self.error(token, e)
  File "D:\IT\_OER\gauri oer\oer\venv\Lib\site-packages\django\template\base.py", line 516, in parse
    compiled_result = compile_func(self, token)
                      ^^^^^^^^^^^^^^^^^^^^^^^^^
  File "D:\IT\_OER\gauri oer\oer\venv\Lib\site-packages\django\template\defaulttags.py", line 862, in do_for
    nodelist_loop = parser.parse(
                    ^^^^^^^^^^^^^
  File "D:\IT\_OER\gauri oer\oer\venv\Lib\site-packages\django\template\base.py", line 518, in parse
    raise self.error(token, e)
  File "D:\IT\_OER\gauri oer\oer\venv\Lib\site-packages\django\template\base.py", line 516, in parse
    compiled_result = compile_func(self, token)
                      ^^^^^^^^^^^^^^^^^^^^^^^^^
  File "D:\IT\_OER\gauri oer\oer\venv\Lib\site-packages\django\template\defaulttags.py", line 1438, in url
    args.append(parser.compile_filter(value))
                ^^^^^^^^^^^^^^^^^^^^^^^^^^^^
  File "D:\IT\_OER\gauri oer\oer\venv\Lib\site-packages\django\template\base.py", line 609, in compile_filter
    return FilterExpression(token, self)
           ^^^^^^^^^^^^^^^^^^^^^^^^^^^^^
  File "D:\IT\_OER\gauri oer\oer\venv\Lib\site-packages\django\template\base.py", line 710, in __init__
    raise TemplateSyntaxError(
django.template.exceptions.TemplateSyntaxError: Could not parse the remainder: '(request.user).id' from 't.other_of(request.user).id'
[ERROR] 2025-10-28 15:04:19,672 | django.server | "GET /messages/ HTTP/1.1" 500 180764
[WARNING] 2025-10-28 15:07:04,996 | django.request | Not Found: /favicon.ico
[WARNING] 2025-10-28 15:07:04,998 | django.server | "GET /favicon.ico HTTP/1.1" 404 9303
[WARNING] 2025-10-28 15:07:42,192 | django.server | "GET /static/frontend/css/style.css HTTP/1.1" 404 1880
[WARNING] 2025-10-28 15:07:42,470 | django.request | Not Found: /favicon.ico
[WARNING] 2025-10-28 15:07:42,471 | django.server | "GET /favicon.ico HTTP/1.1" 404 9303
[WARNING] 2025-10-28 15:07:45,114 | django.request | Not Found: /accounts/login/
[WARNING] 2025-10-28 15:07:45,115 | django.server | "GET /accounts/login/?next=/dashboard/contributor/ HTTP/1.1" 404 9344
[WARNING] 2025-10-28 15:07:45,180 | django.request | Not Found: /accounts/login/
[WARNING] 2025-10-28 15:07:45,181 | django.server | "GET /accounts/login/?next=/dashboard/contributor/ HTTP/1.1" 404 9344
[ERROR] 2025-10-28 15:09:02,593 | django.request | Internal Server Error: /register/
Traceback (most recent call last):
  File "D:\IT\_OER\gauri oer\oer\venv\Lib\site-packages\django\core\handlers\exception.py", line 55, in inner
    response = get_response(request)
               ^^^^^^^^^^^^^^^^^^^^^
  File "D:\IT\_OER\gauri oer\oer\venv\Lib\site-packages\django\core\handlers\base.py", line 197, in _get_response
    response = wrapped_callback(request, *callback_args, **callback_kwargs)
               ^^^^^^^^^^^^^^^^^^^^^^^^^^^^^^^^^^^^^^^^^^^^^^^^^^^^^^^^^^^^
  File "D:\IT\_OER\gauri oer\oer\accounts\views\views.py", line 147, in register_view
    user.program = Program.objects.get(program_name=request.POST.get('program'))
                   ^^^^^^^^^^^^^^^^^^^^^^^^^^^^^^^^^^^^^^^^^^^^^^^^^^^^^^^^^^^^^
  File "D:\IT\_OER\gauri oer\oer\venv\Lib\site-packages\django\db\models\manager.py", line 87, in manager_method
    return getattr(self.get_queryset(), name)(*args, **kwargs)
           ^^^^^^^^^^^^^^^^^^^^^^^^^^^^^^^^^^^^^^^^^^^^^^^^^^^
  File "D:\IT\_OER\gauri oer\oer\venv\Lib\site-packages\django\db\models\query.py", line 633, in get
    raise self.model.DoesNotExist(
accounts.models.Program.DoesNotExist: Program matching query does not exist.
[ERROR] 2025-10-28 15:09:02,596 | django.server | "POST /register/ HTTP/1.1" 500 86148
