[INFO] 2025-10-21 11:00:21,873 | googleapiclient.discovery_cache | file_cache is only supported with oauth2client<4.0.0
[WARNING] 2025-10-21 11:00:28,803 | django.request | Not Found: /favicon.ico
[WARNING] 2025-10-21 11:00:28,803 | django.server | "GET /favicon.ico HTTP/1.1" 404 4912
[INFO] 2025-10-21 11:00:30,150 | sentence_transformers.SentenceTransformer | Use pytorch device_name: cpu
[INFO] 2025-10-21 11:00:30,154 | sentence_transformers.SentenceTransformer | Load pretrained SentenceTransformer: all-MiniLM-L6-v2
[WARNING] 2025-10-21 11:00:33,566 | huggingface_hub.file_download | Xet Storage is enabled for this repo, but the 'hf_xet' package is not installed. Falling back to regular HTTP download. For better performance, install the package with: `pip install huggingface_hub[hf_xet]` or `pip install hf_xet`
[WARNING] 2025-10-21 11:00:39,680 | django.server | "GET /static/frontend/css/style.css HTTP/1.1" 404 1880
[INFO] 2025-10-21 11:08:39,702 | googleapiclient.discovery_cache | file_cache is only supported with oauth2client<4.0.0
[INFO] 2025-10-21 11:08:52,713 | sentence_transformers.SentenceTransformer | Use pytorch device_name: cpu
[INFO] 2025-10-21 11:08:52,713 | sentence_transformers.SentenceTransformer | Load pretrained SentenceTransformer: all-MiniLM-L6-v2
[WARNING] 2025-10-21 11:08:58,102 | django.server | "GET /static/frontend/css/style.css HTTP/1.1" 404 1880
[INFO] 2025-10-21 11:09:44,032 | googleapiclient.discovery_cache | file_cache is only supported with oauth2client<4.0.0
[INFO] 2025-10-21 11:10:23,127 | googleapiclient.discovery_cache | file_cache is only supported with oauth2client<4.0.0
[INFO] 2025-10-21 11:11:08,013 | googleapiclient.discovery_cache | file_cache is only supported with oauth2client<4.0.0
[INFO] 2025-10-21 11:20:53,636 | sentence_transformers.SentenceTransformer | Use pytorch device_name: cpu
[INFO] 2025-10-21 11:20:53,644 | sentence_transformers.SentenceTransformer | Load pretrained SentenceTransformer: all-MiniLM-L6-v2
[WARNING] 2025-10-21 11:21:00,902 | django.server | "GET /static/frontend/css/style.css HTTP/1.1" 404 1880
[INFO] 2025-10-21 11:39:06,452 | googleapiclient.discovery_cache | file_cache is only supported with oauth2client<4.0.0
[INFO] 2025-10-21 11:39:54,015 | sentence_transformers.SentenceTransformer | Use pytorch device_name: cpu
[INFO] 2025-10-21 11:39:54,015 | sentence_transformers.SentenceTransformer | Load pretrained SentenceTransformer: all-MiniLM-L6-v2
[WARNING] 2025-10-21 11:39:59,692 | django.server | "GET /static/frontend/css/style.css HTTP/1.1" 404 1880
[INFO] 2025-10-21 11:55:38,838 | googleapiclient.discovery_cache | file_cache is only supported with oauth2client<4.0.0
[INFO] 2025-10-21 11:56:01,959 | googleapiclient.discovery_cache | file_cache is only supported with oauth2client<4.0.0
[INFO] 2025-10-21 12:10:36,859 | googleapiclient.discovery_cache | file_cache is only supported with oauth2client<4.0.0
[WARNING] 2025-10-21 12:10:54,070 | django.server | "GET /static/frontend/css/style.css HTTP/1.1" 404 1880
[WARNING] 2025-10-21 12:10:57,975 | django.server | "GET /static/frontend/css/style_contro.css HTTP/1.1" 404 1901
[WARNING] 2025-10-21 12:11:03,835 | django.server | "GET /static/frontend/css/style.css HTTP/1.1" 404 1880
[WARNING] 2025-10-21 12:11:06,779 | django.server | "GET /static/frontend/css/style_contro.css HTTP/1.1" 404 1901
[WARNING] 2025-10-21 12:11:10,739 | django.server | "GET /static/frontend/css/style.css HTTP/1.1" 404 1880
[WARNING] 2025-10-21 12:12:04,614 | django.server | "GET /static/frontend/css/style_contro.css HTTP/1.1" 404 1901
[WARNING] 2025-10-21 12:12:13,708 | django.server | "GET /static/frontend/css/style.css HTTP/1.1" 404 1880
[WARNING] 2025-10-21 12:12:15,642 | django.server | "GET /static/frontend/css/style_contro.css HTTP/1.1" 404 1901
[INFO] 2025-10-21 12:13:27,789 | googleapiclient.discovery_cache | file_cache is only supported with oauth2client<4.0.0
[WARNING] 2025-10-21 12:17:30,266 | django.server | "GET /static/frontend/css/style.css HTTP/1.1" 404 1880
[WARNING] 2025-10-21 12:17:32,881 | django.server | "GET /static/frontend/css/style_contro.css HTTP/1.1" 404 1901
[INFO] 2025-10-21 12:29:43,371 | googleapiclient.discovery_cache | file_cache is only supported with oauth2client<4.0.0
[INFO] 2025-10-21 12:31:34,512 | googleapiclient.discovery_cache | file_cache is only supported with oauth2client<4.0.0
[INFO] 2025-10-21 12:49:47,849 | googleapiclient.discovery_cache | file_cache is only supported with oauth2client<4.0.0
[WARNING] 2025-10-21 12:53:21,291 | django.server | "GET /static/frontend/css/style.css HTTP/1.1" 404 1880
[WARNING] 2025-10-21 12:53:21,419 | django.request | Not Found: /favicon.ico
[WARNING] 2025-10-21 12:53:21,420 | django.server | "GET /favicon.ico HTTP/1.1" 404 4912
[ERROR] 2025-10-21 14:02:48,986 | django.request | Internal Server Error: /register/
Traceback (most recent call last):
  File "C:\Users\gauri\AppData\Local\Programs\Python\Python310\lib\site-packages\django\core\handlers\exception.py", line 55, in inner
    response = get_response(request)
  File "C:\Users\gauri\AppData\Local\Programs\Python\Python310\lib\site-packages\django\core\handlers\base.py", line 197, in _get_response
    response = wrapped_callback(request, *callback_args, **callback_kwargs)
  File "C:\Users\gauri\IdeaProjects\oer\accounts\views\views.py", line 123, in register_view
    user.role = User.Role.CONTRIBUTOR
AttributeError: type object 'User' has no attribute 'Role'
[ERROR] 2025-10-21 14:02:49,036 | django.server | "POST /register/ HTTP/1.1" 500 74507
[INFO] 2025-10-21 14:06:09,137 | googleapiclient.discovery_cache | file_cache is only supported with oauth2client<4.0.0
[INFO] 2025-10-21 14:06:39,404 | googleapiclient.discovery_cache | file_cache is only supported with oauth2client<4.0.0
[ERROR] 2025-10-21 14:07:49,814 | django.request | Internal Server Error: /register/
Traceback (most recent call last):
  File "C:\Users\gauri\AppData\Local\Programs\Python\Python310\lib\site-packages\django\core\handlers\exception.py", line 55, in inner
    response = get_response(request)
  File "C:\Users\gauri\AppData\Local\Programs\Python\Python310\lib\site-packages\django\core\handlers\base.py", line 197, in _get_response
    response = wrapped_callback(request, *callback_args, **callback_kwargs)
  File "C:\Users\gauri\IdeaProjects\oer\accounts\views\views.py", line 129, in register_view
    user.domain_of_expertise = ','.join(domain_ids)
  File "C:\Users\gauri\AppData\Local\Programs\Python\Python310\lib\site-packages\django\db\models\fields\related_descriptors.py", line 291, in __set__
    raise ValueError(
ValueError: Cannot assign "'17,19'": "User.domain_of_expertise" must be a "Expertise" instance.
[ERROR] 2025-10-21 14:07:49,836 | django.server | "POST /register/ HTTP/1.1" 500 79176
[INFO] 2025-10-21 14:12:08,014 | googleapiclient.discovery_cache | file_cache is only supported with oauth2client<4.0.0
[INFO] 2025-10-21 14:12:33,542 | googleapiclient.discovery_cache | file_cache is only supported with oauth2client<4.0.0
[INFO] 2025-10-21 14:26:05,330 | googleapiclient.discovery_cache | file_cache is only supported with oauth2client<4.0.0
[ERROR] 2025-10-21 14:29:51,975 | django.request | Internal Server Error: /register/
Traceback (most recent call last):
  File "C:\Users\gauri\AppData\Local\Programs\Python\Python310\lib\site-packages\django\db\backends\utils.py", line 105, in _execute
    return self.cursor.execute(sql, params)
psycopg2.errors.UndefinedTable: relation "accounts_user_domain_of_expertise" does not exist
LINE 1: ..."id" AS "id" FROM "accounts_expertise" INNER JOIN "accounts_...
                                                             ^


The above exception was the direct cause of the following exception:

Traceback (most recent call last):
  File "C:\Users\gauri\AppData\Local\Programs\Python\Python310\lib\site-packages\django\core\handlers\exception.py", line 55, in inner
    response = get_response(request)
  File "C:\Users\gauri\AppData\Local\Programs\Python\Python310\lib\site-packages\django\core\handlers\base.py", line 197, in _get_response
    response = wrapped_callback(request, *callback_args, **callback_kwargs)
  File "C:\Users\gauri\IdeaProjects\oer\accounts\views\views.py", line 132, in register_view
    user.domain_of_expertise.set(domain_ids)  # assign multiple Expertise objects
  File "C:\Users\gauri\AppData\Local\Programs\Python\Python310\lib\site-packages\django\db\models\fields\related_descriptors.py", line 1336, in set
    old_ids = set(
  File "C:\Users\gauri\AppData\Local\Programs\Python\Python310\lib\site-packages\django\db\models\query.py", line 384, in __iter__
    self._fetch_all()
  File "C:\Users\gauri\AppData\Local\Programs\Python\Python310\lib\site-packages\django\db\models\query.py", line 1949, in _fetch_all
    self._result_cache = list(self._iterable_class(self))
  File "C:\Users\gauri\AppData\Local\Programs\Python\Python310\lib\site-packages\django\db\models\query.py", line 271, in __iter__
    for row in compiler.results_iter(
  File "C:\Users\gauri\AppData\Local\Programs\Python\Python310\lib\site-packages\django\db\models\sql\compiler.py", line 1572, in results_iter
    results = self.execute_sql(
  File "C:\Users\gauri\AppData\Local\Programs\Python\Python310\lib\site-packages\django\db\models\sql\compiler.py", line 1623, in execute_sql
    cursor.execute(sql, params)
  File "C:\Users\gauri\AppData\Local\Programs\Python\Python310\lib\site-packages\django\db\backends\utils.py", line 122, in execute
    return super().execute(sql, params)
  File "C:\Users\gauri\AppData\Local\Programs\Python\Python310\lib\site-packages\django\db\backends\utils.py", line 79, in execute
    return self._execute_with_wrappers(
  File "C:\Users\gauri\AppData\Local\Programs\Python\Python310\lib\site-packages\django\db\backends\utils.py", line 92, in _execute_with_wrappers
    return executor(sql, params, many, context)
  File "C:\Users\gauri\AppData\Local\Programs\Python\Python310\lib\site-packages\django\db\backends\utils.py", line 100, in _execute
    with self.db.wrap_database_errors:
  File "C:\Users\gauri\AppData\Local\Programs\Python\Python310\lib\site-packages\django\db\utils.py", line 91, in __exit__
    raise dj_exc_value.with_traceback(traceback) from exc_value
  File "C:\Users\gauri\AppData\Local\Programs\Python\Python310\lib\site-packages\django\db\backends\utils.py", line 105, in _execute
    return self.cursor.execute(sql, params)
django.db.utils.ProgrammingError: relation "accounts_user_domain_of_expertise" does not exist
LINE 1: ..."id" AS "id" FROM "accounts_expertise" INNER JOIN "accounts_...
                                                             ^

[ERROR] 2025-10-21 14:29:52,008 | django.server | "POST /register/ HTTP/1.1" 500 137813
[INFO] 2025-10-21 14:36:36,774 | googleapiclient.discovery_cache | file_cache is only supported with oauth2client<4.0.0
[INFO] 2025-10-21 14:36:51,343 | googleapiclient.discovery_cache | file_cache is only supported with oauth2client<4.0.0
[INFO] 2025-10-21 14:37:26,847 | googleapiclient.discovery_cache | file_cache is only supported with oauth2client<4.0.0
[INFO] 2025-10-21 14:38:17,035 | googleapiclient.discovery_cache | file_cache is only supported with oauth2client<4.0.0
[INFO] 2025-10-21 14:42:04,812 | googleapiclient.discovery_cache | file_cache is only supported with oauth2client<4.0.0
[INFO] 2025-10-21 14:42:21,018 | googleapiclient.discovery_cache | file_cache is only supported with oauth2client<4.0.0
[INFO] 2025-10-21 14:43:01,180 | googleapiclient.discovery_cache | file_cache is only supported with oauth2client<4.0.0
[ERROR] 2025-10-21 14:43:41,963 | django.request | Internal Server Error: /register/
Traceback (most recent call last):
  File "C:\Users\gauri\AppData\Local\Programs\Python\Python310\lib\site-packages\django\core\handlers\exception.py", line 55, in inner
    response = get_response(request)
  File "C:\Users\gauri\AppData\Local\Programs\Python\Python310\lib\site-packages\django\core\handlers\base.py", line 197, in _get_response
    response = wrapped_callback(request, *callback_args, **callback_kwargs)
  File "C:\Users\gauri\IdeaProjects\oer\accounts\views\views.py", line 134, in register_view
    user.domain_of_expertise = ','.join(domain_ids)
  File "C:\Users\gauri\AppData\Local\Programs\Python\Python310\lib\site-packages\django\db\models\fields\related_descriptors.py", line 668, in __set__
    raise TypeError(
TypeError: Direct assignment to the forward side of a many-to-many set is prohibited. Use domain_of_expertise.set() instead.
[ERROR] 2025-10-21 14:43:41,970 | django.server | "POST /register/ HTTP/1.1" 500 78892
[INFO] 2025-10-21 18:26:57,833 | googleapiclient.discovery_cache | file_cache is only supported with oauth2client<4.0.0
[WARNING] 2025-10-21 18:27:15,876 | django.request | Not Found: /favicon.ico
[WARNING] 2025-10-21 18:27:15,876 | django.server | "GET /favicon.ico HTTP/1.1" 404 4912
[INFO] 2025-10-21 18:38:59,656 | googleapiclient.discovery_cache | file_cache is only supported with oauth2client<4.0.0
[WARNING] 2025-10-21 18:39:09,003 | django.server | "GET /static/frontend/css/style_contro.css HTTP/1.1" 404 1901
[WARNING] 2025-10-21 18:40:42,789 | django.server | "GET /static/frontend/css/style_contro.css HTTP/1.1" 404 1901
[INFO] 2025-10-21 18:41:45,871 | googleapiclient.discovery_cache | file_cache is only supported with oauth2client<4.0.0
[ERROR] 2025-10-21 18:59:32,927 | django.request | Internal Server Error: /
Traceback (most recent call last):
  File "C:\Users\gauri\AppData\Local\Programs\Python\Python310\lib\site-packages\django\core\handlers\exception.py", line 55, in inner
    response = get_response(request)
  File "C:\Users\gauri\AppData\Local\Programs\Python\Python310\lib\site-packages\django\core\handlers\base.py", line 197, in _get_response
    response = wrapped_callback(request, *callback_args, **callback_kwargs)
  File "C:\Users\gauri\IdeaProjects\oer\accounts\views\views.py", line 22, in home_view
    return render(request, 'home/index.html')
  File "C:\Users\gauri\AppData\Local\Programs\Python\Python310\lib\site-packages\django\shortcuts.py", line 25, in render
    content = loader.render_to_string(template_name, context, request, using=using)
  File "C:\Users\gauri\AppData\Local\Programs\Python\Python310\lib\site-packages\django\template\loader.py", line 62, in render_to_string
    return template.render(context, request)
  File "C:\Users\gauri\AppData\Local\Programs\Python\Python310\lib\site-packages\django\template\backends\django.py", line 107, in render
    return self.template.render(context)
  File "C:\Users\gauri\AppData\Local\Programs\Python\Python310\lib\site-packages\django\template\base.py", line 171, in render
    return self._render(context)
  File "C:\Users\gauri\AppData\Local\Programs\Python\Python310\lib\site-packages\django\template\base.py", line 163, in _render
    return self.nodelist.render(context)
  File "C:\Users\gauri\AppData\Local\Programs\Python\Python310\lib\site-packages\django\template\base.py", line 1016, in render
    return SafeString("".join([node.render_annotated(context) for node in self]))
  File "C:\Users\gauri\AppData\Local\Programs\Python\Python310\lib\site-packages\django\template\base.py", line 1016, in <listcomp>
    return SafeString("".join([node.render_annotated(context) for node in self]))
  File "C:\Users\gauri\AppData\Local\Programs\Python\Python310\lib\site-packages\django\template\base.py", line 977, in render_annotated
    return self.render(context)
  File "C:\Users\gauri\AppData\Local\Programs\Python\Python310\lib\site-packages\django\template\defaulttags.py", line 480, in render
    url = reverse(view_name, args=args, kwargs=kwargs, current_app=current_app)
  File "C:\Users\gauri\AppData\Local\Programs\Python\Python310\lib\site-packages\django\urls\base.py", line 98, in reverse
    resolved_url = resolver._reverse_with_prefix(view, prefix, *args, **kwargs)
  File "C:\Users\gauri\AppData\Local\Programs\Python\Python310\lib\site-packages\django\urls\resolvers.py", line 831, in _reverse_with_prefix
    raise NoReverseMatch(msg)
django.urls.exceptions.NoReverseMatch: Reverse for 'contributor_dashboard' not found. 'contributor_dashboard' is not a valid view function or pattern name.
[ERROR] 2025-10-21 18:59:33,101 | django.server | "GET / HTTP/1.1" 500 122375
[WARNING] 2025-10-21 18:59:53,235 | django.server | "GET /static/frontend/css/style_contro.css HTTP/1.1" 404 1901
[WARNING] 2025-10-21 19:00:38,691 | django.request | Not Found: /dashboard/contributor/
[WARNING] 2025-10-21 19:00:38,691 | django.server | "GET /dashboard/contributor/ HTTP/1.1" 404 4383
[WARNING] 2025-10-21 19:07:28,158 | django.server | "GET /static/frontend/css/style_contro.css HTTP/1.1" 404 1901
[WARNING] 2025-10-21 19:08:46,090 | django.server | "GET /static/frontend/css/style_contro.css HTTP/1.1" 404 1901
[WARNING] 2025-10-21 19:08:51,242 | django.server | "GET /static/frontend/css/style_contro.css HTTP/1.1" 404 1901
[WARNING] 2025-10-21 19:13:18,214 | django.server | "GET /static/frontend/images/high-five.jpg HTTP/1.1" 404 1901
[WARNING] 2025-10-21 19:13:18,220 | django.server | "GET /static/frontend/js/contributor.js HTTP/1.1" 404 1892
[WARNING] 2025-10-21 19:13:18,506 | django.server | "GET /static/frontend/css/style_contro.css HTTP/1.1" 404 1901
[WARNING] 2025-10-21 19:14:01,463 | django.server | "GET /static/frontend/images/high-five.jpg HTTP/1.1" 404 1901
[WARNING] 2025-10-21 19:14:01,463 | django.server | "GET /static/frontend/js/contributor.js HTTP/1.1" 404 1892
[WARNING] 2025-10-21 19:14:01,464 | django.server | "GET /static/frontend/css/style_contro.css HTTP/1.1" 404 1901
[WARNING] 2025-10-21 19:14:15,390 | django.server | "GET /static/frontend/css/style_contro.css HTTP/1.1" 404 1901
[WARNING] 2025-10-21 19:14:15,390 | django.server | "GET /static/frontend/images/high-five.jpg HTTP/1.1" 404 1901
[WARNING] 2025-10-21 19:14:15,683 | django.server | "GET /static/frontend/js/contributor.js HTTP/1.1" 404 1892
[WARNING] 2025-10-21 19:14:20,745 | django.server | "GET /static/frontend/css/style_contro.css HTTP/1.1" 404 1901
[WARNING] 2025-10-21 19:14:20,745 | django.server | "GET /static/frontend/images/high-five.jpg HTTP/1.1" 404 1901
[WARNING] 2025-10-21 19:14:21,034 | django.server | "GET /static/frontend/js/contributor.js HTTP/1.1" 404 1892
[WARNING] 2025-10-21 19:28:09,679 | django.server | "GET /static/frontend/css/style_contro.css HTTP/1.1" 404 1901
[WARNING] 2025-10-21 19:28:13,923 | django.server | "GET /static/frontend/css/style_contro.css HTTP/1.1" 404 1901
[WARNING] 2025-10-21 19:28:18,995 | django.server | "GET /static/frontend/css/style_contro.css HTTP/1.1" 404 1901
[WARNING] 2025-10-21 19:28:19,319 | django.server | "GET /static/frontend/images/high-five.jpg HTTP/1.1" 404 1901
[WARNING] 2025-10-21 19:28:19,319 | django.server | "GET /static/frontend/js/contributor.js HTTP/1.1" 404 1892
[WARNING] 2025-10-21 19:29:32,973 | django.server | "GET /static/frontend/css/style_contro.css HTTP/1.1" 404 1901
[WARNING] 2025-10-21 19:29:32,975 | django.server | "GET /static/frontend/js/contributor.js HTTP/1.1" 404 1892
[WARNING] 2025-10-21 19:29:32,976 | django.server | "GET /static/frontend/images/high-five.jpg HTTP/1.1" 404 1901
[WARNING] 2025-10-21 19:32:04,618 | django.server | "GET /static/frontend/css/style_contro.css HTTP/1.1" 404 1901
[WARNING] 2025-10-21 19:32:09,222 | django.server | "GET /static/frontend/css/style_contro.css HTTP/1.1" 404 1901
[WARNING] 2025-10-21 19:32:15,346 | django.server | "GET /static/frontend/js/contributor.js HTTP/1.1" 404 1892
[WARNING] 2025-10-21 19:32:15,348 | django.server | "GET /static/frontend/images/high-five.jpg HTTP/1.1" 404 1901
[WARNING] 2025-10-21 19:32:15,349 | django.server | "GET /static/frontend/css/style_contro.css HTTP/1.1" 404 1901
[WARNING] 2025-10-21 19:34:03,462 | django.server | "GET /static/frontend/images/high-five.jpg HTTP/1.1" 404 1901
[WARNING] 2025-10-21 19:34:03,463 | django.server | "GET /static/frontend/js/contributor.js HTTP/1.1" 404 1892
[WARNING] 2025-10-21 19:34:03,463 | django.server | "GET /static/frontend/css/style_contro.css HTTP/1.1" 404 1901
[WARNING] 2025-10-21 19:34:26,216 | django.server | "GET /static/frontend/images/high-five.jpg HTTP/1.1" 404 1901
[WARNING] 2025-10-21 19:34:26,228 | django.server | "GET /static/frontend/js/contributor.js HTTP/1.1" 404 1892
[WARNING] 2025-10-21 19:34:26,228 | django.server | "GET /static/frontend/css/style_contro.css HTTP/1.1" 404 1901
[WARNING] 2025-10-21 19:35:38,980 | django.server | "GET /static/frontend/css/style_contro.css HTTP/1.1" 404 1901
[WARNING] 2025-10-21 19:35:38,986 | django.server | "GET /static/frontend/images/high-five.jpg HTTP/1.1" 404 1901
[WARNING] 2025-10-21 19:35:38,986 | django.server | "GET /static/frontend/js/contributor.js HTTP/1.1" 404 1892
[INFO] 2025-10-21 19:41:00,733 | googleapiclient.discovery_cache | file_cache is only supported with oauth2client<4.0.0
[ERROR] 2025-10-21 19:41:02,736 | django.request | Internal Server Error: /dashboard/contributor/submit_content/upload
Traceback (most recent call last):
  File "C:\Users\gauri\AppData\Local\Programs\Python\Python310\lib\site-packages\django\core\handlers\exception.py", line 55, in inner
    response = get_response(request)
  File "C:\Users\gauri\AppData\Local\Programs\Python\Python310\lib\site-packages\django\core\handlers\base.py", line 197, in _get_response
    response = wrapped_callback(request, *callback_args, **callback_kwargs)
  File "C:\Users\gauri\IdeaProjects\oer\accounts\views\contributor\submit_content.py", line 85, in upload_files
    oer_content_id = get_or_create_drive_folder(service, "oer_content")
  File "C:\Users\gauri\IdeaProjects\oer\accounts\views\contributor\submit_content.py", line 44, in get_or_create_drive_folder
    ).execute()
  File "C:\Users\gauri\AppData\Local\Programs\Python\Python310\lib\site-packages\googleapiclient\_helpers.py", line 130, in positional_wrapper
    return wrapped(*args, **kwargs)
  File "C:\Users\gauri\AppData\Local\Programs\Python\Python310\lib\site-packages\googleapiclient\http.py", line 938, in execute
    raise HttpError(resp, content, uri=self.uri)
googleapiclient.errors.HttpError: <HttpError 404 when requesting https://www.googleapis.com/drive/v3/files?q=mimeType%3D%27application%2Fvnd.google-apps.folder%27+and+name%3D%27oer_content%27&spaces=drive&corpora=drive&driveId=1SsOPpMRDccaUkdqSZOCOfku5WbXzhZ8U&includeItemsFromAllDrives=true&supportsAllDrives=true&fields=files%28id%2C+name%29&alt=json returned "Shared drive not found: 1SsOPpMRDccaUkdqSZOCOfku5WbXzhZ8U". Details: "[{'message': 'Shared drive not found: 1SsOPpMRDccaUkdqSZOCOfku5WbXzhZ8U', 'domain': 'global', 'reason': 'notFound', 'location': 'driveId', 'locationType': 'parameter'}]">
[ERROR] 2025-10-21 19:41:02,752 | django.server | "POST /dashboard/contributor/submit_content/upload HTTP/1.1" 500 88377
[WARNING] 2025-10-21 20:15:40,987 | django.server | "GET /static/frontend/css/style_contro.css HTTP/1.1" 404 1901
[WARNING] 2025-10-21 20:15:54,969 | django.server | "GET /static/frontend/css/style_contro.css HTTP/1.1" 404 1901
[WARNING] 2025-10-21 20:16:04,255 | django.server | "GET /static/frontend/css/style_contro.css HTTP/1.1" 404 1901
[WARNING] 2025-10-21 20:16:07,777 | django.server | "GET /static/frontend/css/style_contro.css HTTP/1.1" 404 1901
[WARNING] 2025-10-21 20:16:07,777 | django.server | "GET /static/frontend/images/high-five.jpg HTTP/1.1" 404 1901
[WARNING] 2025-10-21 20:16:08,103 | django.server | "GET /static/frontend/js/contributor.js HTTP/1.1" 404 1892
[INFO] 2025-10-21 20:16:29,915 | googleapiclient.discovery_cache | file_cache is only supported with oauth2client<4.0.0
[ERROR] 2025-10-21 20:16:30,931 | django.request | Internal Server Error: /dashboard/contributor/submit_content/upload
Traceback (most recent call last):
  File "C:\Users\gauri\AppData\Local\Programs\Python\Python310\lib\site-packages\django\core\handlers\exception.py", line 55, in inner
    response = get_response(request)
  File "C:\Users\gauri\AppData\Local\Programs\Python\Python310\lib\site-packages\django\core\handlers\base.py", line 197, in _get_response
    response = wrapped_callback(request, *callback_args, **callback_kwargs)
  File "C:\Users\gauri\IdeaProjects\oer\accounts\views\contributor\submit_content.py", line 85, in upload_files
    oer_content_id = get_or_create_drive_folder(service, "oer_content")
  File "C:\Users\gauri\IdeaProjects\oer\accounts\views\contributor\submit_content.py", line 44, in get_or_create_drive_folder
    ).execute()
  File "C:\Users\gauri\AppData\Local\Programs\Python\Python310\lib\site-packages\googleapiclient\_helpers.py", line 130, in positional_wrapper
    return wrapped(*args, **kwargs)
  File "C:\Users\gauri\AppData\Local\Programs\Python\Python310\lib\site-packages\googleapiclient\http.py", line 938, in execute
    raise HttpError(resp, content, uri=self.uri)
googleapiclient.errors.HttpError: <HttpError 404 when requesting https://www.googleapis.com/drive/v3/files?q=mimeType%3D%27application%2Fvnd.google-apps.folder%27+and+name%3D%27oer_content%27&spaces=drive&corpora=drive&driveId=1SsOPpMRDccaUkdqSZOCOfku5WbXzhZ8U&includeItemsFromAllDrives=true&supportsAllDrives=true&fields=files%28id%2C+name%29&alt=json returned "Shared drive not found: 1SsOPpMRDccaUkdqSZOCOfku5WbXzhZ8U". Details: "[{'message': 'Shared drive not found: 1SsOPpMRDccaUkdqSZOCOfku5WbXzhZ8U', 'domain': 'global', 'reason': 'notFound', 'location': 'driveId', 'locationType': 'parameter'}]">
[ERROR] 2025-10-21 20:16:30,931 | django.server | "POST /dashboard/contributor/submit_content/upload HTTP/1.1" 500 88377
[WARNING] 2025-10-21 20:23:06,097 | django.request | Not Found: /favicon.ico
[WARNING] 2025-10-21 20:23:06,118 | django.server | "GET /favicon.ico HTTP/1.1" 404 4912
